[2019-11-25 16:20:13,940][uWSGIWorker1Core0:140377544300608][task_id:django.request][log.py:228][ERROR][Internal Server Error: /api2/api/articleList/]
Traceback (most recent call last):
  File "/root/site/xiao2Blog/server/venv/lib/python3.6/site-packages/django/core/handlers/exception.py", line 34, in inner
    response = get_response(request)
  File "/root/site/xiao2Blog/server/venv/lib/python3.6/site-packages/django/core/handlers/base.py", line 145, in _get_response
    response = self.process_exception_by_middleware(e, request)
  File "/root/site/xiao2Blog/server/venv/lib/python3.6/site-packages/django/core/handlers/base.py", line 143, in _get_response
    response = response.render()
  File "/root/site/xiao2Blog/server/venv/lib/python3.6/site-packages/django/template/response.py", line 106, in render
    self.content = self.rendered_content
  File "/root/site/xiao2Blog/server/venv/lib/python3.6/site-packages/rest_framework/response.py", line 70, in rendered_content
    ret = renderer.render(self.data, accepted_media_type, context)
  File "/root/site/xiao2Blog/server/venv/lib/python3.6/site-packages/rest_framework/renderers.py", line 726, in render
    ret = template.render(context, request=renderer_context['request'])
  File "/root/site/xiao2Blog/server/venv/lib/python3.6/site-packages/django/template/backends/django.py", line 61, in render
    return self.template.render(context)
  File "/root/site/xiao2Blog/server/venv/lib/python3.6/site-packages/django/template/base.py", line 171, in render
    return self._render(context)
  File "/root/site/xiao2Blog/server/venv/lib/python3.6/site-packages/django/template/base.py", line 163, in _render
    return self.nodelist.render(context)
  File "/root/site/xiao2Blog/server/venv/lib/python3.6/site-packages/django/template/base.py", line 937, in render
    bit = node.render_annotated(context)
  File "/root/site/xiao2Blog/server/venv/lib/python3.6/site-packages/django/template/base.py", line 904, in render_annotated
    return self.render(context)
  File "/root/site/xiao2Blog/server/venv/lib/python3.6/site-packages/django/template/loader_tags.py", line 150, in render
    return compiled_parent._render(context)
  File "/root/site/xiao2Blog/server/venv/lib/python3.6/site-packages/django/template/base.py", line 163, in _render
    return self.nodelist.render(context)
  File "/root/site/xiao2Blog/server/venv/lib/python3.6/site-packages/django/template/base.py", line 937, in render
    bit = node.render_annotated(context)
  File "/root/site/xiao2Blog/server/venv/lib/python3.6/site-packages/django/template/base.py", line 904, in render_annotated
    return self.render(context)
  File "/root/site/xiao2Blog/server/venv/lib/python3.6/site-packages/django/template/loader_tags.py", line 62, in render
    result = block.nodelist.render(context)
  File "/root/site/xiao2Blog/server/venv/lib/python3.6/site-packages/django/template/base.py", line 937, in render
    bit = node.render_annotated(context)
  File "/root/site/xiao2Blog/server/venv/lib/python3.6/site-packages/django/template/base.py", line 904, in render_annotated
    return self.render(context)
  File "/root/site/xiao2Blog/server/venv/lib/python3.6/site-packages/django/template/loader_tags.py", line 62, in render
    result = block.nodelist.render(context)
  File "/root/site/xiao2Blog/server/venv/lib/python3.6/site-packages/django/template/base.py", line 937, in render
    bit = node.render_annotated(context)
  File "/root/site/xiao2Blog/server/venv/lib/python3.6/site-packages/django/template/base.py", line 904, in render_annotated
    return self.render(context)
  File "/root/site/xiao2Blog/server/venv/lib/python3.6/site-packages/django/template/loader_tags.py", line 62, in render
    result = block.nodelist.render(context)
  File "/root/site/xiao2Blog/server/venv/lib/python3.6/site-packages/django/template/base.py", line 937, in render
    bit = node.render_annotated(context)
  File "/root/site/xiao2Blog/server/venv/lib/python3.6/site-packages/django/template/base.py", line 904, in render_annotated
    return self.render(context)
  File "/root/site/xiao2Blog/server/venv/lib/python3.6/site-packages/django/template/defaulttags.py", line 309, in render
    return nodelist.render(context)
  File "/root/site/xiao2Blog/server/venv/lib/python3.6/site-packages/django/template/base.py", line 937, in render
    bit = node.render_annotated(context)
  File "/root/site/xiao2Blog/server/venv/lib/python3.6/site-packages/django/template/base.py", line 904, in render_annotated
    return self.render(context)
  File "/root/site/xiao2Blog/server/venv/lib/python3.6/site-packages/django/template/library.py", line 192, in render
    output = self.func(*resolved_args, **resolved_kwargs)
  File "/root/site/xiao2Blog/server/venv/lib/python3.6/site-packages/rest_framework/templatetags/rest_framework.py", line 96, in optional_login
    login_url = reverse('rest_framework:login')
  File "/root/site/xiao2Blog/server/venv/lib/python3.6/site-packages/django/urls/base.py", line 58, in reverse
    app_list = resolver.app_dict[ns]
  File "/root/site/xiao2Blog/server/venv/lib/python3.6/site-packages/django/urls/resolvers.py", line 513, in app_dict
    self._populate()
  File "/root/site/xiao2Blog/server/venv/lib/python3.6/site-packages/django/urls/resolvers.py", line 464, in _populate
    url_pattern._populate()
  File "/root/site/xiao2Blog/server/venv/lib/python3.6/site-packages/django/urls/resolvers.py", line 447, in _populate
    for url_pattern in reversed(self.url_patterns):
TypeError: 'set' object is not reversible
[2019-11-25 16:33:24,803][uWSGIWorker1Core0:140056096737344][task_id:django.request][log.py:228][WARNING][Not Found: /api2/api/adsa]
[2019-11-25 16:33:28,563][uWSGIWorker1Core0:140056096737344][task_id:django.request][log.py:228][WARNING][Not Found: /api2/api/]
[2019-11-25 16:33:37,064][uWSGIWorker1Core0:140056096737344][task_id:django.request][log.py:228][WARNING][Not Found: /api2/api/articleLis2]
[2019-11-25 16:34:13,177][uWSGIWorker1Core0:140056096737344][task_id:django.request][log.py:228][ERROR][Internal Server Error: /api2/admin/login/]
Traceback (most recent call last):
  File "/root/site/xiao2Blog/server/venv/lib/python3.6/site-packages/django/db/backends/utils.py", line 84, in _execute
    return self.cursor.execute(sql, params)
  File "/root/site/xiao2Blog/server/venv/lib/python3.6/site-packages/django/db/backends/mysql/base.py", line 71, in execute
    return self.cursor.execute(query, args)
  File "/root/site/xiao2Blog/server/venv/lib/python3.6/site-packages/pymysql/cursors.py", line 170, in execute
    result = self._query(query)
  File "/root/site/xiao2Blog/server/venv/lib/python3.6/site-packages/pymysql/cursors.py", line 328, in _query
    conn.query(q)
  File "/root/site/xiao2Blog/server/venv/lib/python3.6/site-packages/pymysql/connections.py", line 517, in query
    self._affected_rows = self._read_query_result(unbuffered=unbuffered)
  File "/root/site/xiao2Blog/server/venv/lib/python3.6/site-packages/pymysql/connections.py", line 732, in _read_query_result
    result.read()
  File "/root/site/xiao2Blog/server/venv/lib/python3.6/site-packages/pymysql/connections.py", line 1075, in read
    first_packet = self.connection._read_packet()
  File "/root/site/xiao2Blog/server/venv/lib/python3.6/site-packages/pymysql/connections.py", line 684, in _read_packet
    packet.check_error()
  File "/root/site/xiao2Blog/server/venv/lib/python3.6/site-packages/pymysql/protocol.py", line 220, in check_error
    err.raise_mysql_exception(self._data)
  File "/root/site/xiao2Blog/server/venv/lib/python3.6/site-packages/pymysql/err.py", line 109, in raise_mysql_exception
    raise errorclass(errno, errval)
pymysql.err.ProgrammingError: (1146, "Table 'blog2.django_session' doesn't exist")

The above exception was the direct cause of the following exception:

Traceback (most recent call last):
  File "/root/site/xiao2Blog/server/venv/lib/python3.6/site-packages/django/core/handlers/exception.py", line 34, in inner
    response = get_response(request)
  File "/root/site/xiao2Blog/server/venv/lib/python3.6/site-packages/django/core/handlers/base.py", line 115, in _get_response
    response = self.process_exception_by_middleware(e, request)
  File "/root/site/xiao2Blog/server/venv/lib/python3.6/site-packages/django/core/handlers/base.py", line 113, in _get_response
    response = wrapped_callback(request, *callback_args, **callback_kwargs)
  File "/root/site/xiao2Blog/server/venv/lib/python3.6/site-packages/django/views/decorators/cache.py", line 44, in _wrapped_view_func
    response = view_func(request, *args, **kwargs)
  File "/root/site/xiao2Blog/server/venv/lib/python3.6/site-packages/django/contrib/admin/sites.py", line 399, in login
    return LoginView.as_view(**defaults)(request)
  File "/root/site/xiao2Blog/server/venv/lib/python3.6/site-packages/django/views/generic/base.py", line 71, in view
    return self.dispatch(request, *args, **kwargs)
  File "/root/site/xiao2Blog/server/venv/lib/python3.6/site-packages/django/utils/decorators.py", line 45, in _wrapper
    return bound_method(*args, **kwargs)
  File "/root/site/xiao2Blog/server/venv/lib/python3.6/site-packages/django/views/decorators/debug.py", line 76, in sensitive_post_parameters_wrapper
    return view(request, *args, **kwargs)
  File "/root/site/xiao2Blog/server/venv/lib/python3.6/site-packages/django/utils/decorators.py", line 45, in _wrapper
    return bound_method(*args, **kwargs)
  File "/root/site/xiao2Blog/server/venv/lib/python3.6/site-packages/django/utils/decorators.py", line 142, in _wrapped_view
    response = view_func(request, *args, **kwargs)
  File "/root/site/xiao2Blog/server/venv/lib/python3.6/site-packages/django/utils/decorators.py", line 45, in _wrapper
    return bound_method(*args, **kwargs)
  File "/root/site/xiao2Blog/server/venv/lib/python3.6/site-packages/django/views/decorators/cache.py", line 44, in _wrapped_view_func
    response = view_func(request, *args, **kwargs)
  File "/root/site/xiao2Blog/server/venv/lib/python3.6/site-packages/django/contrib/auth/views.py", line 61, in dispatch
    return super().dispatch(request, *args, **kwargs)
  File "/root/site/xiao2Blog/server/venv/lib/python3.6/site-packages/django/views/generic/base.py", line 97, in dispatch
    return handler(request, *args, **kwargs)
  File "/root/site/xiao2Blog/server/venv/lib/python3.6/site-packages/django/views/generic/edit.py", line 142, in post
    return self.form_valid(form)
  File "/root/site/xiao2Blog/server/venv/lib/python3.6/site-packages/django/contrib/auth/views.py", line 90, in form_valid
    auth_login(self.request, form.get_user())
  File "/root/site/xiao2Blog/server/venv/lib/python3.6/site-packages/django/contrib/auth/__init__.py", line 108, in login
    request.session.cycle_key()
  File "/root/site/xiao2Blog/server/venv/lib/python3.6/site-packages/django/contrib/sessions/backends/base.py", line 297, in cycle_key
    self.create()
  File "/root/site/xiao2Blog/server/venv/lib/python3.6/site-packages/django/contrib/sessions/backends/db.py", line 51, in create
    self._session_key = self._get_new_session_key()
  File "/root/site/xiao2Blog/server/venv/lib/python3.6/site-packages/django/contrib/sessions/backends/base.py", line 152, in _get_new_session_key
    if not self.exists(session_key):
  File "/root/site/xiao2Blog/server/venv/lib/python3.6/site-packages/django/contrib/sessions/backends/db.py", line 47, in exists
    return self.model.objects.filter(session_key=session_key).exists()
  File "/root/site/xiao2Blog/server/venv/lib/python3.6/site-packages/django/db/models/query.py", line 766, in exists
    return self.query.has_results(using=self.db)
  File "/root/site/xiao2Blog/server/venv/lib/python3.6/site-packages/django/db/models/sql/query.py", line 522, in has_results
    return compiler.has_results()
  File "/root/site/xiao2Blog/server/venv/lib/python3.6/site-packages/django/db/models/sql/compiler.py", line 1070, in has_results
    return bool(self.execute_sql(SINGLE))
  File "/root/site/xiao2Blog/server/venv/lib/python3.6/site-packages/django/db/models/sql/compiler.py", line 1100, in execute_sql
    cursor.execute(sql, params)
  File "/root/site/xiao2Blog/server/venv/lib/python3.6/site-packages/django/db/backends/utils.py", line 67, in execute
    return self._execute_with_wrappers(sql, params, many=False, executor=self._execute)
  File "/root/site/xiao2Blog/server/venv/lib/python3.6/site-packages/django/db/backends/utils.py", line 76, in _execute_with_wrappers
    return executor(sql, params, many, context)
  File "/root/site/xiao2Blog/server/venv/lib/python3.6/site-packages/django/db/backends/utils.py", line 84, in _execute
    return self.cursor.execute(sql, params)
  File "/root/site/xiao2Blog/server/venv/lib/python3.6/site-packages/django/db/utils.py", line 89, in __exit__
    raise dj_exc_value.with_traceback(traceback) from exc_value
  File "/root/site/xiao2Blog/server/venv/lib/python3.6/site-packages/django/db/backends/utils.py", line 84, in _execute
    return self.cursor.execute(sql, params)
  File "/root/site/xiao2Blog/server/venv/lib/python3.6/site-packages/django/db/backends/mysql/base.py", line 71, in execute
    return self.cursor.execute(query, args)
  File "/root/site/xiao2Blog/server/venv/lib/python3.6/site-packages/pymysql/cursors.py", line 170, in execute
    result = self._query(query)
  File "/root/site/xiao2Blog/server/venv/lib/python3.6/site-packages/pymysql/cursors.py", line 328, in _query
    conn.query(q)
  File "/root/site/xiao2Blog/server/venv/lib/python3.6/site-packages/pymysql/connections.py", line 517, in query
    self._affected_rows = self._read_query_result(unbuffered=unbuffered)
  File "/root/site/xiao2Blog/server/venv/lib/python3.6/site-packages/pymysql/connections.py", line 732, in _read_query_result
    result.read()
  File "/root/site/xiao2Blog/server/venv/lib/python3.6/site-packages/pymysql/connections.py", line 1075, in read
    first_packet = self.connection._read_packet()
  File "/root/site/xiao2Blog/server/venv/lib/python3.6/site-packages/pymysql/connections.py", line 684, in _read_packet
    packet.check_error()
  File "/root/site/xiao2Blog/server/venv/lib/python3.6/site-packages/pymysql/protocol.py", line 220, in check_error
    err.raise_mysql_exception(self._data)
  File "/root/site/xiao2Blog/server/venv/lib/python3.6/site-packages/pymysql/err.py", line 109, in raise_mysql_exception
    raise errorclass(errno, errval)
django.db.utils.ProgrammingError: (1146, "Table 'blog2.django_session' doesn't exist")
[2019-11-25 16:34:19,737][uWSGIWorker1Core0:140056096737344][task_id:django.request][log.py:228][ERROR][Internal Server Error: /api2/admin/login/]
Traceback (most recent call last):
  File "/root/site/xiao2Blog/server/venv/lib/python3.6/site-packages/django/db/backends/utils.py", line 84, in _execute
    return self.cursor.execute(sql, params)
  File "/root/site/xiao2Blog/server/venv/lib/python3.6/site-packages/django/db/backends/mysql/base.py", line 71, in execute
    return self.cursor.execute(query, args)
  File "/root/site/xiao2Blog/server/venv/lib/python3.6/site-packages/pymysql/cursors.py", line 170, in execute
    result = self._query(query)
  File "/root/site/xiao2Blog/server/venv/lib/python3.6/site-packages/pymysql/cursors.py", line 328, in _query
    conn.query(q)
  File "/root/site/xiao2Blog/server/venv/lib/python3.6/site-packages/pymysql/connections.py", line 517, in query
    self._affected_rows = self._read_query_result(unbuffered=unbuffered)
  File "/root/site/xiao2Blog/server/venv/lib/python3.6/site-packages/pymysql/connections.py", line 732, in _read_query_result
    result.read()
  File "/root/site/xiao2Blog/server/venv/lib/python3.6/site-packages/pymysql/connections.py", line 1075, in read
    first_packet = self.connection._read_packet()
  File "/root/site/xiao2Blog/server/venv/lib/python3.6/site-packages/pymysql/connections.py", line 684, in _read_packet
    packet.check_error()
  File "/root/site/xiao2Blog/server/venv/lib/python3.6/site-packages/pymysql/protocol.py", line 220, in check_error
    err.raise_mysql_exception(self._data)
  File "/root/site/xiao2Blog/server/venv/lib/python3.6/site-packages/pymysql/err.py", line 109, in raise_mysql_exception
    raise errorclass(errno, errval)
pymysql.err.ProgrammingError: (1146, "Table 'blog2.django_session' doesn't exist")

The above exception was the direct cause of the following exception:

Traceback (most recent call last):
  File "/root/site/xiao2Blog/server/venv/lib/python3.6/site-packages/django/core/handlers/exception.py", line 34, in inner
    response = get_response(request)
  File "/root/site/xiao2Blog/server/venv/lib/python3.6/site-packages/django/core/handlers/base.py", line 115, in _get_response
    response = self.process_exception_by_middleware(e, request)
  File "/root/site/xiao2Blog/server/venv/lib/python3.6/site-packages/django/core/handlers/base.py", line 113, in _get_response
    response = wrapped_callback(request, *callback_args, **callback_kwargs)
  File "/root/site/xiao2Blog/server/venv/lib/python3.6/site-packages/django/views/decorators/cache.py", line 44, in _wrapped_view_func
    response = view_func(request, *args, **kwargs)
  File "/root/site/xiao2Blog/server/venv/lib/python3.6/site-packages/django/contrib/admin/sites.py", line 399, in login
    return LoginView.as_view(**defaults)(request)
  File "/root/site/xiao2Blog/server/venv/lib/python3.6/site-packages/django/views/generic/base.py", line 71, in view
    return self.dispatch(request, *args, **kwargs)
  File "/root/site/xiao2Blog/server/venv/lib/python3.6/site-packages/django/utils/decorators.py", line 45, in _wrapper
    return bound_method(*args, **kwargs)
  File "/root/site/xiao2Blog/server/venv/lib/python3.6/site-packages/django/views/decorators/debug.py", line 76, in sensitive_post_parameters_wrapper
    return view(request, *args, **kwargs)
  File "/root/site/xiao2Blog/server/venv/lib/python3.6/site-packages/django/utils/decorators.py", line 45, in _wrapper
    return bound_method(*args, **kwargs)
  File "/root/site/xiao2Blog/server/venv/lib/python3.6/site-packages/django/utils/decorators.py", line 142, in _wrapped_view
    response = view_func(request, *args, **kwargs)
  File "/root/site/xiao2Blog/server/venv/lib/python3.6/site-packages/django/utils/decorators.py", line 45, in _wrapper
    return bound_method(*args, **kwargs)
  File "/root/site/xiao2Blog/server/venv/lib/python3.6/site-packages/django/views/decorators/cache.py", line 44, in _wrapped_view_func
    response = view_func(request, *args, **kwargs)
  File "/root/site/xiao2Blog/server/venv/lib/python3.6/site-packages/django/contrib/auth/views.py", line 61, in dispatch
    return super().dispatch(request, *args, **kwargs)
  File "/root/site/xiao2Blog/server/venv/lib/python3.6/site-packages/django/views/generic/base.py", line 97, in dispatch
    return handler(request, *args, **kwargs)
  File "/root/site/xiao2Blog/server/venv/lib/python3.6/site-packages/django/views/generic/edit.py", line 142, in post
    return self.form_valid(form)
  File "/root/site/xiao2Blog/server/venv/lib/python3.6/site-packages/django/contrib/auth/views.py", line 90, in form_valid
    auth_login(self.request, form.get_user())
  File "/root/site/xiao2Blog/server/venv/lib/python3.6/site-packages/django/contrib/auth/__init__.py", line 108, in login
    request.session.cycle_key()
  File "/root/site/xiao2Blog/server/venv/lib/python3.6/site-packages/django/contrib/sessions/backends/base.py", line 297, in cycle_key
    self.create()
  File "/root/site/xiao2Blog/server/venv/lib/python3.6/site-packages/django/contrib/sessions/backends/db.py", line 51, in create
    self._session_key = self._get_new_session_key()
  File "/root/site/xiao2Blog/server/venv/lib/python3.6/site-packages/django/contrib/sessions/backends/base.py", line 152, in _get_new_session_key
    if not self.exists(session_key):
  File "/root/site/xiao2Blog/server/venv/lib/python3.6/site-packages/django/contrib/sessions/backends/db.py", line 47, in exists
    return self.model.objects.filter(session_key=session_key).exists()
  File "/root/site/xiao2Blog/server/venv/lib/python3.6/site-packages/django/db/models/query.py", line 766, in exists
    return self.query.has_results(using=self.db)
  File "/root/site/xiao2Blog/server/venv/lib/python3.6/site-packages/django/db/models/sql/query.py", line 522, in has_results
    return compiler.has_results()
  File "/root/site/xiao2Blog/server/venv/lib/python3.6/site-packages/django/db/models/sql/compiler.py", line 1070, in has_results
    return bool(self.execute_sql(SINGLE))
  File "/root/site/xiao2Blog/server/venv/lib/python3.6/site-packages/django/db/models/sql/compiler.py", line 1100, in execute_sql
    cursor.execute(sql, params)
  File "/root/site/xiao2Blog/server/venv/lib/python3.6/site-packages/django/db/backends/utils.py", line 67, in execute
    return self._execute_with_wrappers(sql, params, many=False, executor=self._execute)
  File "/root/site/xiao2Blog/server/venv/lib/python3.6/site-packages/django/db/backends/utils.py", line 76, in _execute_with_wrappers
    return executor(sql, params, many, context)
  File "/root/site/xiao2Blog/server/venv/lib/python3.6/site-packages/django/db/backends/utils.py", line 84, in _execute
    return self.cursor.execute(sql, params)
  File "/root/site/xiao2Blog/server/venv/lib/python3.6/site-packages/django/db/utils.py", line 89, in __exit__
    raise dj_exc_value.with_traceback(traceback) from exc_value
  File "/root/site/xiao2Blog/server/venv/lib/python3.6/site-packages/django/db/backends/utils.py", line 84, in _execute
    return self.cursor.execute(sql, params)
  File "/root/site/xiao2Blog/server/venv/lib/python3.6/site-packages/django/db/backends/mysql/base.py", line 71, in execute
    return self.cursor.execute(query, args)
  File "/root/site/xiao2Blog/server/venv/lib/python3.6/site-packages/pymysql/cursors.py", line 170, in execute
    result = self._query(query)
  File "/root/site/xiao2Blog/server/venv/lib/python3.6/site-packages/pymysql/cursors.py", line 328, in _query
    conn.query(q)
  File "/root/site/xiao2Blog/server/venv/lib/python3.6/site-packages/pymysql/connections.py", line 517, in query
    self._affected_rows = self._read_query_result(unbuffered=unbuffered)
  File "/root/site/xiao2Blog/server/venv/lib/python3.6/site-packages/pymysql/connections.py", line 732, in _read_query_result
    result.read()
  File "/root/site/xiao2Blog/server/venv/lib/python3.6/site-packages/pymysql/connections.py", line 1075, in read
    first_packet = self.connection._read_packet()
  File "/root/site/xiao2Blog/server/venv/lib/python3.6/site-packages/pymysql/connections.py", line 684, in _read_packet
    packet.check_error()
  File "/root/site/xiao2Blog/server/venv/lib/python3.6/site-packages/pymysql/protocol.py", line 220, in check_error
    err.raise_mysql_exception(self._data)
  File "/root/site/xiao2Blog/server/venv/lib/python3.6/site-packages/pymysql/err.py", line 109, in raise_mysql_exception
    raise errorclass(errno, errval)
django.db.utils.ProgrammingError: (1146, "Table 'blog2.django_session' doesn't exist")
[2019-11-25 16:34:58,240][uWSGIWorker1Core0:140056096737344][task_id:django.request][log.py:228][ERROR][Internal Server Error: /api2/admin/login/]
Traceback (most recent call last):
  File "/root/site/xiao2Blog/server/venv/lib/python3.6/site-packages/django/db/backends/utils.py", line 84, in _execute
    return self.cursor.execute(sql, params)
  File "/root/site/xiao2Blog/server/venv/lib/python3.6/site-packages/django/db/backends/mysql/base.py", line 71, in execute
    return self.cursor.execute(query, args)
  File "/root/site/xiao2Blog/server/venv/lib/python3.6/site-packages/pymysql/cursors.py", line 170, in execute
    result = self._query(query)
  File "/root/site/xiao2Blog/server/venv/lib/python3.6/site-packages/pymysql/cursors.py", line 328, in _query
    conn.query(q)
  File "/root/site/xiao2Blog/server/venv/lib/python3.6/site-packages/pymysql/connections.py", line 517, in query
    self._affected_rows = self._read_query_result(unbuffered=unbuffered)
  File "/root/site/xiao2Blog/server/venv/lib/python3.6/site-packages/pymysql/connections.py", line 732, in _read_query_result
    result.read()
  File "/root/site/xiao2Blog/server/venv/lib/python3.6/site-packages/pymysql/connections.py", line 1075, in read
    first_packet = self.connection._read_packet()
  File "/root/site/xiao2Blog/server/venv/lib/python3.6/site-packages/pymysql/connections.py", line 684, in _read_packet
    packet.check_error()
  File "/root/site/xiao2Blog/server/venv/lib/python3.6/site-packages/pymysql/protocol.py", line 220, in check_error
    err.raise_mysql_exception(self._data)
  File "/root/site/xiao2Blog/server/venv/lib/python3.6/site-packages/pymysql/err.py", line 109, in raise_mysql_exception
    raise errorclass(errno, errval)
pymysql.err.ProgrammingError: (1146, "Table 'blog2.django_session' doesn't exist")

The above exception was the direct cause of the following exception:

Traceback (most recent call last):
  File "/root/site/xiao2Blog/server/venv/lib/python3.6/site-packages/django/core/handlers/exception.py", line 34, in inner
    response = get_response(request)
  File "/root/site/xiao2Blog/server/venv/lib/python3.6/site-packages/django/core/handlers/base.py", line 115, in _get_response
    response = self.process_exception_by_middleware(e, request)
  File "/root/site/xiao2Blog/server/venv/lib/python3.6/site-packages/django/core/handlers/base.py", line 113, in _get_response
    response = wrapped_callback(request, *callback_args, **callback_kwargs)
  File "/root/site/xiao2Blog/server/venv/lib/python3.6/site-packages/django/views/decorators/cache.py", line 44, in _wrapped_view_func
    response = view_func(request, *args, **kwargs)
  File "/root/site/xiao2Blog/server/venv/lib/python3.6/site-packages/django/contrib/admin/sites.py", line 399, in login
    return LoginView.as_view(**defaults)(request)
  File "/root/site/xiao2Blog/server/venv/lib/python3.6/site-packages/django/views/generic/base.py", line 71, in view
    return self.dispatch(request, *args, **kwargs)
  File "/root/site/xiao2Blog/server/venv/lib/python3.6/site-packages/django/utils/decorators.py", line 45, in _wrapper
    return bound_method(*args, **kwargs)
  File "/root/site/xiao2Blog/server/venv/lib/python3.6/site-packages/django/views/decorators/debug.py", line 76, in sensitive_post_parameters_wrapper
    return view(request, *args, **kwargs)
  File "/root/site/xiao2Blog/server/venv/lib/python3.6/site-packages/django/utils/decorators.py", line 45, in _wrapper
    return bound_method(*args, **kwargs)
  File "/root/site/xiao2Blog/server/venv/lib/python3.6/site-packages/django/utils/decorators.py", line 142, in _wrapped_view
    response = view_func(request, *args, **kwargs)
  File "/root/site/xiao2Blog/server/venv/lib/python3.6/site-packages/django/utils/decorators.py", line 45, in _wrapper
    return bound_method(*args, **kwargs)
  File "/root/site/xiao2Blog/server/venv/lib/python3.6/site-packages/django/views/decorators/cache.py", line 44, in _wrapped_view_func
    response = view_func(request, *args, **kwargs)
  File "/root/site/xiao2Blog/server/venv/lib/python3.6/site-packages/django/contrib/auth/views.py", line 61, in dispatch
    return super().dispatch(request, *args, **kwargs)
  File "/root/site/xiao2Blog/server/venv/lib/python3.6/site-packages/django/views/generic/base.py", line 97, in dispatch
    return handler(request, *args, **kwargs)
  File "/root/site/xiao2Blog/server/venv/lib/python3.6/site-packages/django/views/generic/edit.py", line 142, in post
    return self.form_valid(form)
  File "/root/site/xiao2Blog/server/venv/lib/python3.6/site-packages/django/contrib/auth/views.py", line 90, in form_valid
    auth_login(self.request, form.get_user())
  File "/root/site/xiao2Blog/server/venv/lib/python3.6/site-packages/django/contrib/auth/__init__.py", line 108, in login
    request.session.cycle_key()
  File "/root/site/xiao2Blog/server/venv/lib/python3.6/site-packages/django/contrib/sessions/backends/base.py", line 297, in cycle_key
    self.create()
  File "/root/site/xiao2Blog/server/venv/lib/python3.6/site-packages/django/contrib/sessions/backends/db.py", line 51, in create
    self._session_key = self._get_new_session_key()
  File "/root/site/xiao2Blog/server/venv/lib/python3.6/site-packages/django/contrib/sessions/backends/base.py", line 152, in _get_new_session_key
    if not self.exists(session_key):
  File "/root/site/xiao2Blog/server/venv/lib/python3.6/site-packages/django/contrib/sessions/backends/db.py", line 47, in exists
    return self.model.objects.filter(session_key=session_key).exists()
  File "/root/site/xiao2Blog/server/venv/lib/python3.6/site-packages/django/db/models/query.py", line 766, in exists
    return self.query.has_results(using=self.db)
  File "/root/site/xiao2Blog/server/venv/lib/python3.6/site-packages/django/db/models/sql/query.py", line 522, in has_results
    return compiler.has_results()
  File "/root/site/xiao2Blog/server/venv/lib/python3.6/site-packages/django/db/models/sql/compiler.py", line 1070, in has_results
    return bool(self.execute_sql(SINGLE))
  File "/root/site/xiao2Blog/server/venv/lib/python3.6/site-packages/django/db/models/sql/compiler.py", line 1100, in execute_sql
    cursor.execute(sql, params)
  File "/root/site/xiao2Blog/server/venv/lib/python3.6/site-packages/django/db/backends/utils.py", line 67, in execute
    return self._execute_with_wrappers(sql, params, many=False, executor=self._execute)
  File "/root/site/xiao2Blog/server/venv/lib/python3.6/site-packages/django/db/backends/utils.py", line 76, in _execute_with_wrappers
    return executor(sql, params, many, context)
  File "/root/site/xiao2Blog/server/venv/lib/python3.6/site-packages/django/db/backends/utils.py", line 84, in _execute
    return self.cursor.execute(sql, params)
  File "/root/site/xiao2Blog/server/venv/lib/python3.6/site-packages/django/db/utils.py", line 89, in __exit__
    raise dj_exc_value.with_traceback(traceback) from exc_value
  File "/root/site/xiao2Blog/server/venv/lib/python3.6/site-packages/django/db/backends/utils.py", line 84, in _execute
    return self.cursor.execute(sql, params)
  File "/root/site/xiao2Blog/server/venv/lib/python3.6/site-packages/django/db/backends/mysql/base.py", line 71, in execute
    return self.cursor.execute(query, args)
  File "/root/site/xiao2Blog/server/venv/lib/python3.6/site-packages/pymysql/cursors.py", line 170, in execute
    result = self._query(query)
  File "/root/site/xiao2Blog/server/venv/lib/python3.6/site-packages/pymysql/cursors.py", line 328, in _query
    conn.query(q)
  File "/root/site/xiao2Blog/server/venv/lib/python3.6/site-packages/pymysql/connections.py", line 517, in query
    self._affected_rows = self._read_query_result(unbuffered=unbuffered)
  File "/root/site/xiao2Blog/server/venv/lib/python3.6/site-packages/pymysql/connections.py", line 732, in _read_query_result
    result.read()
  File "/root/site/xiao2Blog/server/venv/lib/python3.6/site-packages/pymysql/connections.py", line 1075, in read
    first_packet = self.connection._read_packet()
  File "/root/site/xiao2Blog/server/venv/lib/python3.6/site-packages/pymysql/connections.py", line 684, in _read_packet
    packet.check_error()
  File "/root/site/xiao2Blog/server/venv/lib/python3.6/site-packages/pymysql/protocol.py", line 220, in check_error
    err.raise_mysql_exception(self._data)
  File "/root/site/xiao2Blog/server/venv/lib/python3.6/site-packages/pymysql/err.py", line 109, in raise_mysql_exception
    raise errorclass(errno, errval)
django.db.utils.ProgrammingError: (1146, "Table 'blog2.django_session' doesn't exist")
[2019-11-25 16:38:55,924][uWSGIWorker1Core0:140056096737344][task_id:django.request][log.py:228][ERROR][Internal Server Error: /api2/admin/login/]
Traceback (most recent call last):
  File "/root/site/xiao2Blog/server/venv/lib/python3.6/site-packages/django/db/backends/utils.py", line 84, in _execute
    return self.cursor.execute(sql, params)
  File "/root/site/xiao2Blog/server/venv/lib/python3.6/site-packages/django/db/backends/mysql/base.py", line 71, in execute
    return self.cursor.execute(query, args)
  File "/root/site/xiao2Blog/server/venv/lib/python3.6/site-packages/pymysql/cursors.py", line 170, in execute
    result = self._query(query)
  File "/root/site/xiao2Blog/server/venv/lib/python3.6/site-packages/pymysql/cursors.py", line 328, in _query
    conn.query(q)
  File "/root/site/xiao2Blog/server/venv/lib/python3.6/site-packages/pymysql/connections.py", line 517, in query
    self._affected_rows = self._read_query_result(unbuffered=unbuffered)
  File "/root/site/xiao2Blog/server/venv/lib/python3.6/site-packages/pymysql/connections.py", line 732, in _read_query_result
    result.read()
  File "/root/site/xiao2Blog/server/venv/lib/python3.6/site-packages/pymysql/connections.py", line 1075, in read
    first_packet = self.connection._read_packet()
  File "/root/site/xiao2Blog/server/venv/lib/python3.6/site-packages/pymysql/connections.py", line 684, in _read_packet
    packet.check_error()
  File "/root/site/xiao2Blog/server/venv/lib/python3.6/site-packages/pymysql/protocol.py", line 220, in check_error
    err.raise_mysql_exception(self._data)
  File "/root/site/xiao2Blog/server/venv/lib/python3.6/site-packages/pymysql/err.py", line 109, in raise_mysql_exception
    raise errorclass(errno, errval)
pymysql.err.ProgrammingError: (1146, "Table 'blog2.django_session' doesn't exist")

The above exception was the direct cause of the following exception:

Traceback (most recent call last):
  File "/root/site/xiao2Blog/server/venv/lib/python3.6/site-packages/django/core/handlers/exception.py", line 34, in inner
    response = get_response(request)
  File "/root/site/xiao2Blog/server/venv/lib/python3.6/site-packages/django/core/handlers/base.py", line 115, in _get_response
    response = self.process_exception_by_middleware(e, request)
  File "/root/site/xiao2Blog/server/venv/lib/python3.6/site-packages/django/core/handlers/base.py", line 113, in _get_response
    response = wrapped_callback(request, *callback_args, **callback_kwargs)
  File "/root/site/xiao2Blog/server/venv/lib/python3.6/site-packages/django/views/decorators/cache.py", line 44, in _wrapped_view_func
    response = view_func(request, *args, **kwargs)
  File "/root/site/xiao2Blog/server/venv/lib/python3.6/site-packages/django/contrib/admin/sites.py", line 399, in login
    return LoginView.as_view(**defaults)(request)
  File "/root/site/xiao2Blog/server/venv/lib/python3.6/site-packages/django/views/generic/base.py", line 71, in view
    return self.dispatch(request, *args, **kwargs)
  File "/root/site/xiao2Blog/server/venv/lib/python3.6/site-packages/django/utils/decorators.py", line 45, in _wrapper
    return bound_method(*args, **kwargs)
  File "/root/site/xiao2Blog/server/venv/lib/python3.6/site-packages/django/views/decorators/debug.py", line 76, in sensitive_post_parameters_wrapper
    return view(request, *args, **kwargs)
  File "/root/site/xiao2Blog/server/venv/lib/python3.6/site-packages/django/utils/decorators.py", line 45, in _wrapper
    return bound_method(*args, **kwargs)
  File "/root/site/xiao2Blog/server/venv/lib/python3.6/site-packages/django/utils/decorators.py", line 142, in _wrapped_view
    response = view_func(request, *args, **kwargs)
  File "/root/site/xiao2Blog/server/venv/lib/python3.6/site-packages/django/utils/decorators.py", line 45, in _wrapper
    return bound_method(*args, **kwargs)
  File "/root/site/xiao2Blog/server/venv/lib/python3.6/site-packages/django/views/decorators/cache.py", line 44, in _wrapped_view_func
    response = view_func(request, *args, **kwargs)
  File "/root/site/xiao2Blog/server/venv/lib/python3.6/site-packages/django/contrib/auth/views.py", line 61, in dispatch
    return super().dispatch(request, *args, **kwargs)
  File "/root/site/xiao2Blog/server/venv/lib/python3.6/site-packages/django/views/generic/base.py", line 97, in dispatch
    return handler(request, *args, **kwargs)
  File "/root/site/xiao2Blog/server/venv/lib/python3.6/site-packages/django/views/generic/edit.py", line 142, in post
    return self.form_valid(form)
  File "/root/site/xiao2Blog/server/venv/lib/python3.6/site-packages/django/contrib/auth/views.py", line 90, in form_valid
    auth_login(self.request, form.get_user())
  File "/root/site/xiao2Blog/server/venv/lib/python3.6/site-packages/django/contrib/auth/__init__.py", line 108, in login
    request.session.cycle_key()
  File "/root/site/xiao2Blog/server/venv/lib/python3.6/site-packages/django/contrib/sessions/backends/base.py", line 297, in cycle_key
    self.create()
  File "/root/site/xiao2Blog/server/venv/lib/python3.6/site-packages/django/contrib/sessions/backends/db.py", line 51, in create
    self._session_key = self._get_new_session_key()
  File "/root/site/xiao2Blog/server/venv/lib/python3.6/site-packages/django/contrib/sessions/backends/base.py", line 152, in _get_new_session_key
    if not self.exists(session_key):
  File "/root/site/xiao2Blog/server/venv/lib/python3.6/site-packages/django/contrib/sessions/backends/db.py", line 47, in exists
    return self.model.objects.filter(session_key=session_key).exists()
  File "/root/site/xiao2Blog/server/venv/lib/python3.6/site-packages/django/db/models/query.py", line 766, in exists
    return self.query.has_results(using=self.db)
  File "/root/site/xiao2Blog/server/venv/lib/python3.6/site-packages/django/db/models/sql/query.py", line 522, in has_results
    return compiler.has_results()
  File "/root/site/xiao2Blog/server/venv/lib/python3.6/site-packages/django/db/models/sql/compiler.py", line 1070, in has_results
    return bool(self.execute_sql(SINGLE))
  File "/root/site/xiao2Blog/server/venv/lib/python3.6/site-packages/django/db/models/sql/compiler.py", line 1100, in execute_sql
    cursor.execute(sql, params)
  File "/root/site/xiao2Blog/server/venv/lib/python3.6/site-packages/django/db/backends/utils.py", line 67, in execute
    return self._execute_with_wrappers(sql, params, many=False, executor=self._execute)
  File "/root/site/xiao2Blog/server/venv/lib/python3.6/site-packages/django/db/backends/utils.py", line 76, in _execute_with_wrappers
    return executor(sql, params, many, context)
  File "/root/site/xiao2Blog/server/venv/lib/python3.6/site-packages/django/db/backends/utils.py", line 84, in _execute
    return self.cursor.execute(sql, params)
  File "/root/site/xiao2Blog/server/venv/lib/python3.6/site-packages/django/db/utils.py", line 89, in __exit__
    raise dj_exc_value.with_traceback(traceback) from exc_value
  File "/root/site/xiao2Blog/server/venv/lib/python3.6/site-packages/django/db/backends/utils.py", line 84, in _execute
    return self.cursor.execute(sql, params)
  File "/root/site/xiao2Blog/server/venv/lib/python3.6/site-packages/django/db/backends/mysql/base.py", line 71, in execute
    return self.cursor.execute(query, args)
  File "/root/site/xiao2Blog/server/venv/lib/python3.6/site-packages/pymysql/cursors.py", line 170, in execute
    result = self._query(query)
  File "/root/site/xiao2Blog/server/venv/lib/python3.6/site-packages/pymysql/cursors.py", line 328, in _query
    conn.query(q)
  File "/root/site/xiao2Blog/server/venv/lib/python3.6/site-packages/pymysql/connections.py", line 517, in query
    self._affected_rows = self._read_query_result(unbuffered=unbuffered)
  File "/root/site/xiao2Blog/server/venv/lib/python3.6/site-packages/pymysql/connections.py", line 732, in _read_query_result
    result.read()
  File "/root/site/xiao2Blog/server/venv/lib/python3.6/site-packages/pymysql/connections.py", line 1075, in read
    first_packet = self.connection._read_packet()
  File "/root/site/xiao2Blog/server/venv/lib/python3.6/site-packages/pymysql/connections.py", line 684, in _read_packet
    packet.check_error()
  File "/root/site/xiao2Blog/server/venv/lib/python3.6/site-packages/pymysql/protocol.py", line 220, in check_error
    err.raise_mysql_exception(self._data)
  File "/root/site/xiao2Blog/server/venv/lib/python3.6/site-packages/pymysql/err.py", line 109, in raise_mysql_exception
    raise errorclass(errno, errval)
django.db.utils.ProgrammingError: (1146, "Table 'blog2.django_session' doesn't exist")
