[2019-11-25 16:20:13,940][uWSGIWorker1Core0:140377544300608][task_id:django.request][log.py:228][ERROR][Internal Server Error: /api2/api/articleList/]
Traceback (most recent call last):
  File "/root/site/xiao2Blog/server/venv/lib/python3.6/site-packages/django/core/handlers/exception.py", line 34, in inner
    response = get_response(request)
  File "/root/site/xiao2Blog/server/venv/lib/python3.6/site-packages/django/core/handlers/base.py", line 145, in _get_response
    response = self.process_exception_by_middleware(e, request)
  File "/root/site/xiao2Blog/server/venv/lib/python3.6/site-packages/django/core/handlers/base.py", line 143, in _get_response
    response = response.render()
  File "/root/site/xiao2Blog/server/venv/lib/python3.6/site-packages/django/template/response.py", line 106, in render
    self.content = self.rendered_content
  File "/root/site/xiao2Blog/server/venv/lib/python3.6/site-packages/rest_framework/response.py", line 70, in rendered_content
    ret = renderer.render(self.data, accepted_media_type, context)
  File "/root/site/xiao2Blog/server/venv/lib/python3.6/site-packages/rest_framework/renderers.py", line 726, in render
    ret = template.render(context, request=renderer_context['request'])
  File "/root/site/xiao2Blog/server/venv/lib/python3.6/site-packages/django/template/backends/django.py", line 61, in render
    return self.template.render(context)
  File "/root/site/xiao2Blog/server/venv/lib/python3.6/site-packages/django/template/base.py", line 171, in render
    return self._render(context)
  File "/root/site/xiao2Blog/server/venv/lib/python3.6/site-packages/django/template/base.py", line 163, in _render
    return self.nodelist.render(context)
  File "/root/site/xiao2Blog/server/venv/lib/python3.6/site-packages/django/template/base.py", line 937, in render
    bit = node.render_annotated(context)
  File "/root/site/xiao2Blog/server/venv/lib/python3.6/site-packages/django/template/base.py", line 904, in render_annotated
    return self.render(context)
  File "/root/site/xiao2Blog/server/venv/lib/python3.6/site-packages/django/template/loader_tags.py", line 150, in render
    return compiled_parent._render(context)
  File "/root/site/xiao2Blog/server/venv/lib/python3.6/site-packages/django/template/base.py", line 163, in _render
    return self.nodelist.render(context)
  File "/root/site/xiao2Blog/server/venv/lib/python3.6/site-packages/django/template/base.py", line 937, in render
    bit = node.render_annotated(context)
  File "/root/site/xiao2Blog/server/venv/lib/python3.6/site-packages/django/template/base.py", line 904, in render_annotated
    return self.render(context)
  File "/root/site/xiao2Blog/server/venv/lib/python3.6/site-packages/django/template/loader_tags.py", line 62, in render
    result = block.nodelist.render(context)
  File "/root/site/xiao2Blog/server/venv/lib/python3.6/site-packages/django/template/base.py", line 937, in render
    bit = node.render_annotated(context)
  File "/root/site/xiao2Blog/server/venv/lib/python3.6/site-packages/django/template/base.py", line 904, in render_annotated
    return self.render(context)
  File "/root/site/xiao2Blog/server/venv/lib/python3.6/site-packages/django/template/loader_tags.py", line 62, in render
    result = block.nodelist.render(context)
  File "/root/site/xiao2Blog/server/venv/lib/python3.6/site-packages/django/template/base.py", line 937, in render
    bit = node.render_annotated(context)
  File "/root/site/xiao2Blog/server/venv/lib/python3.6/site-packages/django/template/base.py", line 904, in render_annotated
    return self.render(context)
  File "/root/site/xiao2Blog/server/venv/lib/python3.6/site-packages/django/template/loader_tags.py", line 62, in render
    result = block.nodelist.render(context)
  File "/root/site/xiao2Blog/server/venv/lib/python3.6/site-packages/django/template/base.py", line 937, in render
    bit = node.render_annotated(context)
  File "/root/site/xiao2Blog/server/venv/lib/python3.6/site-packages/django/template/base.py", line 904, in render_annotated
    return self.render(context)
  File "/root/site/xiao2Blog/server/venv/lib/python3.6/site-packages/django/template/defaulttags.py", line 309, in render
    return nodelist.render(context)
  File "/root/site/xiao2Blog/server/venv/lib/python3.6/site-packages/django/template/base.py", line 937, in render
    bit = node.render_annotated(context)
  File "/root/site/xiao2Blog/server/venv/lib/python3.6/site-packages/django/template/base.py", line 904, in render_annotated
    return self.render(context)
  File "/root/site/xiao2Blog/server/venv/lib/python3.6/site-packages/django/template/library.py", line 192, in render
    output = self.func(*resolved_args, **resolved_kwargs)
  File "/root/site/xiao2Blog/server/venv/lib/python3.6/site-packages/rest_framework/templatetags/rest_framework.py", line 96, in optional_login
    login_url = reverse('rest_framework:login')
  File "/root/site/xiao2Blog/server/venv/lib/python3.6/site-packages/django/urls/base.py", line 58, in reverse
    app_list = resolver.app_dict[ns]
  File "/root/site/xiao2Blog/server/venv/lib/python3.6/site-packages/django/urls/resolvers.py", line 513, in app_dict
    self._populate()
  File "/root/site/xiao2Blog/server/venv/lib/python3.6/site-packages/django/urls/resolvers.py", line 464, in _populate
    url_pattern._populate()
  File "/root/site/xiao2Blog/server/venv/lib/python3.6/site-packages/django/urls/resolvers.py", line 447, in _populate
    for url_pattern in reversed(self.url_patterns):
TypeError: 'set' object is not reversible
[2019-11-25 16:34:13,177][uWSGIWorker1Core0:140056096737344][task_id:django.request][log.py:228][ERROR][Internal Server Error: /api2/admin/login/]
Traceback (most recent call last):
  File "/root/site/xiao2Blog/server/venv/lib/python3.6/site-packages/django/db/backends/utils.py", line 84, in _execute
    return self.cursor.execute(sql, params)
  File "/root/site/xiao2Blog/server/venv/lib/python3.6/site-packages/django/db/backends/mysql/base.py", line 71, in execute
    return self.cursor.execute(query, args)
  File "/root/site/xiao2Blog/server/venv/lib/python3.6/site-packages/pymysql/cursors.py", line 170, in execute
    result = self._query(query)
  File "/root/site/xiao2Blog/server/venv/lib/python3.6/site-packages/pymysql/cursors.py", line 328, in _query
    conn.query(q)
  File "/root/site/xiao2Blog/server/venv/lib/python3.6/site-packages/pymysql/connections.py", line 517, in query
    self._affected_rows = self._read_query_result(unbuffered=unbuffered)
  File "/root/site/xiao2Blog/server/venv/lib/python3.6/site-packages/pymysql/connections.py", line 732, in _read_query_result
    result.read()
  File "/root/site/xiao2Blog/server/venv/lib/python3.6/site-packages/pymysql/connections.py", line 1075, in read
    first_packet = self.connection._read_packet()
  File "/root/site/xiao2Blog/server/venv/lib/python3.6/site-packages/pymysql/connections.py", line 684, in _read_packet
    packet.check_error()
  File "/root/site/xiao2Blog/server/venv/lib/python3.6/site-packages/pymysql/protocol.py", line 220, in check_error
    err.raise_mysql_exception(self._data)
  File "/root/site/xiao2Blog/server/venv/lib/python3.6/site-packages/pymysql/err.py", line 109, in raise_mysql_exception
    raise errorclass(errno, errval)
pymysql.err.ProgrammingError: (1146, "Table 'blog2.django_session' doesn't exist")

The above exception was the direct cause of the following exception:

Traceback (most recent call last):
  File "/root/site/xiao2Blog/server/venv/lib/python3.6/site-packages/django/core/handlers/exception.py", line 34, in inner
    response = get_response(request)
  File "/root/site/xiao2Blog/server/venv/lib/python3.6/site-packages/django/core/handlers/base.py", line 115, in _get_response
    response = self.process_exception_by_middleware(e, request)
  File "/root/site/xiao2Blog/server/venv/lib/python3.6/site-packages/django/core/handlers/base.py", line 113, in _get_response
    response = wrapped_callback(request, *callback_args, **callback_kwargs)
  File "/root/site/xiao2Blog/server/venv/lib/python3.6/site-packages/django/views/decorators/cache.py", line 44, in _wrapped_view_func
    response = view_func(request, *args, **kwargs)
  File "/root/site/xiao2Blog/server/venv/lib/python3.6/site-packages/django/contrib/admin/sites.py", line 399, in login
    return LoginView.as_view(**defaults)(request)
  File "/root/site/xiao2Blog/server/venv/lib/python3.6/site-packages/django/views/generic/base.py", line 71, in view
    return self.dispatch(request, *args, **kwargs)
  File "/root/site/xiao2Blog/server/venv/lib/python3.6/site-packages/django/utils/decorators.py", line 45, in _wrapper
    return bound_method(*args, **kwargs)
  File "/root/site/xiao2Blog/server/venv/lib/python3.6/site-packages/django/views/decorators/debug.py", line 76, in sensitive_post_parameters_wrapper
    return view(request, *args, **kwargs)
  File "/root/site/xiao2Blog/server/venv/lib/python3.6/site-packages/django/utils/decorators.py", line 45, in _wrapper
    return bound_method(*args, **kwargs)
  File "/root/site/xiao2Blog/server/venv/lib/python3.6/site-packages/django/utils/decorators.py", line 142, in _wrapped_view
    response = view_func(request, *args, **kwargs)
  File "/root/site/xiao2Blog/server/venv/lib/python3.6/site-packages/django/utils/decorators.py", line 45, in _wrapper
    return bound_method(*args, **kwargs)
  File "/root/site/xiao2Blog/server/venv/lib/python3.6/site-packages/django/views/decorators/cache.py", line 44, in _wrapped_view_func
    response = view_func(request, *args, **kwargs)
  File "/root/site/xiao2Blog/server/venv/lib/python3.6/site-packages/django/contrib/auth/views.py", line 61, in dispatch
    return super().dispatch(request, *args, **kwargs)
  File "/root/site/xiao2Blog/server/venv/lib/python3.6/site-packages/django/views/generic/base.py", line 97, in dispatch
    return handler(request, *args, **kwargs)
  File "/root/site/xiao2Blog/server/venv/lib/python3.6/site-packages/django/views/generic/edit.py", line 142, in post
    return self.form_valid(form)
  File "/root/site/xiao2Blog/server/venv/lib/python3.6/site-packages/django/contrib/auth/views.py", line 90, in form_valid
    auth_login(self.request, form.get_user())
  File "/root/site/xiao2Blog/server/venv/lib/python3.6/site-packages/django/contrib/auth/__init__.py", line 108, in login
    request.session.cycle_key()
  File "/root/site/xiao2Blog/server/venv/lib/python3.6/site-packages/django/contrib/sessions/backends/base.py", line 297, in cycle_key
    self.create()
  File "/root/site/xiao2Blog/server/venv/lib/python3.6/site-packages/django/contrib/sessions/backends/db.py", line 51, in create
    self._session_key = self._get_new_session_key()
  File "/root/site/xiao2Blog/server/venv/lib/python3.6/site-packages/django/contrib/sessions/backends/base.py", line 152, in _get_new_session_key
    if not self.exists(session_key):
  File "/root/site/xiao2Blog/server/venv/lib/python3.6/site-packages/django/contrib/sessions/backends/db.py", line 47, in exists
    return self.model.objects.filter(session_key=session_key).exists()
  File "/root/site/xiao2Blog/server/venv/lib/python3.6/site-packages/django/db/models/query.py", line 766, in exists
    return self.query.has_results(using=self.db)
  File "/root/site/xiao2Blog/server/venv/lib/python3.6/site-packages/django/db/models/sql/query.py", line 522, in has_results
    return compiler.has_results()
  File "/root/site/xiao2Blog/server/venv/lib/python3.6/site-packages/django/db/models/sql/compiler.py", line 1070, in has_results
    return bool(self.execute_sql(SINGLE))
  File "/root/site/xiao2Blog/server/venv/lib/python3.6/site-packages/django/db/models/sql/compiler.py", line 1100, in execute_sql
    cursor.execute(sql, params)
  File "/root/site/xiao2Blog/server/venv/lib/python3.6/site-packages/django/db/backends/utils.py", line 67, in execute
    return self._execute_with_wrappers(sql, params, many=False, executor=self._execute)
  File "/root/site/xiao2Blog/server/venv/lib/python3.6/site-packages/django/db/backends/utils.py", line 76, in _execute_with_wrappers
    return executor(sql, params, many, context)
  File "/root/site/xiao2Blog/server/venv/lib/python3.6/site-packages/django/db/backends/utils.py", line 84, in _execute
    return self.cursor.execute(sql, params)
  File "/root/site/xiao2Blog/server/venv/lib/python3.6/site-packages/django/db/utils.py", line 89, in __exit__
    raise dj_exc_value.with_traceback(traceback) from exc_value
  File "/root/site/xiao2Blog/server/venv/lib/python3.6/site-packages/django/db/backends/utils.py", line 84, in _execute
    return self.cursor.execute(sql, params)
  File "/root/site/xiao2Blog/server/venv/lib/python3.6/site-packages/django/db/backends/mysql/base.py", line 71, in execute
    return self.cursor.execute(query, args)
  File "/root/site/xiao2Blog/server/venv/lib/python3.6/site-packages/pymysql/cursors.py", line 170, in execute
    result = self._query(query)
  File "/root/site/xiao2Blog/server/venv/lib/python3.6/site-packages/pymysql/cursors.py", line 328, in _query
    conn.query(q)
  File "/root/site/xiao2Blog/server/venv/lib/python3.6/site-packages/pymysql/connections.py", line 517, in query
    self._affected_rows = self._read_query_result(unbuffered=unbuffered)
  File "/root/site/xiao2Blog/server/venv/lib/python3.6/site-packages/pymysql/connections.py", line 732, in _read_query_result
    result.read()
  File "/root/site/xiao2Blog/server/venv/lib/python3.6/site-packages/pymysql/connections.py", line 1075, in read
    first_packet = self.connection._read_packet()
  File "/root/site/xiao2Blog/server/venv/lib/python3.6/site-packages/pymysql/connections.py", line 684, in _read_packet
    packet.check_error()
  File "/root/site/xiao2Blog/server/venv/lib/python3.6/site-packages/pymysql/protocol.py", line 220, in check_error
    err.raise_mysql_exception(self._data)
  File "/root/site/xiao2Blog/server/venv/lib/python3.6/site-packages/pymysql/err.py", line 109, in raise_mysql_exception
    raise errorclass(errno, errval)
django.db.utils.ProgrammingError: (1146, "Table 'blog2.django_session' doesn't exist")
[2019-11-25 16:34:19,737][uWSGIWorker1Core0:140056096737344][task_id:django.request][log.py:228][ERROR][Internal Server Error: /api2/admin/login/]
Traceback (most recent call last):
  File "/root/site/xiao2Blog/server/venv/lib/python3.6/site-packages/django/db/backends/utils.py", line 84, in _execute
    return self.cursor.execute(sql, params)
  File "/root/site/xiao2Blog/server/venv/lib/python3.6/site-packages/django/db/backends/mysql/base.py", line 71, in execute
    return self.cursor.execute(query, args)
  File "/root/site/xiao2Blog/server/venv/lib/python3.6/site-packages/pymysql/cursors.py", line 170, in execute
    result = self._query(query)
  File "/root/site/xiao2Blog/server/venv/lib/python3.6/site-packages/pymysql/cursors.py", line 328, in _query
    conn.query(q)
  File "/root/site/xiao2Blog/server/venv/lib/python3.6/site-packages/pymysql/connections.py", line 517, in query
    self._affected_rows = self._read_query_result(unbuffered=unbuffered)
  File "/root/site/xiao2Blog/server/venv/lib/python3.6/site-packages/pymysql/connections.py", line 732, in _read_query_result
    result.read()
  File "/root/site/xiao2Blog/server/venv/lib/python3.6/site-packages/pymysql/connections.py", line 1075, in read
    first_packet = self.connection._read_packet()
  File "/root/site/xiao2Blog/server/venv/lib/python3.6/site-packages/pymysql/connections.py", line 684, in _read_packet
    packet.check_error()
  File "/root/site/xiao2Blog/server/venv/lib/python3.6/site-packages/pymysql/protocol.py", line 220, in check_error
    err.raise_mysql_exception(self._data)
  File "/root/site/xiao2Blog/server/venv/lib/python3.6/site-packages/pymysql/err.py", line 109, in raise_mysql_exception
    raise errorclass(errno, errval)
pymysql.err.ProgrammingError: (1146, "Table 'blog2.django_session' doesn't exist")

The above exception was the direct cause of the following exception:

Traceback (most recent call last):
  File "/root/site/xiao2Blog/server/venv/lib/python3.6/site-packages/django/core/handlers/exception.py", line 34, in inner
    response = get_response(request)
  File "/root/site/xiao2Blog/server/venv/lib/python3.6/site-packages/django/core/handlers/base.py", line 115, in _get_response
    response = self.process_exception_by_middleware(e, request)
  File "/root/site/xiao2Blog/server/venv/lib/python3.6/site-packages/django/core/handlers/base.py", line 113, in _get_response
    response = wrapped_callback(request, *callback_args, **callback_kwargs)
  File "/root/site/xiao2Blog/server/venv/lib/python3.6/site-packages/django/views/decorators/cache.py", line 44, in _wrapped_view_func
    response = view_func(request, *args, **kwargs)
  File "/root/site/xiao2Blog/server/venv/lib/python3.6/site-packages/django/contrib/admin/sites.py", line 399, in login
    return LoginView.as_view(**defaults)(request)
  File "/root/site/xiao2Blog/server/venv/lib/python3.6/site-packages/django/views/generic/base.py", line 71, in view
    return self.dispatch(request, *args, **kwargs)
  File "/root/site/xiao2Blog/server/venv/lib/python3.6/site-packages/django/utils/decorators.py", line 45, in _wrapper
    return bound_method(*args, **kwargs)
  File "/root/site/xiao2Blog/server/venv/lib/python3.6/site-packages/django/views/decorators/debug.py", line 76, in sensitive_post_parameters_wrapper
    return view(request, *args, **kwargs)
  File "/root/site/xiao2Blog/server/venv/lib/python3.6/site-packages/django/utils/decorators.py", line 45, in _wrapper
    return bound_method(*args, **kwargs)
  File "/root/site/xiao2Blog/server/venv/lib/python3.6/site-packages/django/utils/decorators.py", line 142, in _wrapped_view
    response = view_func(request, *args, **kwargs)
  File "/root/site/xiao2Blog/server/venv/lib/python3.6/site-packages/django/utils/decorators.py", line 45, in _wrapper
    return bound_method(*args, **kwargs)
  File "/root/site/xiao2Blog/server/venv/lib/python3.6/site-packages/django/views/decorators/cache.py", line 44, in _wrapped_view_func
    response = view_func(request, *args, **kwargs)
  File "/root/site/xiao2Blog/server/venv/lib/python3.6/site-packages/django/contrib/auth/views.py", line 61, in dispatch
    return super().dispatch(request, *args, **kwargs)
  File "/root/site/xiao2Blog/server/venv/lib/python3.6/site-packages/django/views/generic/base.py", line 97, in dispatch
    return handler(request, *args, **kwargs)
  File "/root/site/xiao2Blog/server/venv/lib/python3.6/site-packages/django/views/generic/edit.py", line 142, in post
    return self.form_valid(form)
  File "/root/site/xiao2Blog/server/venv/lib/python3.6/site-packages/django/contrib/auth/views.py", line 90, in form_valid
    auth_login(self.request, form.get_user())
  File "/root/site/xiao2Blog/server/venv/lib/python3.6/site-packages/django/contrib/auth/__init__.py", line 108, in login
    request.session.cycle_key()
  File "/root/site/xiao2Blog/server/venv/lib/python3.6/site-packages/django/contrib/sessions/backends/base.py", line 297, in cycle_key
    self.create()
  File "/root/site/xiao2Blog/server/venv/lib/python3.6/site-packages/django/contrib/sessions/backends/db.py", line 51, in create
    self._session_key = self._get_new_session_key()
  File "/root/site/xiao2Blog/server/venv/lib/python3.6/site-packages/django/contrib/sessions/backends/base.py", line 152, in _get_new_session_key
    if not self.exists(session_key):
  File "/root/site/xiao2Blog/server/venv/lib/python3.6/site-packages/django/contrib/sessions/backends/db.py", line 47, in exists
    return self.model.objects.filter(session_key=session_key).exists()
  File "/root/site/xiao2Blog/server/venv/lib/python3.6/site-packages/django/db/models/query.py", line 766, in exists
    return self.query.has_results(using=self.db)
  File "/root/site/xiao2Blog/server/venv/lib/python3.6/site-packages/django/db/models/sql/query.py", line 522, in has_results
    return compiler.has_results()
  File "/root/site/xiao2Blog/server/venv/lib/python3.6/site-packages/django/db/models/sql/compiler.py", line 1070, in has_results
    return bool(self.execute_sql(SINGLE))
  File "/root/site/xiao2Blog/server/venv/lib/python3.6/site-packages/django/db/models/sql/compiler.py", line 1100, in execute_sql
    cursor.execute(sql, params)
  File "/root/site/xiao2Blog/server/venv/lib/python3.6/site-packages/django/db/backends/utils.py", line 67, in execute
    return self._execute_with_wrappers(sql, params, many=False, executor=self._execute)
  File "/root/site/xiao2Blog/server/venv/lib/python3.6/site-packages/django/db/backends/utils.py", line 76, in _execute_with_wrappers
    return executor(sql, params, many, context)
  File "/root/site/xiao2Blog/server/venv/lib/python3.6/site-packages/django/db/backends/utils.py", line 84, in _execute
    return self.cursor.execute(sql, params)
  File "/root/site/xiao2Blog/server/venv/lib/python3.6/site-packages/django/db/utils.py", line 89, in __exit__
    raise dj_exc_value.with_traceback(traceback) from exc_value
  File "/root/site/xiao2Blog/server/venv/lib/python3.6/site-packages/django/db/backends/utils.py", line 84, in _execute
    return self.cursor.execute(sql, params)
  File "/root/site/xiao2Blog/server/venv/lib/python3.6/site-packages/django/db/backends/mysql/base.py", line 71, in execute
    return self.cursor.execute(query, args)
  File "/root/site/xiao2Blog/server/venv/lib/python3.6/site-packages/pymysql/cursors.py", line 170, in execute
    result = self._query(query)
  File "/root/site/xiao2Blog/server/venv/lib/python3.6/site-packages/pymysql/cursors.py", line 328, in _query
    conn.query(q)
  File "/root/site/xiao2Blog/server/venv/lib/python3.6/site-packages/pymysql/connections.py", line 517, in query
    self._affected_rows = self._read_query_result(unbuffered=unbuffered)
  File "/root/site/xiao2Blog/server/venv/lib/python3.6/site-packages/pymysql/connections.py", line 732, in _read_query_result
    result.read()
  File "/root/site/xiao2Blog/server/venv/lib/python3.6/site-packages/pymysql/connections.py", line 1075, in read
    first_packet = self.connection._read_packet()
  File "/root/site/xiao2Blog/server/venv/lib/python3.6/site-packages/pymysql/connections.py", line 684, in _read_packet
    packet.check_error()
  File "/root/site/xiao2Blog/server/venv/lib/python3.6/site-packages/pymysql/protocol.py", line 220, in check_error
    err.raise_mysql_exception(self._data)
  File "/root/site/xiao2Blog/server/venv/lib/python3.6/site-packages/pymysql/err.py", line 109, in raise_mysql_exception
    raise errorclass(errno, errval)
django.db.utils.ProgrammingError: (1146, "Table 'blog2.django_session' doesn't exist")
[2019-11-25 16:34:58,240][uWSGIWorker1Core0:140056096737344][task_id:django.request][log.py:228][ERROR][Internal Server Error: /api2/admin/login/]
Traceback (most recent call last):
  File "/root/site/xiao2Blog/server/venv/lib/python3.6/site-packages/django/db/backends/utils.py", line 84, in _execute
    return self.cursor.execute(sql, params)
  File "/root/site/xiao2Blog/server/venv/lib/python3.6/site-packages/django/db/backends/mysql/base.py", line 71, in execute
    return self.cursor.execute(query, args)
  File "/root/site/xiao2Blog/server/venv/lib/python3.6/site-packages/pymysql/cursors.py", line 170, in execute
    result = self._query(query)
  File "/root/site/xiao2Blog/server/venv/lib/python3.6/site-packages/pymysql/cursors.py", line 328, in _query
    conn.query(q)
  File "/root/site/xiao2Blog/server/venv/lib/python3.6/site-packages/pymysql/connections.py", line 517, in query
    self._affected_rows = self._read_query_result(unbuffered=unbuffered)
  File "/root/site/xiao2Blog/server/venv/lib/python3.6/site-packages/pymysql/connections.py", line 732, in _read_query_result
    result.read()
  File "/root/site/xiao2Blog/server/venv/lib/python3.6/site-packages/pymysql/connections.py", line 1075, in read
    first_packet = self.connection._read_packet()
  File "/root/site/xiao2Blog/server/venv/lib/python3.6/site-packages/pymysql/connections.py", line 684, in _read_packet
    packet.check_error()
  File "/root/site/xiao2Blog/server/venv/lib/python3.6/site-packages/pymysql/protocol.py", line 220, in check_error
    err.raise_mysql_exception(self._data)
  File "/root/site/xiao2Blog/server/venv/lib/python3.6/site-packages/pymysql/err.py", line 109, in raise_mysql_exception
    raise errorclass(errno, errval)
pymysql.err.ProgrammingError: (1146, "Table 'blog2.django_session' doesn't exist")

The above exception was the direct cause of the following exception:

Traceback (most recent call last):
  File "/root/site/xiao2Blog/server/venv/lib/python3.6/site-packages/django/core/handlers/exception.py", line 34, in inner
    response = get_response(request)
  File "/root/site/xiao2Blog/server/venv/lib/python3.6/site-packages/django/core/handlers/base.py", line 115, in _get_response
    response = self.process_exception_by_middleware(e, request)
  File "/root/site/xiao2Blog/server/venv/lib/python3.6/site-packages/django/core/handlers/base.py", line 113, in _get_response
    response = wrapped_callback(request, *callback_args, **callback_kwargs)
  File "/root/site/xiao2Blog/server/venv/lib/python3.6/site-packages/django/views/decorators/cache.py", line 44, in _wrapped_view_func
    response = view_func(request, *args, **kwargs)
  File "/root/site/xiao2Blog/server/venv/lib/python3.6/site-packages/django/contrib/admin/sites.py", line 399, in login
    return LoginView.as_view(**defaults)(request)
  File "/root/site/xiao2Blog/server/venv/lib/python3.6/site-packages/django/views/generic/base.py", line 71, in view
    return self.dispatch(request, *args, **kwargs)
  File "/root/site/xiao2Blog/server/venv/lib/python3.6/site-packages/django/utils/decorators.py", line 45, in _wrapper
    return bound_method(*args, **kwargs)
  File "/root/site/xiao2Blog/server/venv/lib/python3.6/site-packages/django/views/decorators/debug.py", line 76, in sensitive_post_parameters_wrapper
    return view(request, *args, **kwargs)
  File "/root/site/xiao2Blog/server/venv/lib/python3.6/site-packages/django/utils/decorators.py", line 45, in _wrapper
    return bound_method(*args, **kwargs)
  File "/root/site/xiao2Blog/server/venv/lib/python3.6/site-packages/django/utils/decorators.py", line 142, in _wrapped_view
    response = view_func(request, *args, **kwargs)
  File "/root/site/xiao2Blog/server/venv/lib/python3.6/site-packages/django/utils/decorators.py", line 45, in _wrapper
    return bound_method(*args, **kwargs)
  File "/root/site/xiao2Blog/server/venv/lib/python3.6/site-packages/django/views/decorators/cache.py", line 44, in _wrapped_view_func
    response = view_func(request, *args, **kwargs)
  File "/root/site/xiao2Blog/server/venv/lib/python3.6/site-packages/django/contrib/auth/views.py", line 61, in dispatch
    return super().dispatch(request, *args, **kwargs)
  File "/root/site/xiao2Blog/server/venv/lib/python3.6/site-packages/django/views/generic/base.py", line 97, in dispatch
    return handler(request, *args, **kwargs)
  File "/root/site/xiao2Blog/server/venv/lib/python3.6/site-packages/django/views/generic/edit.py", line 142, in post
    return self.form_valid(form)
  File "/root/site/xiao2Blog/server/venv/lib/python3.6/site-packages/django/contrib/auth/views.py", line 90, in form_valid
    auth_login(self.request, form.get_user())
  File "/root/site/xiao2Blog/server/venv/lib/python3.6/site-packages/django/contrib/auth/__init__.py", line 108, in login
    request.session.cycle_key()
  File "/root/site/xiao2Blog/server/venv/lib/python3.6/site-packages/django/contrib/sessions/backends/base.py", line 297, in cycle_key
    self.create()
  File "/root/site/xiao2Blog/server/venv/lib/python3.6/site-packages/django/contrib/sessions/backends/db.py", line 51, in create
    self._session_key = self._get_new_session_key()
  File "/root/site/xiao2Blog/server/venv/lib/python3.6/site-packages/django/contrib/sessions/backends/base.py", line 152, in _get_new_session_key
    if not self.exists(session_key):
  File "/root/site/xiao2Blog/server/venv/lib/python3.6/site-packages/django/contrib/sessions/backends/db.py", line 47, in exists
    return self.model.objects.filter(session_key=session_key).exists()
  File "/root/site/xiao2Blog/server/venv/lib/python3.6/site-packages/django/db/models/query.py", line 766, in exists
    return self.query.has_results(using=self.db)
  File "/root/site/xiao2Blog/server/venv/lib/python3.6/site-packages/django/db/models/sql/query.py", line 522, in has_results
    return compiler.has_results()
  File "/root/site/xiao2Blog/server/venv/lib/python3.6/site-packages/django/db/models/sql/compiler.py", line 1070, in has_results
    return bool(self.execute_sql(SINGLE))
  File "/root/site/xiao2Blog/server/venv/lib/python3.6/site-packages/django/db/models/sql/compiler.py", line 1100, in execute_sql
    cursor.execute(sql, params)
  File "/root/site/xiao2Blog/server/venv/lib/python3.6/site-packages/django/db/backends/utils.py", line 67, in execute
    return self._execute_with_wrappers(sql, params, many=False, executor=self._execute)
  File "/root/site/xiao2Blog/server/venv/lib/python3.6/site-packages/django/db/backends/utils.py", line 76, in _execute_with_wrappers
    return executor(sql, params, many, context)
  File "/root/site/xiao2Blog/server/venv/lib/python3.6/site-packages/django/db/backends/utils.py", line 84, in _execute
    return self.cursor.execute(sql, params)
  File "/root/site/xiao2Blog/server/venv/lib/python3.6/site-packages/django/db/utils.py", line 89, in __exit__
    raise dj_exc_value.with_traceback(traceback) from exc_value
  File "/root/site/xiao2Blog/server/venv/lib/python3.6/site-packages/django/db/backends/utils.py", line 84, in _execute
    return self.cursor.execute(sql, params)
  File "/root/site/xiao2Blog/server/venv/lib/python3.6/site-packages/django/db/backends/mysql/base.py", line 71, in execute
    return self.cursor.execute(query, args)
  File "/root/site/xiao2Blog/server/venv/lib/python3.6/site-packages/pymysql/cursors.py", line 170, in execute
    result = self._query(query)
  File "/root/site/xiao2Blog/server/venv/lib/python3.6/site-packages/pymysql/cursors.py", line 328, in _query
    conn.query(q)
  File "/root/site/xiao2Blog/server/venv/lib/python3.6/site-packages/pymysql/connections.py", line 517, in query
    self._affected_rows = self._read_query_result(unbuffered=unbuffered)
  File "/root/site/xiao2Blog/server/venv/lib/python3.6/site-packages/pymysql/connections.py", line 732, in _read_query_result
    result.read()
  File "/root/site/xiao2Blog/server/venv/lib/python3.6/site-packages/pymysql/connections.py", line 1075, in read
    first_packet = self.connection._read_packet()
  File "/root/site/xiao2Blog/server/venv/lib/python3.6/site-packages/pymysql/connections.py", line 684, in _read_packet
    packet.check_error()
  File "/root/site/xiao2Blog/server/venv/lib/python3.6/site-packages/pymysql/protocol.py", line 220, in check_error
    err.raise_mysql_exception(self._data)
  File "/root/site/xiao2Blog/server/venv/lib/python3.6/site-packages/pymysql/err.py", line 109, in raise_mysql_exception
    raise errorclass(errno, errval)
django.db.utils.ProgrammingError: (1146, "Table 'blog2.django_session' doesn't exist")
[2019-11-25 16:38:55,924][uWSGIWorker1Core0:140056096737344][task_id:django.request][log.py:228][ERROR][Internal Server Error: /api2/admin/login/]
Traceback (most recent call last):
  File "/root/site/xiao2Blog/server/venv/lib/python3.6/site-packages/django/db/backends/utils.py", line 84, in _execute
    return self.cursor.execute(sql, params)
  File "/root/site/xiao2Blog/server/venv/lib/python3.6/site-packages/django/db/backends/mysql/base.py", line 71, in execute
    return self.cursor.execute(query, args)
  File "/root/site/xiao2Blog/server/venv/lib/python3.6/site-packages/pymysql/cursors.py", line 170, in execute
    result = self._query(query)
  File "/root/site/xiao2Blog/server/venv/lib/python3.6/site-packages/pymysql/cursors.py", line 328, in _query
    conn.query(q)
  File "/root/site/xiao2Blog/server/venv/lib/python3.6/site-packages/pymysql/connections.py", line 517, in query
    self._affected_rows = self._read_query_result(unbuffered=unbuffered)
  File "/root/site/xiao2Blog/server/venv/lib/python3.6/site-packages/pymysql/connections.py", line 732, in _read_query_result
    result.read()
  File "/root/site/xiao2Blog/server/venv/lib/python3.6/site-packages/pymysql/connections.py", line 1075, in read
    first_packet = self.connection._read_packet()
  File "/root/site/xiao2Blog/server/venv/lib/python3.6/site-packages/pymysql/connections.py", line 684, in _read_packet
    packet.check_error()
  File "/root/site/xiao2Blog/server/venv/lib/python3.6/site-packages/pymysql/protocol.py", line 220, in check_error
    err.raise_mysql_exception(self._data)
  File "/root/site/xiao2Blog/server/venv/lib/python3.6/site-packages/pymysql/err.py", line 109, in raise_mysql_exception
    raise errorclass(errno, errval)
pymysql.err.ProgrammingError: (1146, "Table 'blog2.django_session' doesn't exist")

The above exception was the direct cause of the following exception:

Traceback (most recent call last):
  File "/root/site/xiao2Blog/server/venv/lib/python3.6/site-packages/django/core/handlers/exception.py", line 34, in inner
    response = get_response(request)
  File "/root/site/xiao2Blog/server/venv/lib/python3.6/site-packages/django/core/handlers/base.py", line 115, in _get_response
    response = self.process_exception_by_middleware(e, request)
  File "/root/site/xiao2Blog/server/venv/lib/python3.6/site-packages/django/core/handlers/base.py", line 113, in _get_response
    response = wrapped_callback(request, *callback_args, **callback_kwargs)
  File "/root/site/xiao2Blog/server/venv/lib/python3.6/site-packages/django/views/decorators/cache.py", line 44, in _wrapped_view_func
    response = view_func(request, *args, **kwargs)
  File "/root/site/xiao2Blog/server/venv/lib/python3.6/site-packages/django/contrib/admin/sites.py", line 399, in login
    return LoginView.as_view(**defaults)(request)
  File "/root/site/xiao2Blog/server/venv/lib/python3.6/site-packages/django/views/generic/base.py", line 71, in view
    return self.dispatch(request, *args, **kwargs)
  File "/root/site/xiao2Blog/server/venv/lib/python3.6/site-packages/django/utils/decorators.py", line 45, in _wrapper
    return bound_method(*args, **kwargs)
  File "/root/site/xiao2Blog/server/venv/lib/python3.6/site-packages/django/views/decorators/debug.py", line 76, in sensitive_post_parameters_wrapper
    return view(request, *args, **kwargs)
  File "/root/site/xiao2Blog/server/venv/lib/python3.6/site-packages/django/utils/decorators.py", line 45, in _wrapper
    return bound_method(*args, **kwargs)
  File "/root/site/xiao2Blog/server/venv/lib/python3.6/site-packages/django/utils/decorators.py", line 142, in _wrapped_view
    response = view_func(request, *args, **kwargs)
  File "/root/site/xiao2Blog/server/venv/lib/python3.6/site-packages/django/utils/decorators.py", line 45, in _wrapper
    return bound_method(*args, **kwargs)
  File "/root/site/xiao2Blog/server/venv/lib/python3.6/site-packages/django/views/decorators/cache.py", line 44, in _wrapped_view_func
    response = view_func(request, *args, **kwargs)
  File "/root/site/xiao2Blog/server/venv/lib/python3.6/site-packages/django/contrib/auth/views.py", line 61, in dispatch
    return super().dispatch(request, *args, **kwargs)
  File "/root/site/xiao2Blog/server/venv/lib/python3.6/site-packages/django/views/generic/base.py", line 97, in dispatch
    return handler(request, *args, **kwargs)
  File "/root/site/xiao2Blog/server/venv/lib/python3.6/site-packages/django/views/generic/edit.py", line 142, in post
    return self.form_valid(form)
  File "/root/site/xiao2Blog/server/venv/lib/python3.6/site-packages/django/contrib/auth/views.py", line 90, in form_valid
    auth_login(self.request, form.get_user())
  File "/root/site/xiao2Blog/server/venv/lib/python3.6/site-packages/django/contrib/auth/__init__.py", line 108, in login
    request.session.cycle_key()
  File "/root/site/xiao2Blog/server/venv/lib/python3.6/site-packages/django/contrib/sessions/backends/base.py", line 297, in cycle_key
    self.create()
  File "/root/site/xiao2Blog/server/venv/lib/python3.6/site-packages/django/contrib/sessions/backends/db.py", line 51, in create
    self._session_key = self._get_new_session_key()
  File "/root/site/xiao2Blog/server/venv/lib/python3.6/site-packages/django/contrib/sessions/backends/base.py", line 152, in _get_new_session_key
    if not self.exists(session_key):
  File "/root/site/xiao2Blog/server/venv/lib/python3.6/site-packages/django/contrib/sessions/backends/db.py", line 47, in exists
    return self.model.objects.filter(session_key=session_key).exists()
  File "/root/site/xiao2Blog/server/venv/lib/python3.6/site-packages/django/db/models/query.py", line 766, in exists
    return self.query.has_results(using=self.db)
  File "/root/site/xiao2Blog/server/venv/lib/python3.6/site-packages/django/db/models/sql/query.py", line 522, in has_results
    return compiler.has_results()
  File "/root/site/xiao2Blog/server/venv/lib/python3.6/site-packages/django/db/models/sql/compiler.py", line 1070, in has_results
    return bool(self.execute_sql(SINGLE))
  File "/root/site/xiao2Blog/server/venv/lib/python3.6/site-packages/django/db/models/sql/compiler.py", line 1100, in execute_sql
    cursor.execute(sql, params)
  File "/root/site/xiao2Blog/server/venv/lib/python3.6/site-packages/django/db/backends/utils.py", line 67, in execute
    return self._execute_with_wrappers(sql, params, many=False, executor=self._execute)
  File "/root/site/xiao2Blog/server/venv/lib/python3.6/site-packages/django/db/backends/utils.py", line 76, in _execute_with_wrappers
    return executor(sql, params, many, context)
  File "/root/site/xiao2Blog/server/venv/lib/python3.6/site-packages/django/db/backends/utils.py", line 84, in _execute
    return self.cursor.execute(sql, params)
  File "/root/site/xiao2Blog/server/venv/lib/python3.6/site-packages/django/db/utils.py", line 89, in __exit__
    raise dj_exc_value.with_traceback(traceback) from exc_value
  File "/root/site/xiao2Blog/server/venv/lib/python3.6/site-packages/django/db/backends/utils.py", line 84, in _execute
    return self.cursor.execute(sql, params)
  File "/root/site/xiao2Blog/server/venv/lib/python3.6/site-packages/django/db/backends/mysql/base.py", line 71, in execute
    return self.cursor.execute(query, args)
  File "/root/site/xiao2Blog/server/venv/lib/python3.6/site-packages/pymysql/cursors.py", line 170, in execute
    result = self._query(query)
  File "/root/site/xiao2Blog/server/venv/lib/python3.6/site-packages/pymysql/cursors.py", line 328, in _query
    conn.query(q)
  File "/root/site/xiao2Blog/server/venv/lib/python3.6/site-packages/pymysql/connections.py", line 517, in query
    self._affected_rows = self._read_query_result(unbuffered=unbuffered)
  File "/root/site/xiao2Blog/server/venv/lib/python3.6/site-packages/pymysql/connections.py", line 732, in _read_query_result
    result.read()
  File "/root/site/xiao2Blog/server/venv/lib/python3.6/site-packages/pymysql/connections.py", line 1075, in read
    first_packet = self.connection._read_packet()
  File "/root/site/xiao2Blog/server/venv/lib/python3.6/site-packages/pymysql/connections.py", line 684, in _read_packet
    packet.check_error()
  File "/root/site/xiao2Blog/server/venv/lib/python3.6/site-packages/pymysql/protocol.py", line 220, in check_error
    err.raise_mysql_exception(self._data)
  File "/root/site/xiao2Blog/server/venv/lib/python3.6/site-packages/pymysql/err.py", line 109, in raise_mysql_exception
    raise errorclass(errno, errval)
django.db.utils.ProgrammingError: (1146, "Table 'blog2.django_session' doesn't exist")
[2019-11-28 09:22:43,482][Thread-1:123145503248384][task_id:django.request][log.py:228][ERROR][Internal Server Error: /api2/api/articleList]
Traceback (most recent call last):
  File "/Users/xiao2/Desktop/Coder/MyBlog/server/venv/lib/python3.7/site-packages/django/core/handlers/exception.py", line 34, in inner
    response = get_response(request)
  File "/Users/xiao2/Desktop/Coder/MyBlog/server/venv/lib/python3.7/site-packages/django/core/handlers/base.py", line 115, in _get_response
    response = self.process_exception_by_middleware(e, request)
  File "/Users/xiao2/Desktop/Coder/MyBlog/server/venv/lib/python3.7/site-packages/django/core/handlers/base.py", line 113, in _get_response
    response = wrapped_callback(request, *callback_args, **callback_kwargs)
  File "/Users/xiao2/Desktop/Coder/MyBlog/server/venv/lib/python3.7/site-packages/django/views/decorators/csrf.py", line 54, in wrapped_view
    return view_func(*args, **kwargs)
  File "/Users/xiao2/Desktop/Coder/MyBlog/server/venv/lib/python3.7/site-packages/django/views/generic/base.py", line 71, in view
    return self.dispatch(request, *args, **kwargs)
  File "/Users/xiao2/Desktop/Coder/MyBlog/server/venv/lib/python3.7/site-packages/rest_framework/views.py", line 505, in dispatch
    response = self.handle_exception(exc)
  File "/Users/xiao2/Desktop/Coder/MyBlog/server/venv/lib/python3.7/site-packages/rest_framework/views.py", line 465, in handle_exception
    self.raise_uncaught_exception(exc)
  File "/Users/xiao2/Desktop/Coder/MyBlog/server/venv/lib/python3.7/site-packages/rest_framework/views.py", line 476, in raise_uncaught_exception
    raise exc
  File "/Users/xiao2/Desktop/Coder/MyBlog/server/venv/lib/python3.7/site-packages/rest_framework/views.py", line 502, in dispatch
    response = handler(request, *args, **kwargs)
  File "/Users/xiao2/Desktop/Coder/MyBlog/server/blog/views.py", line 73, in get
    return self.post(request)
  File "/Users/xiao2/Desktop/Coder/MyBlog/server/blog/views.py", line 80, in post
    post_data = json.loads(request.body)
  File "/usr/local/Cellar/python/3.7.3/Frameworks/Python.framework/Versions/3.7/lib/python3.7/json/__init__.py", line 348, in loads
    return _default_decoder.decode(s)
  File "/usr/local/Cellar/python/3.7.3/Frameworks/Python.framework/Versions/3.7/lib/python3.7/json/decoder.py", line 337, in decode
    obj, end = self.raw_decode(s, idx=_w(s, 0).end())
  File "/usr/local/Cellar/python/3.7.3/Frameworks/Python.framework/Versions/3.7/lib/python3.7/json/decoder.py", line 355, in raw_decode
    raise JSONDecodeError("Expecting value", s, err.value) from None
json.decoder.JSONDecodeError: Expecting value: line 1 column 1 (char 0)
[2019-11-28 09:22:57,189][Thread-1:123145422577664][task_id:django.request][log.py:228][ERROR][Internal Server Error: /api2/api/articleList]
Traceback (most recent call last):
  File "/Users/xiao2/Desktop/Coder/MyBlog/server/venv/lib/python3.7/site-packages/django/core/handlers/exception.py", line 34, in inner
    response = get_response(request)
  File "/Users/xiao2/Desktop/Coder/MyBlog/server/venv/lib/python3.7/site-packages/django/core/handlers/base.py", line 115, in _get_response
    response = self.process_exception_by_middleware(e, request)
  File "/Users/xiao2/Desktop/Coder/MyBlog/server/venv/lib/python3.7/site-packages/django/core/handlers/base.py", line 113, in _get_response
    response = wrapped_callback(request, *callback_args, **callback_kwargs)
  File "/Users/xiao2/Desktop/Coder/MyBlog/server/venv/lib/python3.7/site-packages/django/views/decorators/csrf.py", line 54, in wrapped_view
    return view_func(*args, **kwargs)
  File "/Users/xiao2/Desktop/Coder/MyBlog/server/venv/lib/python3.7/site-packages/django/views/generic/base.py", line 71, in view
    return self.dispatch(request, *args, **kwargs)
  File "/Users/xiao2/Desktop/Coder/MyBlog/server/venv/lib/python3.7/site-packages/rest_framework/views.py", line 505, in dispatch
    response = self.handle_exception(exc)
  File "/Users/xiao2/Desktop/Coder/MyBlog/server/venv/lib/python3.7/site-packages/rest_framework/views.py", line 465, in handle_exception
    self.raise_uncaught_exception(exc)
  File "/Users/xiao2/Desktop/Coder/MyBlog/server/venv/lib/python3.7/site-packages/rest_framework/views.py", line 476, in raise_uncaught_exception
    raise exc
  File "/Users/xiao2/Desktop/Coder/MyBlog/server/venv/lib/python3.7/site-packages/rest_framework/views.py", line 502, in dispatch
    response = handler(request, *args, **kwargs)
  File "/Users/xiao2/Desktop/Coder/MyBlog/server/blog/views.py", line 73, in get
    return self.post(request)
  File "/Users/xiao2/Desktop/Coder/MyBlog/server/blog/views.py", line 80, in post
    post_data = json.loads(request.body)
  File "/usr/local/Cellar/python/3.7.3/Frameworks/Python.framework/Versions/3.7/lib/python3.7/json/__init__.py", line 348, in loads
    return _default_decoder.decode(s)
  File "/usr/local/Cellar/python/3.7.3/Frameworks/Python.framework/Versions/3.7/lib/python3.7/json/decoder.py", line 337, in decode
    obj, end = self.raw_decode(s, idx=_w(s, 0).end())
  File "/usr/local/Cellar/python/3.7.3/Frameworks/Python.framework/Versions/3.7/lib/python3.7/json/decoder.py", line 355, in raw_decode
    raise JSONDecodeError("Expecting value", s, err.value) from None
json.decoder.JSONDecodeError: Expecting value: line 1 column 1 (char 0)
[2019-11-28 09:26:09,754][Thread-1:123145417011200][task_id:django.request][log.py:228][ERROR][Internal Server Error: /api2/api/articleList]
Traceback (most recent call last):
  File "/Users/xiao2/Desktop/Coder/MyBlog/server/venv/lib/python3.7/site-packages/django/core/handlers/exception.py", line 34, in inner
    response = get_response(request)
  File "/Users/xiao2/Desktop/Coder/MyBlog/server/venv/lib/python3.7/site-packages/django/core/handlers/base.py", line 115, in _get_response
    response = self.process_exception_by_middleware(e, request)
  File "/Users/xiao2/Desktop/Coder/MyBlog/server/venv/lib/python3.7/site-packages/django/core/handlers/base.py", line 113, in _get_response
    response = wrapped_callback(request, *callback_args, **callback_kwargs)
  File "/Users/xiao2/Desktop/Coder/MyBlog/server/venv/lib/python3.7/site-packages/django/views/decorators/csrf.py", line 54, in wrapped_view
    return view_func(*args, **kwargs)
  File "/Users/xiao2/Desktop/Coder/MyBlog/server/venv/lib/python3.7/site-packages/django/views/generic/base.py", line 71, in view
    return self.dispatch(request, *args, **kwargs)
  File "/Users/xiao2/Desktop/Coder/MyBlog/server/venv/lib/python3.7/site-packages/rest_framework/views.py", line 505, in dispatch
    response = self.handle_exception(exc)
  File "/Users/xiao2/Desktop/Coder/MyBlog/server/venv/lib/python3.7/site-packages/rest_framework/views.py", line 465, in handle_exception
    self.raise_uncaught_exception(exc)
  File "/Users/xiao2/Desktop/Coder/MyBlog/server/venv/lib/python3.7/site-packages/rest_framework/views.py", line 476, in raise_uncaught_exception
    raise exc
  File "/Users/xiao2/Desktop/Coder/MyBlog/server/venv/lib/python3.7/site-packages/rest_framework/views.py", line 502, in dispatch
    response = handler(request, *args, **kwargs)
  File "/Users/xiao2/Desktop/Coder/MyBlog/server/blog/views.py", line 73, in get
    return self.post(request)
  File "/Users/xiao2/Desktop/Coder/MyBlog/server/blog/views.py", line 80, in post
    post_data = json.loads(request.body)
  File "/usr/local/Cellar/python/3.7.3/Frameworks/Python.framework/Versions/3.7/lib/python3.7/json/__init__.py", line 348, in loads
    return _default_decoder.decode(s)
  File "/usr/local/Cellar/python/3.7.3/Frameworks/Python.framework/Versions/3.7/lib/python3.7/json/decoder.py", line 337, in decode
    obj, end = self.raw_decode(s, idx=_w(s, 0).end())
  File "/usr/local/Cellar/python/3.7.3/Frameworks/Python.framework/Versions/3.7/lib/python3.7/json/decoder.py", line 355, in raw_decode
    raise JSONDecodeError("Expecting value", s, err.value) from None
json.decoder.JSONDecodeError: Expecting value: line 1 column 1 (char 0)
[2019-11-28 09:26:58,540][Thread-1:123145550061568][task_id:django.request][log.py:228][ERROR][Internal Server Error: /api2/api/articleList]
Traceback (most recent call last):
  File "/Users/xiao2/Desktop/Coder/MyBlog/server/venv/lib/python3.7/site-packages/django/core/handlers/exception.py", line 34, in inner
    response = get_response(request)
  File "/Users/xiao2/Desktop/Coder/MyBlog/server/venv/lib/python3.7/site-packages/django/core/handlers/base.py", line 115, in _get_response
    response = self.process_exception_by_middleware(e, request)
  File "/Users/xiao2/Desktop/Coder/MyBlog/server/venv/lib/python3.7/site-packages/django/core/handlers/base.py", line 113, in _get_response
    response = wrapped_callback(request, *callback_args, **callback_kwargs)
  File "/Users/xiao2/Desktop/Coder/MyBlog/server/venv/lib/python3.7/site-packages/django/views/decorators/csrf.py", line 54, in wrapped_view
    return view_func(*args, **kwargs)
  File "/Users/xiao2/Desktop/Coder/MyBlog/server/venv/lib/python3.7/site-packages/django/views/generic/base.py", line 71, in view
    return self.dispatch(request, *args, **kwargs)
  File "/Users/xiao2/Desktop/Coder/MyBlog/server/venv/lib/python3.7/site-packages/rest_framework/views.py", line 505, in dispatch
    response = self.handle_exception(exc)
  File "/Users/xiao2/Desktop/Coder/MyBlog/server/venv/lib/python3.7/site-packages/rest_framework/views.py", line 465, in handle_exception
    self.raise_uncaught_exception(exc)
  File "/Users/xiao2/Desktop/Coder/MyBlog/server/venv/lib/python3.7/site-packages/rest_framework/views.py", line 476, in raise_uncaught_exception
    raise exc
  File "/Users/xiao2/Desktop/Coder/MyBlog/server/venv/lib/python3.7/site-packages/rest_framework/views.py", line 502, in dispatch
    response = handler(request, *args, **kwargs)
  File "/Users/xiao2/Desktop/Coder/MyBlog/server/blog/views.py", line 73, in get
    return self.post(request)
  File "/Users/xiao2/Desktop/Coder/MyBlog/server/blog/views.py", line 82, in post
    post_data = json.loads(request.body)
  File "/usr/local/Cellar/python/3.7.3/Frameworks/Python.framework/Versions/3.7/lib/python3.7/json/__init__.py", line 348, in loads
    return _default_decoder.decode(s)
  File "/usr/local/Cellar/python/3.7.3/Frameworks/Python.framework/Versions/3.7/lib/python3.7/json/decoder.py", line 337, in decode
    obj, end = self.raw_decode(s, idx=_w(s, 0).end())
  File "/usr/local/Cellar/python/3.7.3/Frameworks/Python.framework/Versions/3.7/lib/python3.7/json/decoder.py", line 355, in raw_decode
    raise JSONDecodeError("Expecting value", s, err.value) from None
json.decoder.JSONDecodeError: Expecting value: line 1 column 1 (char 0)
[2019-11-28 09:42:45,528][Thread-3:123145550061568][task_id:django.request][log.py:228][ERROR][Internal Server Error: /api2/api/articleList]
Traceback (most recent call last):
  File "/Users/xiao2/Desktop/Coder/MyBlog/server/venv/lib/python3.7/site-packages/django/core/handlers/exception.py", line 34, in inner
    response = get_response(request)
  File "/Users/xiao2/Desktop/Coder/MyBlog/server/venv/lib/python3.7/site-packages/django/core/handlers/base.py", line 115, in _get_response
    response = self.process_exception_by_middleware(e, request)
  File "/Users/xiao2/Desktop/Coder/MyBlog/server/venv/lib/python3.7/site-packages/django/core/handlers/base.py", line 113, in _get_response
    response = wrapped_callback(request, *callback_args, **callback_kwargs)
  File "/Users/xiao2/Desktop/Coder/MyBlog/server/venv/lib/python3.7/site-packages/django/views/decorators/csrf.py", line 54, in wrapped_view
    return view_func(*args, **kwargs)
  File "/Users/xiao2/Desktop/Coder/MyBlog/server/venv/lib/python3.7/site-packages/django/views/generic/base.py", line 71, in view
    return self.dispatch(request, *args, **kwargs)
  File "/Users/xiao2/Desktop/Coder/MyBlog/server/venv/lib/python3.7/site-packages/rest_framework/views.py", line 505, in dispatch
    response = self.handle_exception(exc)
  File "/Users/xiao2/Desktop/Coder/MyBlog/server/venv/lib/python3.7/site-packages/rest_framework/views.py", line 465, in handle_exception
    self.raise_uncaught_exception(exc)
  File "/Users/xiao2/Desktop/Coder/MyBlog/server/venv/lib/python3.7/site-packages/rest_framework/views.py", line 476, in raise_uncaught_exception
    raise exc
  File "/Users/xiao2/Desktop/Coder/MyBlog/server/venv/lib/python3.7/site-packages/rest_framework/views.py", line 502, in dispatch
    response = handler(request, *args, **kwargs)
  File "/Users/xiao2/Desktop/Coder/MyBlog/server/blog/views.py", line 73, in get
    return self.post(request)
  File "/Users/xiao2/Desktop/Coder/MyBlog/server/blog/views.py", line 82, in post
    post_data = json.loads(request.body)
  File "/usr/local/Cellar/python/3.7.3/Frameworks/Python.framework/Versions/3.7/lib/python3.7/json/__init__.py", line 348, in loads
    return _default_decoder.decode(s)
  File "/usr/local/Cellar/python/3.7.3/Frameworks/Python.framework/Versions/3.7/lib/python3.7/json/decoder.py", line 337, in decode
    obj, end = self.raw_decode(s, idx=_w(s, 0).end())
  File "/usr/local/Cellar/python/3.7.3/Frameworks/Python.framework/Versions/3.7/lib/python3.7/json/decoder.py", line 355, in raw_decode
    raise JSONDecodeError("Expecting value", s, err.value) from None
json.decoder.JSONDecodeError: Expecting value: line 1 column 1 (char 0)
[2019-11-28 09:43:59,901][Thread-1:123145368936448][task_id:django.request][log.py:228][ERROR][Internal Server Error: /api2/api/articleList]
Traceback (most recent call last):
  File "/Users/xiao2/Desktop/Coder/MyBlog/server/venv/lib/python3.7/site-packages/django/core/handlers/exception.py", line 34, in inner
    response = get_response(request)
  File "/Users/xiao2/Desktop/Coder/MyBlog/server/venv/lib/python3.7/site-packages/django/core/handlers/base.py", line 115, in _get_response
    response = self.process_exception_by_middleware(e, request)
  File "/Users/xiao2/Desktop/Coder/MyBlog/server/venv/lib/python3.7/site-packages/django/core/handlers/base.py", line 113, in _get_response
    response = wrapped_callback(request, *callback_args, **callback_kwargs)
  File "/Users/xiao2/Desktop/Coder/MyBlog/server/venv/lib/python3.7/site-packages/django/views/decorators/csrf.py", line 54, in wrapped_view
    return view_func(*args, **kwargs)
  File "/Users/xiao2/Desktop/Coder/MyBlog/server/venv/lib/python3.7/site-packages/django/views/generic/base.py", line 71, in view
    return self.dispatch(request, *args, **kwargs)
  File "/Users/xiao2/Desktop/Coder/MyBlog/server/venv/lib/python3.7/site-packages/rest_framework/views.py", line 505, in dispatch
    response = self.handle_exception(exc)
  File "/Users/xiao2/Desktop/Coder/MyBlog/server/venv/lib/python3.7/site-packages/rest_framework/views.py", line 465, in handle_exception
    self.raise_uncaught_exception(exc)
  File "/Users/xiao2/Desktop/Coder/MyBlog/server/venv/lib/python3.7/site-packages/rest_framework/views.py", line 476, in raise_uncaught_exception
    raise exc
  File "/Users/xiao2/Desktop/Coder/MyBlog/server/venv/lib/python3.7/site-packages/rest_framework/views.py", line 502, in dispatch
    response = handler(request, *args, **kwargs)
  File "/Users/xiao2/Desktop/Coder/MyBlog/server/blog/views.py", line 73, in get
    return self.post(request)
  File "/Users/xiao2/Desktop/Coder/MyBlog/server/blog/views.py", line 82, in post
    post_data = json.loads(request.body)
  File "/usr/local/Cellar/python/3.7.3/Frameworks/Python.framework/Versions/3.7/lib/python3.7/json/__init__.py", line 348, in loads
    return _default_decoder.decode(s)
  File "/usr/local/Cellar/python/3.7.3/Frameworks/Python.framework/Versions/3.7/lib/python3.7/json/decoder.py", line 337, in decode
    obj, end = self.raw_decode(s, idx=_w(s, 0).end())
  File "/usr/local/Cellar/python/3.7.3/Frameworks/Python.framework/Versions/3.7/lib/python3.7/json/decoder.py", line 355, in raw_decode
    raise JSONDecodeError("Expecting value", s, err.value) from None
json.decoder.JSONDecodeError: Expecting value: line 1 column 1 (char 0)
[2019-11-28 09:45:23,079][Thread-1:123145368936448][task_id:django.request][log.py:228][ERROR][Internal Server Error: /api2/api/articleList]
Traceback (most recent call last):
  File "/Users/xiao2/Desktop/Coder/MyBlog/server/venv/lib/python3.7/site-packages/django/core/handlers/exception.py", line 34, in inner
    response = get_response(request)
  File "/Users/xiao2/Desktop/Coder/MyBlog/server/venv/lib/python3.7/site-packages/django/core/handlers/base.py", line 115, in _get_response
    response = self.process_exception_by_middleware(e, request)
  File "/Users/xiao2/Desktop/Coder/MyBlog/server/venv/lib/python3.7/site-packages/django/core/handlers/base.py", line 113, in _get_response
    response = wrapped_callback(request, *callback_args, **callback_kwargs)
  File "/Users/xiao2/Desktop/Coder/MyBlog/server/venv/lib/python3.7/site-packages/django/views/decorators/csrf.py", line 54, in wrapped_view
    return view_func(*args, **kwargs)
  File "/Users/xiao2/Desktop/Coder/MyBlog/server/venv/lib/python3.7/site-packages/django/views/generic/base.py", line 71, in view
    return self.dispatch(request, *args, **kwargs)
  File "/Users/xiao2/Desktop/Coder/MyBlog/server/venv/lib/python3.7/site-packages/rest_framework/views.py", line 505, in dispatch
    response = self.handle_exception(exc)
  File "/Users/xiao2/Desktop/Coder/MyBlog/server/venv/lib/python3.7/site-packages/rest_framework/views.py", line 465, in handle_exception
    self.raise_uncaught_exception(exc)
  File "/Users/xiao2/Desktop/Coder/MyBlog/server/venv/lib/python3.7/site-packages/rest_framework/views.py", line 476, in raise_uncaught_exception
    raise exc
  File "/Users/xiao2/Desktop/Coder/MyBlog/server/venv/lib/python3.7/site-packages/rest_framework/views.py", line 502, in dispatch
    response = handler(request, *args, **kwargs)
  File "/Users/xiao2/Desktop/Coder/MyBlog/server/blog/views.py", line 73, in get
    return self.post(request)
  File "/Users/xiao2/Desktop/Coder/MyBlog/server/blog/views.py", line 82, in post
    post_data = json.loads(request.body)
  File "/usr/local/Cellar/python/3.7.3/Frameworks/Python.framework/Versions/3.7/lib/python3.7/json/__init__.py", line 348, in loads
    return _default_decoder.decode(s)
  File "/usr/local/Cellar/python/3.7.3/Frameworks/Python.framework/Versions/3.7/lib/python3.7/json/decoder.py", line 337, in decode
    obj, end = self.raw_decode(s, idx=_w(s, 0).end())
  File "/usr/local/Cellar/python/3.7.3/Frameworks/Python.framework/Versions/3.7/lib/python3.7/json/decoder.py", line 355, in raw_decode
    raise JSONDecodeError("Expecting value", s, err.value) from None
json.decoder.JSONDecodeError: Expecting value: line 1 column 1 (char 0)
[2019-11-28 09:52:50,169][Thread-1:123145545912320][task_id:django.request][log.py:228][ERROR][Internal Server Error: /api2/api/articleList]
Traceback (most recent call last):
  File "/Users/xiao2/Desktop/Coder/MyBlog/server/venv/lib/python3.7/site-packages/django/core/handlers/exception.py", line 34, in inner
    response = get_response(request)
  File "/Users/xiao2/Desktop/Coder/MyBlog/server/venv/lib/python3.7/site-packages/django/core/handlers/base.py", line 115, in _get_response
    response = self.process_exception_by_middleware(e, request)
  File "/Users/xiao2/Desktop/Coder/MyBlog/server/venv/lib/python3.7/site-packages/django/core/handlers/base.py", line 113, in _get_response
    response = wrapped_callback(request, *callback_args, **callback_kwargs)
  File "/Users/xiao2/Desktop/Coder/MyBlog/server/venv/lib/python3.7/site-packages/django/views/decorators/csrf.py", line 54, in wrapped_view
    return view_func(*args, **kwargs)
  File "/Users/xiao2/Desktop/Coder/MyBlog/server/venv/lib/python3.7/site-packages/django/views/generic/base.py", line 71, in view
    return self.dispatch(request, *args, **kwargs)
  File "/Users/xiao2/Desktop/Coder/MyBlog/server/venv/lib/python3.7/site-packages/rest_framework/views.py", line 505, in dispatch
    response = self.handle_exception(exc)
  File "/Users/xiao2/Desktop/Coder/MyBlog/server/venv/lib/python3.7/site-packages/rest_framework/views.py", line 465, in handle_exception
    self.raise_uncaught_exception(exc)
  File "/Users/xiao2/Desktop/Coder/MyBlog/server/venv/lib/python3.7/site-packages/rest_framework/views.py", line 476, in raise_uncaught_exception
    raise exc
  File "/Users/xiao2/Desktop/Coder/MyBlog/server/venv/lib/python3.7/site-packages/rest_framework/views.py", line 502, in dispatch
    response = handler(request, *args, **kwargs)
  File "/Users/xiao2/Desktop/Coder/MyBlog/server/blog/views.py", line 84, in post
    print(request.body)
  File "/Users/xiao2/Desktop/Coder/MyBlog/server/venv/lib/python3.7/site-packages/rest_framework/request.py", line 409, in __getattr__
    return getattr(self._request, attr)
  File "/Users/xiao2/Desktop/Coder/MyBlog/server/venv/lib/python3.7/site-packages/django/http/request.py", line 281, in body
    raise RawPostDataException("You cannot access body after reading from request's data stream")
django.http.request.RawPostDataException: You cannot access body after reading from request's data stream
[2019-11-28 09:53:13,053][Thread-1:123145545912320][task_id:django.request][log.py:228][ERROR][Internal Server Error: /api2/api/articleList]
Traceback (most recent call last):
  File "/Users/xiao2/Desktop/Coder/MyBlog/server/venv/lib/python3.7/site-packages/django/core/handlers/exception.py", line 34, in inner
    response = get_response(request)
  File "/Users/xiao2/Desktop/Coder/MyBlog/server/venv/lib/python3.7/site-packages/django/core/handlers/base.py", line 115, in _get_response
    response = self.process_exception_by_middleware(e, request)
  File "/Users/xiao2/Desktop/Coder/MyBlog/server/venv/lib/python3.7/site-packages/django/core/handlers/base.py", line 113, in _get_response
    response = wrapped_callback(request, *callback_args, **callback_kwargs)
  File "/Users/xiao2/Desktop/Coder/MyBlog/server/venv/lib/python3.7/site-packages/django/views/decorators/csrf.py", line 54, in wrapped_view
    return view_func(*args, **kwargs)
  File "/Users/xiao2/Desktop/Coder/MyBlog/server/venv/lib/python3.7/site-packages/django/views/generic/base.py", line 71, in view
    return self.dispatch(request, *args, **kwargs)
  File "/Users/xiao2/Desktop/Coder/MyBlog/server/venv/lib/python3.7/site-packages/rest_framework/views.py", line 505, in dispatch
    response = self.handle_exception(exc)
  File "/Users/xiao2/Desktop/Coder/MyBlog/server/venv/lib/python3.7/site-packages/rest_framework/views.py", line 465, in handle_exception
    self.raise_uncaught_exception(exc)
  File "/Users/xiao2/Desktop/Coder/MyBlog/server/venv/lib/python3.7/site-packages/rest_framework/views.py", line 476, in raise_uncaught_exception
    raise exc
  File "/Users/xiao2/Desktop/Coder/MyBlog/server/venv/lib/python3.7/site-packages/rest_framework/views.py", line 502, in dispatch
    response = handler(request, *args, **kwargs)
  File "/Users/xiao2/Desktop/Coder/MyBlog/server/blog/views.py", line 84, in post
    print(request.body)
  File "/Users/xiao2/Desktop/Coder/MyBlog/server/venv/lib/python3.7/site-packages/rest_framework/request.py", line 409, in __getattr__
    return getattr(self._request, attr)
  File "/Users/xiao2/Desktop/Coder/MyBlog/server/venv/lib/python3.7/site-packages/django/http/request.py", line 281, in body
    raise RawPostDataException("You cannot access body after reading from request's data stream")
django.http.request.RawPostDataException: You cannot access body after reading from request's data stream
[2019-11-28 09:53:49,373][Thread-1:123145545912320][task_id:django.request][log.py:228][ERROR][Internal Server Error: /api2/api/articleList]
Traceback (most recent call last):
  File "/Users/xiao2/Desktop/Coder/MyBlog/server/venv/lib/python3.7/site-packages/django/core/handlers/exception.py", line 34, in inner
    response = get_response(request)
  File "/Users/xiao2/Desktop/Coder/MyBlog/server/venv/lib/python3.7/site-packages/django/core/handlers/base.py", line 115, in _get_response
    response = self.process_exception_by_middleware(e, request)
  File "/Users/xiao2/Desktop/Coder/MyBlog/server/venv/lib/python3.7/site-packages/django/core/handlers/base.py", line 113, in _get_response
    response = wrapped_callback(request, *callback_args, **callback_kwargs)
  File "/Users/xiao2/Desktop/Coder/MyBlog/server/venv/lib/python3.7/site-packages/django/views/decorators/csrf.py", line 54, in wrapped_view
    return view_func(*args, **kwargs)
  File "/Users/xiao2/Desktop/Coder/MyBlog/server/venv/lib/python3.7/site-packages/django/views/generic/base.py", line 71, in view
    return self.dispatch(request, *args, **kwargs)
  File "/Users/xiao2/Desktop/Coder/MyBlog/server/venv/lib/python3.7/site-packages/rest_framework/views.py", line 505, in dispatch
    response = self.handle_exception(exc)
  File "/Users/xiao2/Desktop/Coder/MyBlog/server/venv/lib/python3.7/site-packages/rest_framework/views.py", line 465, in handle_exception
    self.raise_uncaught_exception(exc)
  File "/Users/xiao2/Desktop/Coder/MyBlog/server/venv/lib/python3.7/site-packages/rest_framework/views.py", line 476, in raise_uncaught_exception
    raise exc
  File "/Users/xiao2/Desktop/Coder/MyBlog/server/venv/lib/python3.7/site-packages/rest_framework/views.py", line 502, in dispatch
    response = handler(request, *args, **kwargs)
  File "/Users/xiao2/Desktop/Coder/MyBlog/server/blog/views.py", line 84, in post
    print(request.body)
  File "/Users/xiao2/Desktop/Coder/MyBlog/server/venv/lib/python3.7/site-packages/rest_framework/request.py", line 409, in __getattr__
    return getattr(self._request, attr)
  File "/Users/xiao2/Desktop/Coder/MyBlog/server/venv/lib/python3.7/site-packages/django/http/request.py", line 281, in body
    raise RawPostDataException("You cannot access body after reading from request's data stream")
django.http.request.RawPostDataException: You cannot access body after reading from request's data stream
[2019-11-28 10:03:51,904][Thread-1:123145449971712][task_id:django.request][log.py:228][ERROR][Internal Server Error: /api2/api/articleList]
Traceback (most recent call last):
  File "/Users/xiao2/Desktop/Coder/MyBlog/server/venv/lib/python3.7/site-packages/django/core/handlers/exception.py", line 34, in inner
    response = get_response(request)
  File "/Users/xiao2/Desktop/Coder/MyBlog/server/venv/lib/python3.7/site-packages/django/core/handlers/base.py", line 115, in _get_response
    response = self.process_exception_by_middleware(e, request)
  File "/Users/xiao2/Desktop/Coder/MyBlog/server/venv/lib/python3.7/site-packages/django/core/handlers/base.py", line 113, in _get_response
    response = wrapped_callback(request, *callback_args, **callback_kwargs)
  File "/Users/xiao2/Desktop/Coder/MyBlog/server/venv/lib/python3.7/site-packages/django/views/decorators/csrf.py", line 54, in wrapped_view
    return view_func(*args, **kwargs)
  File "/Users/xiao2/Desktop/Coder/MyBlog/server/venv/lib/python3.7/site-packages/django/views/generic/base.py", line 71, in view
    return self.dispatch(request, *args, **kwargs)
  File "/Users/xiao2/Desktop/Coder/MyBlog/server/venv/lib/python3.7/site-packages/rest_framework/views.py", line 505, in dispatch
    response = self.handle_exception(exc)
  File "/Users/xiao2/Desktop/Coder/MyBlog/server/venv/lib/python3.7/site-packages/rest_framework/views.py", line 465, in handle_exception
    self.raise_uncaught_exception(exc)
  File "/Users/xiao2/Desktop/Coder/MyBlog/server/venv/lib/python3.7/site-packages/rest_framework/views.py", line 476, in raise_uncaught_exception
    raise exc
  File "/Users/xiao2/Desktop/Coder/MyBlog/server/venv/lib/python3.7/site-packages/rest_framework/views.py", line 502, in dispatch
    response = handler(request, *args, **kwargs)
  File "/Users/xiao2/Desktop/Coder/MyBlog/server/blog/views.py", line 84, in post
    print(json.loads(request.data))
  File "/usr/local/Cellar/python/3.7.3/Frameworks/Python.framework/Versions/3.7/lib/python3.7/json/__init__.py", line 348, in loads
    return _default_decoder.decode(s)
  File "/usr/local/Cellar/python/3.7.3/Frameworks/Python.framework/Versions/3.7/lib/python3.7/json/decoder.py", line 337, in decode
    obj, end = self.raw_decode(s, idx=_w(s, 0).end())
  File "/usr/local/Cellar/python/3.7.3/Frameworks/Python.framework/Versions/3.7/lib/python3.7/json/decoder.py", line 353, in raw_decode
    obj, end = self.scan_once(s, idx)
json.decoder.JSONDecodeError: Expecting property name enclosed in double quotes: line 1 column 2 (char 1)
[2019-11-28 10:03:59,260][Thread-1:123145449971712][task_id:django.request][log.py:228][ERROR][Internal Server Error: /api2/api/articleList]
Traceback (most recent call last):
  File "/Users/xiao2/Desktop/Coder/MyBlog/server/venv/lib/python3.7/site-packages/django/core/handlers/exception.py", line 34, in inner
    response = get_response(request)
  File "/Users/xiao2/Desktop/Coder/MyBlog/server/venv/lib/python3.7/site-packages/django/core/handlers/base.py", line 115, in _get_response
    response = self.process_exception_by_middleware(e, request)
  File "/Users/xiao2/Desktop/Coder/MyBlog/server/venv/lib/python3.7/site-packages/django/core/handlers/base.py", line 113, in _get_response
    response = wrapped_callback(request, *callback_args, **callback_kwargs)
  File "/Users/xiao2/Desktop/Coder/MyBlog/server/venv/lib/python3.7/site-packages/django/views/decorators/csrf.py", line 54, in wrapped_view
    return view_func(*args, **kwargs)
  File "/Users/xiao2/Desktop/Coder/MyBlog/server/venv/lib/python3.7/site-packages/django/views/generic/base.py", line 71, in view
    return self.dispatch(request, *args, **kwargs)
  File "/Users/xiao2/Desktop/Coder/MyBlog/server/venv/lib/python3.7/site-packages/rest_framework/views.py", line 505, in dispatch
    response = self.handle_exception(exc)
  File "/Users/xiao2/Desktop/Coder/MyBlog/server/venv/lib/python3.7/site-packages/rest_framework/views.py", line 465, in handle_exception
    self.raise_uncaught_exception(exc)
  File "/Users/xiao2/Desktop/Coder/MyBlog/server/venv/lib/python3.7/site-packages/rest_framework/views.py", line 476, in raise_uncaught_exception
    raise exc
  File "/Users/xiao2/Desktop/Coder/MyBlog/server/venv/lib/python3.7/site-packages/rest_framework/views.py", line 502, in dispatch
    response = handler(request, *args, **kwargs)
  File "/Users/xiao2/Desktop/Coder/MyBlog/server/blog/views.py", line 73, in get
    return self.post(request)
  File "/Users/xiao2/Desktop/Coder/MyBlog/server/blog/views.py", line 84, in post
    print(json.loads(request.data))
  File "/usr/local/Cellar/python/3.7.3/Frameworks/Python.framework/Versions/3.7/lib/python3.7/json/__init__.py", line 341, in loads
    raise TypeError(f'the JSON object must be str, bytes or bytearray, '
TypeError: the JSON object must be str, bytes or bytearray, not dict
[2019-11-28 10:04:00,546][Thread-1:123145449971712][task_id:django.request][log.py:228][ERROR][Internal Server Error: /api2/api/articleList]
Traceback (most recent call last):
  File "/Users/xiao2/Desktop/Coder/MyBlog/server/venv/lib/python3.7/site-packages/django/core/handlers/exception.py", line 34, in inner
    response = get_response(request)
  File "/Users/xiao2/Desktop/Coder/MyBlog/server/venv/lib/python3.7/site-packages/django/core/handlers/base.py", line 115, in _get_response
    response = self.process_exception_by_middleware(e, request)
  File "/Users/xiao2/Desktop/Coder/MyBlog/server/venv/lib/python3.7/site-packages/django/core/handlers/base.py", line 113, in _get_response
    response = wrapped_callback(request, *callback_args, **callback_kwargs)
  File "/Users/xiao2/Desktop/Coder/MyBlog/server/venv/lib/python3.7/site-packages/django/views/decorators/csrf.py", line 54, in wrapped_view
    return view_func(*args, **kwargs)
  File "/Users/xiao2/Desktop/Coder/MyBlog/server/venv/lib/python3.7/site-packages/django/views/generic/base.py", line 71, in view
    return self.dispatch(request, *args, **kwargs)
  File "/Users/xiao2/Desktop/Coder/MyBlog/server/venv/lib/python3.7/site-packages/rest_framework/views.py", line 505, in dispatch
    response = self.handle_exception(exc)
  File "/Users/xiao2/Desktop/Coder/MyBlog/server/venv/lib/python3.7/site-packages/rest_framework/views.py", line 465, in handle_exception
    self.raise_uncaught_exception(exc)
  File "/Users/xiao2/Desktop/Coder/MyBlog/server/venv/lib/python3.7/site-packages/rest_framework/views.py", line 476, in raise_uncaught_exception
    raise exc
  File "/Users/xiao2/Desktop/Coder/MyBlog/server/venv/lib/python3.7/site-packages/rest_framework/views.py", line 502, in dispatch
    response = handler(request, *args, **kwargs)
  File "/Users/xiao2/Desktop/Coder/MyBlog/server/blog/views.py", line 73, in get
    return self.post(request)
  File "/Users/xiao2/Desktop/Coder/MyBlog/server/blog/views.py", line 84, in post
    print(json.loads(request.data))
  File "/usr/local/Cellar/python/3.7.3/Frameworks/Python.framework/Versions/3.7/lib/python3.7/json/__init__.py", line 341, in loads
    raise TypeError(f'the JSON object must be str, bytes or bytearray, '
TypeError: the JSON object must be str, bytes or bytearray, not dict
[2019-11-28 10:04:01,756][Thread-1:123145449971712][task_id:django.request][log.py:228][ERROR][Internal Server Error: /api2/api/articleList]
Traceback (most recent call last):
  File "/Users/xiao2/Desktop/Coder/MyBlog/server/venv/lib/python3.7/site-packages/django/core/handlers/exception.py", line 34, in inner
    response = get_response(request)
  File "/Users/xiao2/Desktop/Coder/MyBlog/server/venv/lib/python3.7/site-packages/django/core/handlers/base.py", line 115, in _get_response
    response = self.process_exception_by_middleware(e, request)
  File "/Users/xiao2/Desktop/Coder/MyBlog/server/venv/lib/python3.7/site-packages/django/core/handlers/base.py", line 113, in _get_response
    response = wrapped_callback(request, *callback_args, **callback_kwargs)
  File "/Users/xiao2/Desktop/Coder/MyBlog/server/venv/lib/python3.7/site-packages/django/views/decorators/csrf.py", line 54, in wrapped_view
    return view_func(*args, **kwargs)
  File "/Users/xiao2/Desktop/Coder/MyBlog/server/venv/lib/python3.7/site-packages/django/views/generic/base.py", line 71, in view
    return self.dispatch(request, *args, **kwargs)
  File "/Users/xiao2/Desktop/Coder/MyBlog/server/venv/lib/python3.7/site-packages/rest_framework/views.py", line 505, in dispatch
    response = self.handle_exception(exc)
  File "/Users/xiao2/Desktop/Coder/MyBlog/server/venv/lib/python3.7/site-packages/rest_framework/views.py", line 465, in handle_exception
    self.raise_uncaught_exception(exc)
  File "/Users/xiao2/Desktop/Coder/MyBlog/server/venv/lib/python3.7/site-packages/rest_framework/views.py", line 476, in raise_uncaught_exception
    raise exc
  File "/Users/xiao2/Desktop/Coder/MyBlog/server/venv/lib/python3.7/site-packages/rest_framework/views.py", line 502, in dispatch
    response = handler(request, *args, **kwargs)
  File "/Users/xiao2/Desktop/Coder/MyBlog/server/blog/views.py", line 73, in get
    return self.post(request)
  File "/Users/xiao2/Desktop/Coder/MyBlog/server/blog/views.py", line 84, in post
    print(json.loads(request.data))
  File "/usr/local/Cellar/python/3.7.3/Frameworks/Python.framework/Versions/3.7/lib/python3.7/json/__init__.py", line 341, in loads
    raise TypeError(f'the JSON object must be str, bytes or bytearray, '
TypeError: the JSON object must be str, bytes or bytearray, not dict
[2019-11-28 10:04:18,440][Thread-1:123145449971712][task_id:django.request][log.py:228][ERROR][Internal Server Error: /api2/api/articleList]
Traceback (most recent call last):
  File "/Users/xiao2/Desktop/Coder/MyBlog/server/venv/lib/python3.7/site-packages/django/core/handlers/exception.py", line 34, in inner
    response = get_response(request)
  File "/Users/xiao2/Desktop/Coder/MyBlog/server/venv/lib/python3.7/site-packages/django/core/handlers/base.py", line 115, in _get_response
    response = self.process_exception_by_middleware(e, request)
  File "/Users/xiao2/Desktop/Coder/MyBlog/server/venv/lib/python3.7/site-packages/django/core/handlers/base.py", line 113, in _get_response
    response = wrapped_callback(request, *callback_args, **callback_kwargs)
  File "/Users/xiao2/Desktop/Coder/MyBlog/server/venv/lib/python3.7/site-packages/django/views/decorators/csrf.py", line 54, in wrapped_view
    return view_func(*args, **kwargs)
  File "/Users/xiao2/Desktop/Coder/MyBlog/server/venv/lib/python3.7/site-packages/django/views/generic/base.py", line 71, in view
    return self.dispatch(request, *args, **kwargs)
  File "/Users/xiao2/Desktop/Coder/MyBlog/server/venv/lib/python3.7/site-packages/rest_framework/views.py", line 505, in dispatch
    response = self.handle_exception(exc)
  File "/Users/xiao2/Desktop/Coder/MyBlog/server/venv/lib/python3.7/site-packages/rest_framework/views.py", line 465, in handle_exception
    self.raise_uncaught_exception(exc)
  File "/Users/xiao2/Desktop/Coder/MyBlog/server/venv/lib/python3.7/site-packages/rest_framework/views.py", line 476, in raise_uncaught_exception
    raise exc
  File "/Users/xiao2/Desktop/Coder/MyBlog/server/venv/lib/python3.7/site-packages/rest_framework/views.py", line 502, in dispatch
    response = handler(request, *args, **kwargs)
  File "/Users/xiao2/Desktop/Coder/MyBlog/server/blog/views.py", line 73, in get
    return self.post(request)
  File "/Users/xiao2/Desktop/Coder/MyBlog/server/blog/views.py", line 84, in post
    print(json.loads(request.data))
  File "/usr/local/Cellar/python/3.7.3/Frameworks/Python.framework/Versions/3.7/lib/python3.7/json/__init__.py", line 341, in loads
    raise TypeError(f'the JSON object must be str, bytes or bytearray, '
TypeError: the JSON object must be str, bytes or bytearray, not dict
[2019-11-28 10:05:17,575][Thread-1:123145449971712][task_id:django.request][log.py:228][ERROR][Internal Server Error: /api2/api/articleList]
Traceback (most recent call last):
  File "/Users/xiao2/Desktop/Coder/MyBlog/server/venv/lib/python3.7/site-packages/django/core/handlers/exception.py", line 34, in inner
    response = get_response(request)
  File "/Users/xiao2/Desktop/Coder/MyBlog/server/venv/lib/python3.7/site-packages/django/core/handlers/base.py", line 115, in _get_response
    response = self.process_exception_by_middleware(e, request)
  File "/Users/xiao2/Desktop/Coder/MyBlog/server/venv/lib/python3.7/site-packages/django/core/handlers/base.py", line 113, in _get_response
    response = wrapped_callback(request, *callback_args, **callback_kwargs)
  File "/Users/xiao2/Desktop/Coder/MyBlog/server/venv/lib/python3.7/site-packages/django/views/decorators/csrf.py", line 54, in wrapped_view
    return view_func(*args, **kwargs)
  File "/Users/xiao2/Desktop/Coder/MyBlog/server/venv/lib/python3.7/site-packages/django/views/generic/base.py", line 71, in view
    return self.dispatch(request, *args, **kwargs)
  File "/Users/xiao2/Desktop/Coder/MyBlog/server/venv/lib/python3.7/site-packages/rest_framework/views.py", line 505, in dispatch
    response = self.handle_exception(exc)
  File "/Users/xiao2/Desktop/Coder/MyBlog/server/venv/lib/python3.7/site-packages/rest_framework/views.py", line 465, in handle_exception
    self.raise_uncaught_exception(exc)
  File "/Users/xiao2/Desktop/Coder/MyBlog/server/venv/lib/python3.7/site-packages/rest_framework/views.py", line 476, in raise_uncaught_exception
    raise exc
  File "/Users/xiao2/Desktop/Coder/MyBlog/server/venv/lib/python3.7/site-packages/rest_framework/views.py", line 502, in dispatch
    response = handler(request, *args, **kwargs)
  File "/Users/xiao2/Desktop/Coder/MyBlog/server/blog/views.py", line 73, in get
    return self.post(request)
  File "/Users/xiao2/Desktop/Coder/MyBlog/server/blog/views.py", line 84, in post
    print(json.loads(request.data))
  File "/usr/local/Cellar/python/3.7.3/Frameworks/Python.framework/Versions/3.7/lib/python3.7/json/__init__.py", line 341, in loads
    raise TypeError(f'the JSON object must be str, bytes or bytearray, '
TypeError: the JSON object must be str, bytes or bytearray, not dict
[2019-11-28 10:10:06,455][Thread-1:123145320808448][task_id:django.request][log.py:228][ERROR][Internal Server Error: /api2/api/articleList]
Traceback (most recent call last):
  File "/Users/xiao2/Desktop/Coder/MyBlog/server/venv/lib/python3.7/site-packages/django/core/handlers/exception.py", line 34, in inner
    response = get_response(request)
  File "/Users/xiao2/Desktop/Coder/MyBlog/server/venv/lib/python3.7/site-packages/django/core/handlers/base.py", line 115, in _get_response
    response = self.process_exception_by_middleware(e, request)
  File "/Users/xiao2/Desktop/Coder/MyBlog/server/venv/lib/python3.7/site-packages/django/core/handlers/base.py", line 113, in _get_response
    response = wrapped_callback(request, *callback_args, **callback_kwargs)
  File "/Users/xiao2/Desktop/Coder/MyBlog/server/venv/lib/python3.7/site-packages/django/views/decorators/csrf.py", line 54, in wrapped_view
    return view_func(*args, **kwargs)
  File "/Users/xiao2/Desktop/Coder/MyBlog/server/venv/lib/python3.7/site-packages/django/views/generic/base.py", line 71, in view
    return self.dispatch(request, *args, **kwargs)
  File "/Users/xiao2/Desktop/Coder/MyBlog/server/venv/lib/python3.7/site-packages/rest_framework/views.py", line 505, in dispatch
    response = self.handle_exception(exc)
  File "/Users/xiao2/Desktop/Coder/MyBlog/server/venv/lib/python3.7/site-packages/rest_framework/views.py", line 465, in handle_exception
    self.raise_uncaught_exception(exc)
  File "/Users/xiao2/Desktop/Coder/MyBlog/server/venv/lib/python3.7/site-packages/rest_framework/views.py", line 476, in raise_uncaught_exception
    raise exc
  File "/Users/xiao2/Desktop/Coder/MyBlog/server/venv/lib/python3.7/site-packages/rest_framework/views.py", line 502, in dispatch
    response = handler(request, *args, **kwargs)
  File "/Users/xiao2/Desktop/Coder/MyBlog/server/blog/views.py", line 82, in post
    if isinstance(post_data, str) and len(str) > 0:
TypeError: object of type 'type' has no len()
[2019-11-28 10:15:27,660][Thread-2:123145350393856][task_id:django.request][log.py:228][ERROR][Internal Server Error: /api2/api/articleList]
Traceback (most recent call last):
  File "/Users/xiao2/Desktop/Coder/MyBlog/server/venv/lib/python3.7/site-packages/django/core/handlers/exception.py", line 34, in inner
    response = get_response(request)
  File "/Users/xiao2/Desktop/Coder/MyBlog/server/venv/lib/python3.7/site-packages/django/core/handlers/base.py", line 115, in _get_response
    response = self.process_exception_by_middleware(e, request)
  File "/Users/xiao2/Desktop/Coder/MyBlog/server/venv/lib/python3.7/site-packages/django/core/handlers/base.py", line 113, in _get_response
    response = wrapped_callback(request, *callback_args, **callback_kwargs)
  File "/Users/xiao2/Desktop/Coder/MyBlog/server/venv/lib/python3.7/site-packages/django/views/decorators/csrf.py", line 54, in wrapped_view
    return view_func(*args, **kwargs)
  File "/Users/xiao2/Desktop/Coder/MyBlog/server/venv/lib/python3.7/site-packages/django/views/generic/base.py", line 71, in view
    return self.dispatch(request, *args, **kwargs)
  File "/Users/xiao2/Desktop/Coder/MyBlog/server/venv/lib/python3.7/site-packages/rest_framework/views.py", line 505, in dispatch
    response = self.handle_exception(exc)
  File "/Users/xiao2/Desktop/Coder/MyBlog/server/venv/lib/python3.7/site-packages/rest_framework/views.py", line 465, in handle_exception
    self.raise_uncaught_exception(exc)
  File "/Users/xiao2/Desktop/Coder/MyBlog/server/venv/lib/python3.7/site-packages/rest_framework/views.py", line 476, in raise_uncaught_exception
    raise exc
  File "/Users/xiao2/Desktop/Coder/MyBlog/server/venv/lib/python3.7/site-packages/rest_framework/views.py", line 502, in dispatch
    response = handler(request, *args, **kwargs)
  File "/Users/xiao2/Desktop/Coder/MyBlog/server/blog/views.py", line 94, in post
    category = post_data.get('category', None)
AttributeError: 'int' object has no attribute 'get'
[2019-11-28 10:16:35,741][Thread-6:123145464815616][task_id:django.request][log.py:228][ERROR][Internal Server Error: /api2/api/articleList]
Traceback (most recent call last):
  File "/Users/xiao2/Desktop/Coder/MyBlog/server/blog/views.py", line 97, in post
    category = post_data.get('category', None)
AttributeError: 'int' object has no attribute 'get'

During handling of the above exception, another exception occurred:

Traceback (most recent call last):
  File "/Users/xiao2/Desktop/Coder/MyBlog/server/venv/lib/python3.7/site-packages/django/core/handlers/exception.py", line 34, in inner
    response = get_response(request)
  File "/Users/xiao2/Desktop/Coder/MyBlog/server/venv/lib/python3.7/site-packages/django/core/handlers/base.py", line 115, in _get_response
    response = self.process_exception_by_middleware(e, request)
  File "/Users/xiao2/Desktop/Coder/MyBlog/server/venv/lib/python3.7/site-packages/django/core/handlers/base.py", line 113, in _get_response
    response = wrapped_callback(request, *callback_args, **callback_kwargs)
  File "/Users/xiao2/Desktop/Coder/MyBlog/server/venv/lib/python3.7/site-packages/django/views/decorators/csrf.py", line 54, in wrapped_view
    return view_func(*args, **kwargs)
  File "/Users/xiao2/Desktop/Coder/MyBlog/server/venv/lib/python3.7/site-packages/django/views/generic/base.py", line 71, in view
    return self.dispatch(request, *args, **kwargs)
  File "/Users/xiao2/Desktop/Coder/MyBlog/server/venv/lib/python3.7/site-packages/rest_framework/views.py", line 505, in dispatch
    response = self.handle_exception(exc)
  File "/Users/xiao2/Desktop/Coder/MyBlog/server/venv/lib/python3.7/site-packages/rest_framework/views.py", line 465, in handle_exception
    self.raise_uncaught_exception(exc)
  File "/Users/xiao2/Desktop/Coder/MyBlog/server/venv/lib/python3.7/site-packages/rest_framework/views.py", line 476, in raise_uncaught_exception
    raise exc
  File "/Users/xiao2/Desktop/Coder/MyBlog/server/venv/lib/python3.7/site-packages/rest_framework/views.py", line 502, in dispatch
    response = handler(request, *args, **kwargs)
  File "/Users/xiao2/Desktop/Coder/MyBlog/server/blog/views.py", line 111, in post
    return my_response(code=-1, msg=err.default_detail)
AttributeError: 'AttributeError' object has no attribute 'default_detail'
[2019-11-28 10:16:52,014][Thread-3:123145427558400][task_id:django.request][log.py:228][ERROR][Internal Server Error: /api2/api/articleList]
Traceback (most recent call last):
  File "/Users/xiao2/Desktop/Coder/MyBlog/server/venv/lib/python3.7/site-packages/django/core/handlers/exception.py", line 34, in inner
    response = get_response(request)
  File "/Users/xiao2/Desktop/Coder/MyBlog/server/venv/lib/python3.7/site-packages/django/core/handlers/base.py", line 145, in _get_response
    response = self.process_exception_by_middleware(e, request)
  File "/Users/xiao2/Desktop/Coder/MyBlog/server/venv/lib/python3.7/site-packages/django/core/handlers/base.py", line 143, in _get_response
    response = response.render()
  File "/Users/xiao2/Desktop/Coder/MyBlog/server/venv/lib/python3.7/site-packages/django/template/response.py", line 106, in render
    self.content = self.rendered_content
  File "/Users/xiao2/Desktop/Coder/MyBlog/server/venv/lib/python3.7/site-packages/rest_framework/response.py", line 70, in rendered_content
    ret = renderer.render(self.data, accepted_media_type, context)
  File "/Users/xiao2/Desktop/Coder/MyBlog/server/venv/lib/python3.7/site-packages/rest_framework/renderers.py", line 725, in render
    context = self.get_context(data, accepted_media_type, renderer_context)
  File "/Users/xiao2/Desktop/Coder/MyBlog/server/venv/lib/python3.7/site-packages/rest_framework/renderers.py", line 681, in get_context
    'content': self.get_content(renderer, data, accepted_media_type, renderer_context),
  File "/Users/xiao2/Desktop/Coder/MyBlog/server/venv/lib/python3.7/site-packages/rest_framework/renderers.py", line 414, in get_content
    content = renderer.render(data, accepted_media_type, renderer_context)
  File "/Users/xiao2/Desktop/Coder/MyBlog/server/venv/lib/python3.7/site-packages/rest_framework/renderers.py", line 104, in render
    allow_nan=not self.strict, separators=separators
  File "/Users/xiao2/Desktop/Coder/MyBlog/server/venv/lib/python3.7/site-packages/rest_framework/utils/json.py", line 25, in dumps
    return json.dumps(*args, **kwargs)
  File "/usr/local/Cellar/python/3.7.3/Frameworks/Python.framework/Versions/3.7/lib/python3.7/json/__init__.py", line 238, in dumps
    **kw).encode(obj)
  File "/usr/local/Cellar/python/3.7.3/Frameworks/Python.framework/Versions/3.7/lib/python3.7/json/encoder.py", line 201, in encode
    chunks = list(chunks)
  File "/usr/local/Cellar/python/3.7.3/Frameworks/Python.framework/Versions/3.7/lib/python3.7/json/encoder.py", line 431, in _iterencode
    yield from _iterencode_dict(o, _current_indent_level)
  File "/usr/local/Cellar/python/3.7.3/Frameworks/Python.framework/Versions/3.7/lib/python3.7/json/encoder.py", line 405, in _iterencode_dict
    yield from chunks
  File "/usr/local/Cellar/python/3.7.3/Frameworks/Python.framework/Versions/3.7/lib/python3.7/json/encoder.py", line 438, in _iterencode
    o = _default(o)
  File "/Users/xiao2/Desktop/Coder/MyBlog/server/venv/lib/python3.7/site-packages/rest_framework/utils/encoders.py", line 67, in default
    return super().default(obj)
  File "/usr/local/Cellar/python/3.7.3/Frameworks/Python.framework/Versions/3.7/lib/python3.7/json/encoder.py", line 179, in default
    raise TypeError(f'Object of type {o.__class__.__name__} '
TypeError: Object of type AttributeError is not JSON serializable
[2019-11-28 10:17:13,975][Thread-1:123145400762368][task_id:django.request][log.py:228][ERROR][Internal Server Error: /api2/api/articleList]
Traceback (most recent call last):
  File "/Users/xiao2/Desktop/Coder/MyBlog/server/venv/lib/python3.7/site-packages/django/core/handlers/exception.py", line 34, in inner
    response = get_response(request)
  File "/Users/xiao2/Desktop/Coder/MyBlog/server/venv/lib/python3.7/site-packages/django/core/handlers/base.py", line 145, in _get_response
    response = self.process_exception_by_middleware(e, request)
  File "/Users/xiao2/Desktop/Coder/MyBlog/server/venv/lib/python3.7/site-packages/django/core/handlers/base.py", line 143, in _get_response
    response = response.render()
  File "/Users/xiao2/Desktop/Coder/MyBlog/server/venv/lib/python3.7/site-packages/django/template/response.py", line 106, in render
    self.content = self.rendered_content
  File "/Users/xiao2/Desktop/Coder/MyBlog/server/venv/lib/python3.7/site-packages/rest_framework/response.py", line 70, in rendered_content
    ret = renderer.render(self.data, accepted_media_type, context)
  File "/Users/xiao2/Desktop/Coder/MyBlog/server/venv/lib/python3.7/site-packages/rest_framework/renderers.py", line 725, in render
    context = self.get_context(data, accepted_media_type, renderer_context)
  File "/Users/xiao2/Desktop/Coder/MyBlog/server/venv/lib/python3.7/site-packages/rest_framework/renderers.py", line 681, in get_context
    'content': self.get_content(renderer, data, accepted_media_type, renderer_context),
  File "/Users/xiao2/Desktop/Coder/MyBlog/server/venv/lib/python3.7/site-packages/rest_framework/renderers.py", line 414, in get_content
    content = renderer.render(data, accepted_media_type, renderer_context)
  File "/Users/xiao2/Desktop/Coder/MyBlog/server/venv/lib/python3.7/site-packages/rest_framework/renderers.py", line 104, in render
    allow_nan=not self.strict, separators=separators
  File "/Users/xiao2/Desktop/Coder/MyBlog/server/venv/lib/python3.7/site-packages/rest_framework/utils/json.py", line 25, in dumps
    return json.dumps(*args, **kwargs)
  File "/usr/local/Cellar/python/3.7.3/Frameworks/Python.framework/Versions/3.7/lib/python3.7/json/__init__.py", line 238, in dumps
    **kw).encode(obj)
  File "/usr/local/Cellar/python/3.7.3/Frameworks/Python.framework/Versions/3.7/lib/python3.7/json/encoder.py", line 201, in encode
    chunks = list(chunks)
  File "/usr/local/Cellar/python/3.7.3/Frameworks/Python.framework/Versions/3.7/lib/python3.7/json/encoder.py", line 431, in _iterencode
    yield from _iterencode_dict(o, _current_indent_level)
  File "/usr/local/Cellar/python/3.7.3/Frameworks/Python.framework/Versions/3.7/lib/python3.7/json/encoder.py", line 405, in _iterencode_dict
    yield from chunks
  File "/usr/local/Cellar/python/3.7.3/Frameworks/Python.framework/Versions/3.7/lib/python3.7/json/encoder.py", line 438, in _iterencode
    o = _default(o)
  File "/Users/xiao2/Desktop/Coder/MyBlog/server/venv/lib/python3.7/site-packages/rest_framework/utils/encoders.py", line 67, in default
    return super().default(obj)
  File "/usr/local/Cellar/python/3.7.3/Frameworks/Python.framework/Versions/3.7/lib/python3.7/json/encoder.py", line 179, in default
    raise TypeError(f'Object of type {o.__class__.__name__} '
TypeError: Object of type AttributeError is not JSON serializable
[2019-11-28 10:17:33,786][Thread-3:123145411272704][task_id:django.request][log.py:228][ERROR][Internal Server Error: /api2/api/articleList]
Traceback (most recent call last):
  File "/Users/xiao2/Desktop/Coder/MyBlog/server/venv/lib/python3.7/site-packages/django/core/handlers/exception.py", line 34, in inner
    response = get_response(request)
  File "/Users/xiao2/Desktop/Coder/MyBlog/server/venv/lib/python3.7/site-packages/django/core/handlers/base.py", line 145, in _get_response
    response = self.process_exception_by_middleware(e, request)
  File "/Users/xiao2/Desktop/Coder/MyBlog/server/venv/lib/python3.7/site-packages/django/core/handlers/base.py", line 143, in _get_response
    response = response.render()
  File "/Users/xiao2/Desktop/Coder/MyBlog/server/venv/lib/python3.7/site-packages/django/template/response.py", line 106, in render
    self.content = self.rendered_content
  File "/Users/xiao2/Desktop/Coder/MyBlog/server/venv/lib/python3.7/site-packages/rest_framework/response.py", line 70, in rendered_content
    ret = renderer.render(self.data, accepted_media_type, context)
  File "/Users/xiao2/Desktop/Coder/MyBlog/server/venv/lib/python3.7/site-packages/rest_framework/renderers.py", line 725, in render
    context = self.get_context(data, accepted_media_type, renderer_context)
  File "/Users/xiao2/Desktop/Coder/MyBlog/server/venv/lib/python3.7/site-packages/rest_framework/renderers.py", line 681, in get_context
    'content': self.get_content(renderer, data, accepted_media_type, renderer_context),
  File "/Users/xiao2/Desktop/Coder/MyBlog/server/venv/lib/python3.7/site-packages/rest_framework/renderers.py", line 414, in get_content
    content = renderer.render(data, accepted_media_type, renderer_context)
  File "/Users/xiao2/Desktop/Coder/MyBlog/server/venv/lib/python3.7/site-packages/rest_framework/renderers.py", line 104, in render
    allow_nan=not self.strict, separators=separators
  File "/Users/xiao2/Desktop/Coder/MyBlog/server/venv/lib/python3.7/site-packages/rest_framework/utils/json.py", line 25, in dumps
    return json.dumps(*args, **kwargs)
  File "/usr/local/Cellar/python/3.7.3/Frameworks/Python.framework/Versions/3.7/lib/python3.7/json/__init__.py", line 238, in dumps
    **kw).encode(obj)
  File "/usr/local/Cellar/python/3.7.3/Frameworks/Python.framework/Versions/3.7/lib/python3.7/json/encoder.py", line 201, in encode
    chunks = list(chunks)
  File "/usr/local/Cellar/python/3.7.3/Frameworks/Python.framework/Versions/3.7/lib/python3.7/json/encoder.py", line 431, in _iterencode
    yield from _iterencode_dict(o, _current_indent_level)
  File "/usr/local/Cellar/python/3.7.3/Frameworks/Python.framework/Versions/3.7/lib/python3.7/json/encoder.py", line 405, in _iterencode_dict
    yield from chunks
  File "/usr/local/Cellar/python/3.7.3/Frameworks/Python.framework/Versions/3.7/lib/python3.7/json/encoder.py", line 438, in _iterencode
    o = _default(o)
  File "/Users/xiao2/Desktop/Coder/MyBlog/server/venv/lib/python3.7/site-packages/rest_framework/utils/encoders.py", line 67, in default
    return super().default(obj)
  File "/usr/local/Cellar/python/3.7.3/Frameworks/Python.framework/Versions/3.7/lib/python3.7/json/encoder.py", line 179, in default
    raise TypeError(f'Object of type {o.__class__.__name__} '
TypeError: Object of type AttributeError is not JSON serializable
[2019-11-28 10:17:42,630][Thread-7:123145400762368][task_id:django.request][log.py:228][ERROR][Internal Server Error: /api2/api/articleList]
Traceback (most recent call last):
  File "/Users/xiao2/Desktop/Coder/MyBlog/server/venv/lib/python3.7/site-packages/django/core/handlers/exception.py", line 34, in inner
    response = get_response(request)
  File "/Users/xiao2/Desktop/Coder/MyBlog/server/venv/lib/python3.7/site-packages/django/core/handlers/base.py", line 145, in _get_response
    response = self.process_exception_by_middleware(e, request)
  File "/Users/xiao2/Desktop/Coder/MyBlog/server/venv/lib/python3.7/site-packages/django/core/handlers/base.py", line 143, in _get_response
    response = response.render()
  File "/Users/xiao2/Desktop/Coder/MyBlog/server/venv/lib/python3.7/site-packages/django/template/response.py", line 106, in render
    self.content = self.rendered_content
  File "/Users/xiao2/Desktop/Coder/MyBlog/server/venv/lib/python3.7/site-packages/rest_framework/response.py", line 70, in rendered_content
    ret = renderer.render(self.data, accepted_media_type, context)
  File "/Users/xiao2/Desktop/Coder/MyBlog/server/venv/lib/python3.7/site-packages/rest_framework/renderers.py", line 725, in render
    context = self.get_context(data, accepted_media_type, renderer_context)
  File "/Users/xiao2/Desktop/Coder/MyBlog/server/venv/lib/python3.7/site-packages/rest_framework/renderers.py", line 681, in get_context
    'content': self.get_content(renderer, data, accepted_media_type, renderer_context),
  File "/Users/xiao2/Desktop/Coder/MyBlog/server/venv/lib/python3.7/site-packages/rest_framework/renderers.py", line 414, in get_content
    content = renderer.render(data, accepted_media_type, renderer_context)
  File "/Users/xiao2/Desktop/Coder/MyBlog/server/venv/lib/python3.7/site-packages/rest_framework/renderers.py", line 104, in render
    allow_nan=not self.strict, separators=separators
  File "/Users/xiao2/Desktop/Coder/MyBlog/server/venv/lib/python3.7/site-packages/rest_framework/utils/json.py", line 25, in dumps
    return json.dumps(*args, **kwargs)
  File "/usr/local/Cellar/python/3.7.3/Frameworks/Python.framework/Versions/3.7/lib/python3.7/json/__init__.py", line 238, in dumps
    **kw).encode(obj)
  File "/usr/local/Cellar/python/3.7.3/Frameworks/Python.framework/Versions/3.7/lib/python3.7/json/encoder.py", line 201, in encode
    chunks = list(chunks)
  File "/usr/local/Cellar/python/3.7.3/Frameworks/Python.framework/Versions/3.7/lib/python3.7/json/encoder.py", line 431, in _iterencode
    yield from _iterencode_dict(o, _current_indent_level)
  File "/usr/local/Cellar/python/3.7.3/Frameworks/Python.framework/Versions/3.7/lib/python3.7/json/encoder.py", line 405, in _iterencode_dict
    yield from chunks
  File "/usr/local/Cellar/python/3.7.3/Frameworks/Python.framework/Versions/3.7/lib/python3.7/json/encoder.py", line 438, in _iterencode
    o = _default(o)
  File "/Users/xiao2/Desktop/Coder/MyBlog/server/venv/lib/python3.7/site-packages/rest_framework/utils/encoders.py", line 67, in default
    return super().default(obj)
  File "/usr/local/Cellar/python/3.7.3/Frameworks/Python.framework/Versions/3.7/lib/python3.7/json/encoder.py", line 179, in default
    raise TypeError(f'Object of type {o.__class__.__name__} '
TypeError: Object of type AttributeError is not JSON serializable
[2019-11-28 10:20:58,049][Thread-9:123145400762368][task_id:django.request][log.py:228][ERROR][Internal Server Error: /api2/api/articleList]
Traceback (most recent call last):
  File "/Users/xiao2/Desktop/Coder/MyBlog/server/venv/lib/python3.7/site-packages/django/core/handlers/exception.py", line 34, in inner
    response = get_response(request)
  File "/Users/xiao2/Desktop/Coder/MyBlog/server/venv/lib/python3.7/site-packages/django/core/handlers/base.py", line 145, in _get_response
    response = self.process_exception_by_middleware(e, request)
  File "/Users/xiao2/Desktop/Coder/MyBlog/server/venv/lib/python3.7/site-packages/django/core/handlers/base.py", line 143, in _get_response
    response = response.render()
  File "/Users/xiao2/Desktop/Coder/MyBlog/server/venv/lib/python3.7/site-packages/django/template/response.py", line 106, in render
    self.content = self.rendered_content
  File "/Users/xiao2/Desktop/Coder/MyBlog/server/venv/lib/python3.7/site-packages/rest_framework/response.py", line 70, in rendered_content
    ret = renderer.render(self.data, accepted_media_type, context)
  File "/Users/xiao2/Desktop/Coder/MyBlog/server/venv/lib/python3.7/site-packages/rest_framework/renderers.py", line 725, in render
    context = self.get_context(data, accepted_media_type, renderer_context)
  File "/Users/xiao2/Desktop/Coder/MyBlog/server/venv/lib/python3.7/site-packages/rest_framework/renderers.py", line 681, in get_context
    'content': self.get_content(renderer, data, accepted_media_type, renderer_context),
  File "/Users/xiao2/Desktop/Coder/MyBlog/server/venv/lib/python3.7/site-packages/rest_framework/renderers.py", line 414, in get_content
    content = renderer.render(data, accepted_media_type, renderer_context)
  File "/Users/xiao2/Desktop/Coder/MyBlog/server/venv/lib/python3.7/site-packages/rest_framework/renderers.py", line 104, in render
    allow_nan=not self.strict, separators=separators
  File "/Users/xiao2/Desktop/Coder/MyBlog/server/venv/lib/python3.7/site-packages/rest_framework/utils/json.py", line 25, in dumps
    return json.dumps(*args, **kwargs)
  File "/usr/local/Cellar/python/3.7.3/Frameworks/Python.framework/Versions/3.7/lib/python3.7/json/__init__.py", line 238, in dumps
    **kw).encode(obj)
  File "/usr/local/Cellar/python/3.7.3/Frameworks/Python.framework/Versions/3.7/lib/python3.7/json/encoder.py", line 201, in encode
    chunks = list(chunks)
  File "/usr/local/Cellar/python/3.7.3/Frameworks/Python.framework/Versions/3.7/lib/python3.7/json/encoder.py", line 431, in _iterencode
    yield from _iterencode_dict(o, _current_indent_level)
  File "/usr/local/Cellar/python/3.7.3/Frameworks/Python.framework/Versions/3.7/lib/python3.7/json/encoder.py", line 405, in _iterencode_dict
    yield from chunks
  File "/usr/local/Cellar/python/3.7.3/Frameworks/Python.framework/Versions/3.7/lib/python3.7/json/encoder.py", line 438, in _iterencode
    o = _default(o)
  File "/Users/xiao2/Desktop/Coder/MyBlog/server/venv/lib/python3.7/site-packages/rest_framework/utils/encoders.py", line 67, in default
    return super().default(obj)
  File "/usr/local/Cellar/python/3.7.3/Frameworks/Python.framework/Versions/3.7/lib/python3.7/json/encoder.py", line 179, in default
    raise TypeError(f'Object of type {o.__class__.__name__} '
TypeError: Object of type AttributeError is not JSON serializable
[2019-11-28 10:25:28,402][Thread-1:123145373249536][task_id:django.request][log.py:228][ERROR][Internal Server Error: /api2/api/articleList]
Traceback (most recent call last):
  File "/Users/xiao2/Desktop/Coder/MyBlog/server/venv/lib/python3.7/site-packages/django/core/handlers/exception.py", line 34, in inner
    response = get_response(request)
  File "/Users/xiao2/Desktop/Coder/MyBlog/server/venv/lib/python3.7/site-packages/django/core/handlers/base.py", line 145, in _get_response
    response = self.process_exception_by_middleware(e, request)
  File "/Users/xiao2/Desktop/Coder/MyBlog/server/venv/lib/python3.7/site-packages/django/core/handlers/base.py", line 143, in _get_response
    response = response.render()
  File "/Users/xiao2/Desktop/Coder/MyBlog/server/venv/lib/python3.7/site-packages/django/template/response.py", line 106, in render
    self.content = self.rendered_content
  File "/Users/xiao2/Desktop/Coder/MyBlog/server/venv/lib/python3.7/site-packages/rest_framework/response.py", line 70, in rendered_content
    ret = renderer.render(self.data, accepted_media_type, context)
  File "/Users/xiao2/Desktop/Coder/MyBlog/server/venv/lib/python3.7/site-packages/rest_framework/renderers.py", line 725, in render
    context = self.get_context(data, accepted_media_type, renderer_context)
  File "/Users/xiao2/Desktop/Coder/MyBlog/server/venv/lib/python3.7/site-packages/rest_framework/renderers.py", line 681, in get_context
    'content': self.get_content(renderer, data, accepted_media_type, renderer_context),
  File "/Users/xiao2/Desktop/Coder/MyBlog/server/venv/lib/python3.7/site-packages/rest_framework/renderers.py", line 414, in get_content
    content = renderer.render(data, accepted_media_type, renderer_context)
  File "/Users/xiao2/Desktop/Coder/MyBlog/server/venv/lib/python3.7/site-packages/rest_framework/renderers.py", line 104, in render
    allow_nan=not self.strict, separators=separators
  File "/Users/xiao2/Desktop/Coder/MyBlog/server/venv/lib/python3.7/site-packages/rest_framework/utils/json.py", line 25, in dumps
    return json.dumps(*args, **kwargs)
  File "/usr/local/Cellar/python/3.7.3/Frameworks/Python.framework/Versions/3.7/lib/python3.7/json/__init__.py", line 238, in dumps
    **kw).encode(obj)
  File "/usr/local/Cellar/python/3.7.3/Frameworks/Python.framework/Versions/3.7/lib/python3.7/json/encoder.py", line 201, in encode
    chunks = list(chunks)
  File "/usr/local/Cellar/python/3.7.3/Frameworks/Python.framework/Versions/3.7/lib/python3.7/json/encoder.py", line 431, in _iterencode
    yield from _iterencode_dict(o, _current_indent_level)
  File "/usr/local/Cellar/python/3.7.3/Frameworks/Python.framework/Versions/3.7/lib/python3.7/json/encoder.py", line 405, in _iterencode_dict
    yield from chunks
  File "/usr/local/Cellar/python/3.7.3/Frameworks/Python.framework/Versions/3.7/lib/python3.7/json/encoder.py", line 438, in _iterencode
    o = _default(o)
  File "/Users/xiao2/Desktop/Coder/MyBlog/server/venv/lib/python3.7/site-packages/rest_framework/utils/encoders.py", line 67, in default
    return super().default(obj)
  File "/usr/local/Cellar/python/3.7.3/Frameworks/Python.framework/Versions/3.7/lib/python3.7/json/encoder.py", line 179, in default
    raise TypeError(f'Object of type {o.__class__.__name__} '
TypeError: Object of type AttributeError is not JSON serializable
[2019-11-28 10:37:42,866][Thread-1:123145524813824][task_id:django.request][log.py:228][ERROR][Internal Server Error: /api2/api/articleList]
Traceback (most recent call last):
  File "/Users/xiao2/Desktop/Coder/MyBlog/server/venv/lib/python3.7/site-packages/django/core/handlers/exception.py", line 34, in inner
    response = get_response(request)
  File "/Users/xiao2/Desktop/Coder/MyBlog/server/venv/lib/python3.7/site-packages/django/core/handlers/base.py", line 145, in _get_response
    response = self.process_exception_by_middleware(e, request)
  File "/Users/xiao2/Desktop/Coder/MyBlog/server/venv/lib/python3.7/site-packages/django/core/handlers/base.py", line 143, in _get_response
    response = response.render()
  File "/Users/xiao2/Desktop/Coder/MyBlog/server/venv/lib/python3.7/site-packages/django/template/response.py", line 106, in render
    self.content = self.rendered_content
  File "/Users/xiao2/Desktop/Coder/MyBlog/server/venv/lib/python3.7/site-packages/rest_framework/response.py", line 70, in rendered_content
    ret = renderer.render(self.data, accepted_media_type, context)
  File "/Users/xiao2/Desktop/Coder/MyBlog/server/venv/lib/python3.7/site-packages/rest_framework/renderers.py", line 104, in render
    allow_nan=not self.strict, separators=separators
  File "/Users/xiao2/Desktop/Coder/MyBlog/server/venv/lib/python3.7/site-packages/rest_framework/utils/json.py", line 25, in dumps
    return json.dumps(*args, **kwargs)
  File "/usr/local/Cellar/python/3.7.3/Frameworks/Python.framework/Versions/3.7/lib/python3.7/json/__init__.py", line 238, in dumps
    **kw).encode(obj)
  File "/usr/local/Cellar/python/3.7.3/Frameworks/Python.framework/Versions/3.7/lib/python3.7/json/encoder.py", line 199, in encode
    chunks = self.iterencode(o, _one_shot=True)
  File "/usr/local/Cellar/python/3.7.3/Frameworks/Python.framework/Versions/3.7/lib/python3.7/json/encoder.py", line 257, in iterencode
    return _iterencode(o, 0)
  File "/Users/xiao2/Desktop/Coder/MyBlog/server/venv/lib/python3.7/site-packages/rest_framework/utils/encoders.py", line 67, in default
    return super().default(obj)
  File "/usr/local/Cellar/python/3.7.3/Frameworks/Python.framework/Versions/3.7/lib/python3.7/json/encoder.py", line 179, in default
    raise TypeError(f'Object of type {o.__class__.__name__} '
TypeError: Object of type TypeError is not JSON serializable
[2019-11-28 10:48:35,660][Thread-1:123145326362624][task_id:django.request][log.py:228][ERROR][Internal Server Error: /api2/api/articleList]
Traceback (most recent call last):
  File "/Users/xiao2/Desktop/Coder/MyBlog/server/venv/lib/python3.7/site-packages/django/core/handlers/exception.py", line 34, in inner
    response = get_response(request)
  File "/Users/xiao2/Desktop/Coder/MyBlog/server/venv/lib/python3.7/site-packages/django/core/handlers/base.py", line 145, in _get_response
    response = self.process_exception_by_middleware(e, request)
  File "/Users/xiao2/Desktop/Coder/MyBlog/server/venv/lib/python3.7/site-packages/django/core/handlers/base.py", line 143, in _get_response
    response = response.render()
  File "/Users/xiao2/Desktop/Coder/MyBlog/server/venv/lib/python3.7/site-packages/django/template/response.py", line 106, in render
    self.content = self.rendered_content
  File "/Users/xiao2/Desktop/Coder/MyBlog/server/venv/lib/python3.7/site-packages/rest_framework/response.py", line 70, in rendered_content
    ret = renderer.render(self.data, accepted_media_type, context)
  File "/Users/xiao2/Desktop/Coder/MyBlog/server/venv/lib/python3.7/site-packages/rest_framework/renderers.py", line 104, in render
    allow_nan=not self.strict, separators=separators
  File "/Users/xiao2/Desktop/Coder/MyBlog/server/venv/lib/python3.7/site-packages/rest_framework/utils/json.py", line 25, in dumps
    return json.dumps(*args, **kwargs)
  File "/usr/local/Cellar/python/3.7.3/Frameworks/Python.framework/Versions/3.7/lib/python3.7/json/__init__.py", line 238, in dumps
    **kw).encode(obj)
  File "/usr/local/Cellar/python/3.7.3/Frameworks/Python.framework/Versions/3.7/lib/python3.7/json/encoder.py", line 199, in encode
    chunks = self.iterencode(o, _one_shot=True)
  File "/usr/local/Cellar/python/3.7.3/Frameworks/Python.framework/Versions/3.7/lib/python3.7/json/encoder.py", line 257, in iterencode
    return _iterencode(o, 0)
  File "/Users/xiao2/Desktop/Coder/MyBlog/server/venv/lib/python3.7/site-packages/rest_framework/utils/encoders.py", line 67, in default
    return super().default(obj)
  File "/usr/local/Cellar/python/3.7.3/Frameworks/Python.framework/Versions/3.7/lib/python3.7/json/encoder.py", line 179, in default
    raise TypeError(f'Object of type {o.__class__.__name__} '
TypeError: Object of type FieldError is not JSON serializable
[2019-11-28 10:49:12,298][Thread-1:123145387642880][task_id:django.request][log.py:228][ERROR][Internal Server Error: /api2/api/articleList]
Traceback (most recent call last):
  File "/Users/xiao2/Desktop/Coder/MyBlog/server/venv/lib/python3.7/site-packages/django/core/handlers/exception.py", line 34, in inner
    response = get_response(request)
  File "/Users/xiao2/Desktop/Coder/MyBlog/server/venv/lib/python3.7/site-packages/django/core/handlers/base.py", line 145, in _get_response
    response = self.process_exception_by_middleware(e, request)
  File "/Users/xiao2/Desktop/Coder/MyBlog/server/venv/lib/python3.7/site-packages/django/core/handlers/base.py", line 143, in _get_response
    response = response.render()
  File "/Users/xiao2/Desktop/Coder/MyBlog/server/venv/lib/python3.7/site-packages/django/template/response.py", line 106, in render
    self.content = self.rendered_content
  File "/Users/xiao2/Desktop/Coder/MyBlog/server/venv/lib/python3.7/site-packages/rest_framework/response.py", line 70, in rendered_content
    ret = renderer.render(self.data, accepted_media_type, context)
  File "/Users/xiao2/Desktop/Coder/MyBlog/server/venv/lib/python3.7/site-packages/rest_framework/renderers.py", line 104, in render
    allow_nan=not self.strict, separators=separators
  File "/Users/xiao2/Desktop/Coder/MyBlog/server/venv/lib/python3.7/site-packages/rest_framework/utils/json.py", line 25, in dumps
    return json.dumps(*args, **kwargs)
  File "/usr/local/Cellar/python/3.7.3/Frameworks/Python.framework/Versions/3.7/lib/python3.7/json/__init__.py", line 238, in dumps
    **kw).encode(obj)
  File "/usr/local/Cellar/python/3.7.3/Frameworks/Python.framework/Versions/3.7/lib/python3.7/json/encoder.py", line 199, in encode
    chunks = self.iterencode(o, _one_shot=True)
  File "/usr/local/Cellar/python/3.7.3/Frameworks/Python.framework/Versions/3.7/lib/python3.7/json/encoder.py", line 257, in iterencode
    return _iterencode(o, 0)
  File "/Users/xiao2/Desktop/Coder/MyBlog/server/venv/lib/python3.7/site-packages/rest_framework/utils/encoders.py", line 67, in default
    return super().default(obj)
  File "/usr/local/Cellar/python/3.7.3/Frameworks/Python.framework/Versions/3.7/lib/python3.7/json/encoder.py", line 179, in default
    raise TypeError(f'Object of type {o.__class__.__name__} '
TypeError: Object of type FieldError is not JSON serializable
[2019-11-28 14:44:56,529][Thread-1:123145370976256][task_id:django.request][log.py:228][ERROR][Internal Server Error: /api2/api/nextArticle]
Traceback (most recent call last):
  File "/Users/xiao2/Desktop/Coder/MyBlog/server/venv/lib/python3.7/site-packages/django/core/handlers/exception.py", line 34, in inner
    response = get_response(request)
  File "/Users/xiao2/Desktop/Coder/MyBlog/server/venv/lib/python3.7/site-packages/django/core/handlers/base.py", line 115, in _get_response
    response = self.process_exception_by_middleware(e, request)
  File "/Users/xiao2/Desktop/Coder/MyBlog/server/venv/lib/python3.7/site-packages/django/core/handlers/base.py", line 113, in _get_response
    response = wrapped_callback(request, *callback_args, **callback_kwargs)
  File "/Users/xiao2/Desktop/Coder/MyBlog/server/venv/lib/python3.7/site-packages/django/views/decorators/csrf.py", line 54, in wrapped_view
    return view_func(*args, **kwargs)
  File "/Users/xiao2/Desktop/Coder/MyBlog/server/venv/lib/python3.7/site-packages/django/views/generic/base.py", line 71, in view
    return self.dispatch(request, *args, **kwargs)
  File "/Users/xiao2/Desktop/Coder/MyBlog/server/venv/lib/python3.7/site-packages/rest_framework/views.py", line 505, in dispatch
    response = self.handle_exception(exc)
  File "/Users/xiao2/Desktop/Coder/MyBlog/server/venv/lib/python3.7/site-packages/rest_framework/views.py", line 465, in handle_exception
    self.raise_uncaught_exception(exc)
  File "/Users/xiao2/Desktop/Coder/MyBlog/server/venv/lib/python3.7/site-packages/rest_framework/views.py", line 476, in raise_uncaught_exception
    raise exc
  File "/Users/xiao2/Desktop/Coder/MyBlog/server/venv/lib/python3.7/site-packages/rest_framework/views.py", line 502, in dispatch
    response = handler(request, *args, **kwargs)
  File "/Users/xiao2/Desktop/Coder/MyBlog/server/blog/views.py", line 173, in post
    next = Article.objects.filter(pk_gt=id).first()
  File "/Users/xiao2/Desktop/Coder/MyBlog/server/venv/lib/python3.7/site-packages/django/db/models/manager.py", line 82, in manager_method
    return getattr(self.get_queryset(), name)(*args, **kwargs)
  File "/Users/xiao2/Desktop/Coder/MyBlog/server/venv/lib/python3.7/site-packages/django/db/models/query.py", line 892, in filter
    return self._filter_or_exclude(False, *args, **kwargs)
  File "/Users/xiao2/Desktop/Coder/MyBlog/server/venv/lib/python3.7/site-packages/django/db/models/query.py", line 910, in _filter_or_exclude
    clone.query.add_q(Q(*args, **kwargs))
  File "/Users/xiao2/Desktop/Coder/MyBlog/server/venv/lib/python3.7/site-packages/django/db/models/sql/query.py", line 1290, in add_q
    clause, _ = self._add_q(q_object, self.used_aliases)
  File "/Users/xiao2/Desktop/Coder/MyBlog/server/venv/lib/python3.7/site-packages/django/db/models/sql/query.py", line 1318, in _add_q
    split_subq=split_subq, simple_col=simple_col,
  File "/Users/xiao2/Desktop/Coder/MyBlog/server/venv/lib/python3.7/site-packages/django/db/models/sql/query.py", line 1190, in build_filter
    lookups, parts, reffed_expression = self.solve_lookup_type(arg)
  File "/Users/xiao2/Desktop/Coder/MyBlog/server/venv/lib/python3.7/site-packages/django/db/models/sql/query.py", line 1049, in solve_lookup_type
    _, field, _, lookup_parts = self.names_to_path(lookup_splitted, self.get_meta())
  File "/Users/xiao2/Desktop/Coder/MyBlog/server/venv/lib/python3.7/site-packages/django/db/models/sql/query.py", line 1420, in names_to_path
    "Choices are: %s" % (name, ", ".join(available)))
django.core.exceptions.FieldError: Cannot resolve keyword 'pk_gt' into field. Choices are: category, category_id, content, created_time, desc, id, is_delete, modify_time, tags, title, url
[2019-11-28 14:46:12,808][Thread-1:123145547870208][task_id:django.request][log.py:228][ERROR][Internal Server Error: /api2/api/nextArticle]
Traceback (most recent call last):
  File "/Users/xiao2/Desktop/Coder/MyBlog/server/venv/lib/python3.7/site-packages/django/core/handlers/exception.py", line 34, in inner
    response = get_response(request)
  File "/Users/xiao2/Desktop/Coder/MyBlog/server/venv/lib/python3.7/site-packages/django/core/handlers/base.py", line 115, in _get_response
    response = self.process_exception_by_middleware(e, request)
  File "/Users/xiao2/Desktop/Coder/MyBlog/server/venv/lib/python3.7/site-packages/django/core/handlers/base.py", line 113, in _get_response
    response = wrapped_callback(request, *callback_args, **callback_kwargs)
  File "/Users/xiao2/Desktop/Coder/MyBlog/server/venv/lib/python3.7/site-packages/django/views/decorators/csrf.py", line 54, in wrapped_view
    return view_func(*args, **kwargs)
  File "/Users/xiao2/Desktop/Coder/MyBlog/server/venv/lib/python3.7/site-packages/django/views/generic/base.py", line 71, in view
    return self.dispatch(request, *args, **kwargs)
  File "/Users/xiao2/Desktop/Coder/MyBlog/server/venv/lib/python3.7/site-packages/rest_framework/views.py", line 505, in dispatch
    response = self.handle_exception(exc)
  File "/Users/xiao2/Desktop/Coder/MyBlog/server/venv/lib/python3.7/site-packages/rest_framework/views.py", line 465, in handle_exception
    self.raise_uncaught_exception(exc)
  File "/Users/xiao2/Desktop/Coder/MyBlog/server/venv/lib/python3.7/site-packages/rest_framework/views.py", line 476, in raise_uncaught_exception
    raise exc
  File "/Users/xiao2/Desktop/Coder/MyBlog/server/venv/lib/python3.7/site-packages/rest_framework/views.py", line 502, in dispatch
    response = handler(request, *args, **kwargs)
  File "/Users/xiao2/Desktop/Coder/MyBlog/server/blog/views.py", line 173, in post
    next = Article.objects.filter(id_gt=id).first()
  File "/Users/xiao2/Desktop/Coder/MyBlog/server/venv/lib/python3.7/site-packages/django/db/models/manager.py", line 82, in manager_method
    return getattr(self.get_queryset(), name)(*args, **kwargs)
  File "/Users/xiao2/Desktop/Coder/MyBlog/server/venv/lib/python3.7/site-packages/django/db/models/query.py", line 892, in filter
    return self._filter_or_exclude(False, *args, **kwargs)
  File "/Users/xiao2/Desktop/Coder/MyBlog/server/venv/lib/python3.7/site-packages/django/db/models/query.py", line 910, in _filter_or_exclude
    clone.query.add_q(Q(*args, **kwargs))
  File "/Users/xiao2/Desktop/Coder/MyBlog/server/venv/lib/python3.7/site-packages/django/db/models/sql/query.py", line 1290, in add_q
    clause, _ = self._add_q(q_object, self.used_aliases)
  File "/Users/xiao2/Desktop/Coder/MyBlog/server/venv/lib/python3.7/site-packages/django/db/models/sql/query.py", line 1318, in _add_q
    split_subq=split_subq, simple_col=simple_col,
  File "/Users/xiao2/Desktop/Coder/MyBlog/server/venv/lib/python3.7/site-packages/django/db/models/sql/query.py", line 1190, in build_filter
    lookups, parts, reffed_expression = self.solve_lookup_type(arg)
  File "/Users/xiao2/Desktop/Coder/MyBlog/server/venv/lib/python3.7/site-packages/django/db/models/sql/query.py", line 1049, in solve_lookup_type
    _, field, _, lookup_parts = self.names_to_path(lookup_splitted, self.get_meta())
  File "/Users/xiao2/Desktop/Coder/MyBlog/server/venv/lib/python3.7/site-packages/django/db/models/sql/query.py", line 1420, in names_to_path
    "Choices are: %s" % (name, ", ".join(available)))
django.core.exceptions.FieldError: Cannot resolve keyword 'id_gt' into field. Choices are: category, category_id, content, created_time, desc, id, is_delete, modify_time, tags, title, url
[2019-11-28 14:47:15,608][Thread-1:123145412370432][task_id:django.request][log.py:228][ERROR][Internal Server Error: /api2/api/nextArticle]
Traceback (most recent call last):
  File "/Users/xiao2/Desktop/Coder/MyBlog/server/venv/lib/python3.7/site-packages/django/core/handlers/exception.py", line 34, in inner
    response = get_response(request)
  File "/Users/xiao2/Desktop/Coder/MyBlog/server/venv/lib/python3.7/site-packages/django/core/handlers/base.py", line 145, in _get_response
    response = self.process_exception_by_middleware(e, request)
  File "/Users/xiao2/Desktop/Coder/MyBlog/server/venv/lib/python3.7/site-packages/django/core/handlers/base.py", line 143, in _get_response
    response = response.render()
  File "/Users/xiao2/Desktop/Coder/MyBlog/server/venv/lib/python3.7/site-packages/django/template/response.py", line 106, in render
    self.content = self.rendered_content
  File "/Users/xiao2/Desktop/Coder/MyBlog/server/venv/lib/python3.7/site-packages/rest_framework/response.py", line 70, in rendered_content
    ret = renderer.render(self.data, accepted_media_type, context)
  File "/Users/xiao2/Desktop/Coder/MyBlog/server/venv/lib/python3.7/site-packages/rest_framework/renderers.py", line 725, in render
    context = self.get_context(data, accepted_media_type, renderer_context)
  File "/Users/xiao2/Desktop/Coder/MyBlog/server/venv/lib/python3.7/site-packages/rest_framework/renderers.py", line 681, in get_context
    'content': self.get_content(renderer, data, accepted_media_type, renderer_context),
  File "/Users/xiao2/Desktop/Coder/MyBlog/server/venv/lib/python3.7/site-packages/rest_framework/renderers.py", line 414, in get_content
    content = renderer.render(data, accepted_media_type, renderer_context)
  File "/Users/xiao2/Desktop/Coder/MyBlog/server/venv/lib/python3.7/site-packages/rest_framework/renderers.py", line 104, in render
    allow_nan=not self.strict, separators=separators
  File "/Users/xiao2/Desktop/Coder/MyBlog/server/venv/lib/python3.7/site-packages/rest_framework/utils/json.py", line 25, in dumps
    return json.dumps(*args, **kwargs)
  File "/usr/local/Cellar/python/3.7.3/Frameworks/Python.framework/Versions/3.7/lib/python3.7/json/__init__.py", line 238, in dumps
    **kw).encode(obj)
  File "/usr/local/Cellar/python/3.7.3/Frameworks/Python.framework/Versions/3.7/lib/python3.7/json/encoder.py", line 201, in encode
    chunks = list(chunks)
  File "/usr/local/Cellar/python/3.7.3/Frameworks/Python.framework/Versions/3.7/lib/python3.7/json/encoder.py", line 431, in _iterencode
    yield from _iterencode_dict(o, _current_indent_level)
  File "/usr/local/Cellar/python/3.7.3/Frameworks/Python.framework/Versions/3.7/lib/python3.7/json/encoder.py", line 405, in _iterencode_dict
    yield from chunks
  File "/usr/local/Cellar/python/3.7.3/Frameworks/Python.framework/Versions/3.7/lib/python3.7/json/encoder.py", line 376, in _iterencode_dict
    raise TypeError(f'keys must be str, int, float, bool or None, '
TypeError: keys must be str, int, float, bool or None, not Article
[2019-11-28 15:27:41,422][Thread-2:123145370505216][task_id:django.request][log.py:228][ERROR][Internal Server Error: /api2/api/nextArticle]
Traceback (most recent call last):
  File "/Users/xiao2/Desktop/Coder/MyBlog/server/venv/lib/python3.7/site-packages/django/core/handlers/exception.py", line 34, in inner
    response = get_response(request)
  File "/Users/xiao2/Desktop/Coder/MyBlog/server/venv/lib/python3.7/site-packages/django/core/handlers/base.py", line 145, in _get_response
    response = self.process_exception_by_middleware(e, request)
  File "/Users/xiao2/Desktop/Coder/MyBlog/server/venv/lib/python3.7/site-packages/django/core/handlers/base.py", line 143, in _get_response
    response = response.render()
  File "/Users/xiao2/Desktop/Coder/MyBlog/server/venv/lib/python3.7/site-packages/django/template/response.py", line 106, in render
    self.content = self.rendered_content
  File "/Users/xiao2/Desktop/Coder/MyBlog/server/venv/lib/python3.7/site-packages/rest_framework/response.py", line 70, in rendered_content
    ret = renderer.render(self.data, accepted_media_type, context)
  File "/Users/xiao2/Desktop/Coder/MyBlog/server/venv/lib/python3.7/site-packages/rest_framework/renderers.py", line 725, in render
    context = self.get_context(data, accepted_media_type, renderer_context)
  File "/Users/xiao2/Desktop/Coder/MyBlog/server/venv/lib/python3.7/site-packages/rest_framework/renderers.py", line 681, in get_context
    'content': self.get_content(renderer, data, accepted_media_type, renderer_context),
  File "/Users/xiao2/Desktop/Coder/MyBlog/server/venv/lib/python3.7/site-packages/rest_framework/renderers.py", line 414, in get_content
    content = renderer.render(data, accepted_media_type, renderer_context)
  File "/Users/xiao2/Desktop/Coder/MyBlog/server/venv/lib/python3.7/site-packages/rest_framework/renderers.py", line 104, in render
    allow_nan=not self.strict, separators=separators
  File "/Users/xiao2/Desktop/Coder/MyBlog/server/venv/lib/python3.7/site-packages/rest_framework/utils/json.py", line 25, in dumps
    return json.dumps(*args, **kwargs)
  File "/usr/local/Cellar/python/3.7.3/Frameworks/Python.framework/Versions/3.7/lib/python3.7/json/__init__.py", line 238, in dumps
    **kw).encode(obj)
  File "/usr/local/Cellar/python/3.7.3/Frameworks/Python.framework/Versions/3.7/lib/python3.7/json/encoder.py", line 201, in encode
    chunks = list(chunks)
  File "/usr/local/Cellar/python/3.7.3/Frameworks/Python.framework/Versions/3.7/lib/python3.7/json/encoder.py", line 431, in _iterencode
    yield from _iterencode_dict(o, _current_indent_level)
  File "/usr/local/Cellar/python/3.7.3/Frameworks/Python.framework/Versions/3.7/lib/python3.7/json/encoder.py", line 405, in _iterencode_dict
    yield from chunks
  File "/usr/local/Cellar/python/3.7.3/Frameworks/Python.framework/Versions/3.7/lib/python3.7/json/encoder.py", line 376, in _iterencode_dict
    raise TypeError(f'keys must be str, int, float, bool or None, '
TypeError: keys must be str, int, float, bool or None, not Article
[2019-11-28 15:28:29,280][Thread-1:123145477464064][task_id:django.request][log.py:228][ERROR][Internal Server Error: /api2/api/nextArticle]
Traceback (most recent call last):
  File "/Users/xiao2/Desktop/Coder/MyBlog/server/venv/lib/python3.7/site-packages/django/core/handlers/exception.py", line 34, in inner
    response = get_response(request)
  File "/Users/xiao2/Desktop/Coder/MyBlog/server/venv/lib/python3.7/site-packages/django/core/handlers/base.py", line 145, in _get_response
    response = self.process_exception_by_middleware(e, request)
  File "/Users/xiao2/Desktop/Coder/MyBlog/server/venv/lib/python3.7/site-packages/django/core/handlers/base.py", line 143, in _get_response
    response = response.render()
  File "/Users/xiao2/Desktop/Coder/MyBlog/server/venv/lib/python3.7/site-packages/django/template/response.py", line 106, in render
    self.content = self.rendered_content
  File "/Users/xiao2/Desktop/Coder/MyBlog/server/venv/lib/python3.7/site-packages/rest_framework/response.py", line 70, in rendered_content
    ret = renderer.render(self.data, accepted_media_type, context)
  File "/Users/xiao2/Desktop/Coder/MyBlog/server/venv/lib/python3.7/site-packages/rest_framework/renderers.py", line 725, in render
    context = self.get_context(data, accepted_media_type, renderer_context)
  File "/Users/xiao2/Desktop/Coder/MyBlog/server/venv/lib/python3.7/site-packages/rest_framework/renderers.py", line 681, in get_context
    'content': self.get_content(renderer, data, accepted_media_type, renderer_context),
  File "/Users/xiao2/Desktop/Coder/MyBlog/server/venv/lib/python3.7/site-packages/rest_framework/renderers.py", line 414, in get_content
    content = renderer.render(data, accepted_media_type, renderer_context)
  File "/Users/xiao2/Desktop/Coder/MyBlog/server/venv/lib/python3.7/site-packages/rest_framework/renderers.py", line 104, in render
    allow_nan=not self.strict, separators=separators
  File "/Users/xiao2/Desktop/Coder/MyBlog/server/venv/lib/python3.7/site-packages/rest_framework/utils/json.py", line 25, in dumps
    return json.dumps(*args, **kwargs)
  File "/usr/local/Cellar/python/3.7.3/Frameworks/Python.framework/Versions/3.7/lib/python3.7/json/__init__.py", line 238, in dumps
    **kw).encode(obj)
  File "/usr/local/Cellar/python/3.7.3/Frameworks/Python.framework/Versions/3.7/lib/python3.7/json/encoder.py", line 201, in encode
    chunks = list(chunks)
  File "/usr/local/Cellar/python/3.7.3/Frameworks/Python.framework/Versions/3.7/lib/python3.7/json/encoder.py", line 431, in _iterencode
    yield from _iterencode_dict(o, _current_indent_level)
  File "/usr/local/Cellar/python/3.7.3/Frameworks/Python.framework/Versions/3.7/lib/python3.7/json/encoder.py", line 405, in _iterencode_dict
    yield from chunks
  File "/usr/local/Cellar/python/3.7.3/Frameworks/Python.framework/Versions/3.7/lib/python3.7/json/encoder.py", line 405, in _iterencode_dict
    yield from chunks
  File "/usr/local/Cellar/python/3.7.3/Frameworks/Python.framework/Versions/3.7/lib/python3.7/json/encoder.py", line 438, in _iterencode
    o = _default(o)
  File "/Users/xiao2/Desktop/Coder/MyBlog/server/venv/lib/python3.7/site-packages/rest_framework/utils/encoders.py", line 67, in default
    return super().default(obj)
  File "/usr/local/Cellar/python/3.7.3/Frameworks/Python.framework/Versions/3.7/lib/python3.7/json/encoder.py", line 179, in default
    raise TypeError(f'Object of type {o.__class__.__name__} '
TypeError: Object of type Article is not JSON serializable
[2019-11-28 15:32:43,156][Thread-2:123145405743104][task_id:django.request][log.py:228][ERROR][Internal Server Error: /api2/api/nextArticle]
Traceback (most recent call last):
  File "/Users/xiao2/Desktop/Coder/MyBlog/server/venv/lib/python3.7/site-packages/django/core/handlers/exception.py", line 34, in inner
    response = get_response(request)
  File "/Users/xiao2/Desktop/Coder/MyBlog/server/venv/lib/python3.7/site-packages/django/core/handlers/base.py", line 145, in _get_response
    response = self.process_exception_by_middleware(e, request)
  File "/Users/xiao2/Desktop/Coder/MyBlog/server/venv/lib/python3.7/site-packages/django/core/handlers/base.py", line 143, in _get_response
    response = response.render()
  File "/Users/xiao2/Desktop/Coder/MyBlog/server/venv/lib/python3.7/site-packages/django/template/response.py", line 106, in render
    self.content = self.rendered_content
  File "/Users/xiao2/Desktop/Coder/MyBlog/server/venv/lib/python3.7/site-packages/rest_framework/response.py", line 70, in rendered_content
    ret = renderer.render(self.data, accepted_media_type, context)
  File "/Users/xiao2/Desktop/Coder/MyBlog/server/venv/lib/python3.7/site-packages/rest_framework/renderers.py", line 725, in render
    context = self.get_context(data, accepted_media_type, renderer_context)
  File "/Users/xiao2/Desktop/Coder/MyBlog/server/venv/lib/python3.7/site-packages/rest_framework/renderers.py", line 681, in get_context
    'content': self.get_content(renderer, data, accepted_media_type, renderer_context),
  File "/Users/xiao2/Desktop/Coder/MyBlog/server/venv/lib/python3.7/site-packages/rest_framework/renderers.py", line 414, in get_content
    content = renderer.render(data, accepted_media_type, renderer_context)
  File "/Users/xiao2/Desktop/Coder/MyBlog/server/venv/lib/python3.7/site-packages/rest_framework/renderers.py", line 104, in render
    allow_nan=not self.strict, separators=separators
  File "/Users/xiao2/Desktop/Coder/MyBlog/server/venv/lib/python3.7/site-packages/rest_framework/utils/json.py", line 25, in dumps
    return json.dumps(*args, **kwargs)
  File "/usr/local/Cellar/python/3.7.3/Frameworks/Python.framework/Versions/3.7/lib/python3.7/json/__init__.py", line 238, in dumps
    **kw).encode(obj)
  File "/usr/local/Cellar/python/3.7.3/Frameworks/Python.framework/Versions/3.7/lib/python3.7/json/encoder.py", line 201, in encode
    chunks = list(chunks)
  File "/usr/local/Cellar/python/3.7.3/Frameworks/Python.framework/Versions/3.7/lib/python3.7/json/encoder.py", line 431, in _iterencode
    yield from _iterencode_dict(o, _current_indent_level)
  File "/usr/local/Cellar/python/3.7.3/Frameworks/Python.framework/Versions/3.7/lib/python3.7/json/encoder.py", line 405, in _iterencode_dict
    yield from chunks
  File "/usr/local/Cellar/python/3.7.3/Frameworks/Python.framework/Versions/3.7/lib/python3.7/json/encoder.py", line 405, in _iterencode_dict
    yield from chunks
  File "/usr/local/Cellar/python/3.7.3/Frameworks/Python.framework/Versions/3.7/lib/python3.7/json/encoder.py", line 438, in _iterencode
    o = _default(o)
  File "/Users/xiao2/Desktop/Coder/MyBlog/server/venv/lib/python3.7/site-packages/rest_framework/utils/encoders.py", line 67, in default
    return super().default(obj)
  File "/usr/local/Cellar/python/3.7.3/Frameworks/Python.framework/Versions/3.7/lib/python3.7/json/encoder.py", line 179, in default
    raise TypeError(f'Object of type {o.__class__.__name__} '
TypeError: Object of type Article is not JSON serializable
[2019-11-28 15:32:43,282][Thread-2:123145405743104][task_id:django.request][log.py:228][ERROR][Internal Server Error: /api2/api/nextArticle]
Traceback (most recent call last):
  File "/Users/xiao2/Desktop/Coder/MyBlog/server/venv/lib/python3.7/site-packages/django/core/handlers/exception.py", line 34, in inner
    response = get_response(request)
  File "/Users/xiao2/Desktop/Coder/MyBlog/server/venv/lib/python3.7/site-packages/django/core/handlers/base.py", line 115, in _get_response
    response = self.process_exception_by_middleware(e, request)
  File "/Users/xiao2/Desktop/Coder/MyBlog/server/venv/lib/python3.7/site-packages/django/core/handlers/base.py", line 113, in _get_response
    response = wrapped_callback(request, *callback_args, **callback_kwargs)
  File "/Users/xiao2/Desktop/Coder/MyBlog/server/venv/lib/python3.7/site-packages/django/views/decorators/csrf.py", line 54, in wrapped_view
    return view_func(*args, **kwargs)
  File "/Users/xiao2/Desktop/Coder/MyBlog/server/venv/lib/python3.7/site-packages/django/views/generic/base.py", line 71, in view
    return self.dispatch(request, *args, **kwargs)
  File "/Users/xiao2/Desktop/Coder/MyBlog/server/venv/lib/python3.7/site-packages/rest_framework/views.py", line 505, in dispatch
    response = self.handle_exception(exc)
  File "/Users/xiao2/Desktop/Coder/MyBlog/server/venv/lib/python3.7/site-packages/rest_framework/views.py", line 465, in handle_exception
    self.raise_uncaught_exception(exc)
  File "/Users/xiao2/Desktop/Coder/MyBlog/server/venv/lib/python3.7/site-packages/rest_framework/views.py", line 476, in raise_uncaught_exception
    raise exc
  File "/Users/xiao2/Desktop/Coder/MyBlog/server/venv/lib/python3.7/site-packages/rest_framework/views.py", line 502, in dispatch
    response = handler(request, *args, **kwargs)
  File "/Users/xiao2/Desktop/Coder/MyBlog/server/blog/views.py", line 170, in get
    return self.post(request)
  File "/Users/xiao2/Desktop/Coder/MyBlog/server/blog/views.py", line 183, in post
    id = body2.get('id', None)
AttributeError: 'str' object has no attribute 'get'
[2019-11-28 15:33:24,138][Thread-2:123145405743104][task_id:django.request][log.py:228][ERROR][Internal Server Error: /api2/api/nextArticle]
Traceback (most recent call last):
  File "/Users/xiao2/Desktop/Coder/MyBlog/server/venv/lib/python3.7/site-packages/django/core/handlers/exception.py", line 34, in inner
    response = get_response(request)
  File "/Users/xiao2/Desktop/Coder/MyBlog/server/venv/lib/python3.7/site-packages/django/core/handlers/base.py", line 115, in _get_response
    response = self.process_exception_by_middleware(e, request)
  File "/Users/xiao2/Desktop/Coder/MyBlog/server/venv/lib/python3.7/site-packages/django/core/handlers/base.py", line 113, in _get_response
    response = wrapped_callback(request, *callback_args, **callback_kwargs)
  File "/Users/xiao2/Desktop/Coder/MyBlog/server/venv/lib/python3.7/site-packages/django/views/decorators/csrf.py", line 54, in wrapped_view
    return view_func(*args, **kwargs)
  File "/Users/xiao2/Desktop/Coder/MyBlog/server/venv/lib/python3.7/site-packages/django/views/generic/base.py", line 71, in view
    return self.dispatch(request, *args, **kwargs)
  File "/Users/xiao2/Desktop/Coder/MyBlog/server/venv/lib/python3.7/site-packages/rest_framework/views.py", line 505, in dispatch
    response = self.handle_exception(exc)
  File "/Users/xiao2/Desktop/Coder/MyBlog/server/venv/lib/python3.7/site-packages/rest_framework/views.py", line 465, in handle_exception
    self.raise_uncaught_exception(exc)
  File "/Users/xiao2/Desktop/Coder/MyBlog/server/venv/lib/python3.7/site-packages/rest_framework/views.py", line 476, in raise_uncaught_exception
    raise exc
  File "/Users/xiao2/Desktop/Coder/MyBlog/server/venv/lib/python3.7/site-packages/rest_framework/views.py", line 502, in dispatch
    response = handler(request, *args, **kwargs)
  File "/Users/xiao2/Desktop/Coder/MyBlog/server/blog/views.py", line 170, in get
    return self.post(request)
  File "/Users/xiao2/Desktop/Coder/MyBlog/server/blog/views.py", line 183, in post
    id = body2.get('id', None)
AttributeError: 'str' object has no attribute 'get'
[2019-11-28 15:34:13,111][Thread-1:123145392742400][task_id:django.request][log.py:228][ERROR][Internal Server Error: /api2/api/nextArticle]
Traceback (most recent call last):
  File "/Users/xiao2/Desktop/Coder/MyBlog/server/venv/lib/python3.7/site-packages/django/core/handlers/exception.py", line 34, in inner
    response = get_response(request)
  File "/Users/xiao2/Desktop/Coder/MyBlog/server/venv/lib/python3.7/site-packages/django/core/handlers/base.py", line 115, in _get_response
    response = self.process_exception_by_middleware(e, request)
  File "/Users/xiao2/Desktop/Coder/MyBlog/server/venv/lib/python3.7/site-packages/django/core/handlers/base.py", line 113, in _get_response
    response = wrapped_callback(request, *callback_args, **callback_kwargs)
  File "/Users/xiao2/Desktop/Coder/MyBlog/server/venv/lib/python3.7/site-packages/django/views/decorators/csrf.py", line 54, in wrapped_view
    return view_func(*args, **kwargs)
  File "/Users/xiao2/Desktop/Coder/MyBlog/server/venv/lib/python3.7/site-packages/django/views/generic/base.py", line 71, in view
    return self.dispatch(request, *args, **kwargs)
  File "/Users/xiao2/Desktop/Coder/MyBlog/server/venv/lib/python3.7/site-packages/rest_framework/views.py", line 505, in dispatch
    response = self.handle_exception(exc)
  File "/Users/xiao2/Desktop/Coder/MyBlog/server/venv/lib/python3.7/site-packages/rest_framework/views.py", line 465, in handle_exception
    self.raise_uncaught_exception(exc)
  File "/Users/xiao2/Desktop/Coder/MyBlog/server/venv/lib/python3.7/site-packages/rest_framework/views.py", line 476, in raise_uncaught_exception
    raise exc
  File "/Users/xiao2/Desktop/Coder/MyBlog/server/venv/lib/python3.7/site-packages/rest_framework/views.py", line 502, in dispatch
    response = handler(request, *args, **kwargs)
  File "/Users/xiao2/Desktop/Coder/MyBlog/server/blog/views.py", line 167, in get
    return self.post(request)
  File "/Users/xiao2/Desktop/Coder/MyBlog/server/blog/views.py", line 180, in post
    id = body2.get('id', None)
AttributeError: 'str' object has no attribute 'get'
[2019-11-28 15:34:15,345][Thread-1:123145392742400][task_id:django.request][log.py:228][ERROR][Internal Server Error: /api2/api/articleList]
Traceback (most recent call last):
  File "/Users/xiao2/Desktop/Coder/MyBlog/server/venv/lib/python3.7/site-packages/django/core/handlers/exception.py", line 34, in inner
    response = get_response(request)
  File "/Users/xiao2/Desktop/Coder/MyBlog/server/venv/lib/python3.7/site-packages/django/core/handlers/base.py", line 145, in _get_response
    response = self.process_exception_by_middleware(e, request)
  File "/Users/xiao2/Desktop/Coder/MyBlog/server/venv/lib/python3.7/site-packages/django/core/handlers/base.py", line 143, in _get_response
    response = response.render()
  File "/Users/xiao2/Desktop/Coder/MyBlog/server/venv/lib/python3.7/site-packages/django/template/response.py", line 106, in render
    self.content = self.rendered_content
  File "/Users/xiao2/Desktop/Coder/MyBlog/server/venv/lib/python3.7/site-packages/rest_framework/response.py", line 70, in rendered_content
    ret = renderer.render(self.data, accepted_media_type, context)
  File "/Users/xiao2/Desktop/Coder/MyBlog/server/venv/lib/python3.7/site-packages/rest_framework/renderers.py", line 725, in render
    context = self.get_context(data, accepted_media_type, renderer_context)
  File "/Users/xiao2/Desktop/Coder/MyBlog/server/venv/lib/python3.7/site-packages/rest_framework/renderers.py", line 681, in get_context
    'content': self.get_content(renderer, data, accepted_media_type, renderer_context),
  File "/Users/xiao2/Desktop/Coder/MyBlog/server/venv/lib/python3.7/site-packages/rest_framework/renderers.py", line 414, in get_content
    content = renderer.render(data, accepted_media_type, renderer_context)
  File "/Users/xiao2/Desktop/Coder/MyBlog/server/venv/lib/python3.7/site-packages/rest_framework/renderers.py", line 104, in render
    allow_nan=not self.strict, separators=separators
  File "/Users/xiao2/Desktop/Coder/MyBlog/server/venv/lib/python3.7/site-packages/rest_framework/utils/json.py", line 25, in dumps
    return json.dumps(*args, **kwargs)
  File "/usr/local/Cellar/python/3.7.3/Frameworks/Python.framework/Versions/3.7/lib/python3.7/json/__init__.py", line 238, in dumps
    **kw).encode(obj)
  File "/usr/local/Cellar/python/3.7.3/Frameworks/Python.framework/Versions/3.7/lib/python3.7/json/encoder.py", line 201, in encode
    chunks = list(chunks)
  File "/usr/local/Cellar/python/3.7.3/Frameworks/Python.framework/Versions/3.7/lib/python3.7/json/encoder.py", line 431, in _iterencode
    yield from _iterencode_dict(o, _current_indent_level)
  File "/usr/local/Cellar/python/3.7.3/Frameworks/Python.framework/Versions/3.7/lib/python3.7/json/encoder.py", line 405, in _iterencode_dict
    yield from chunks
  File "/usr/local/Cellar/python/3.7.3/Frameworks/Python.framework/Versions/3.7/lib/python3.7/json/encoder.py", line 438, in _iterencode
    o = _default(o)
  File "/Users/xiao2/Desktop/Coder/MyBlog/server/venv/lib/python3.7/site-packages/rest_framework/utils/encoders.py", line 67, in default
    return super().default(obj)
  File "/usr/local/Cellar/python/3.7.3/Frameworks/Python.framework/Versions/3.7/lib/python3.7/json/encoder.py", line 179, in default
    raise TypeError(f'Object of type {o.__class__.__name__} '
TypeError: Object of type AttributeError is not JSON serializable
[2019-11-28 15:34:43,015][Thread-1:123145392742400][task_id:django.request][log.py:228][ERROR][Internal Server Error: /api2/api/articleList]
Traceback (most recent call last):
  File "/Users/xiao2/Desktop/Coder/MyBlog/server/venv/lib/python3.7/site-packages/django/core/handlers/exception.py", line 34, in inner
    response = get_response(request)
  File "/Users/xiao2/Desktop/Coder/MyBlog/server/venv/lib/python3.7/site-packages/django/core/handlers/base.py", line 145, in _get_response
    response = self.process_exception_by_middleware(e, request)
  File "/Users/xiao2/Desktop/Coder/MyBlog/server/venv/lib/python3.7/site-packages/django/core/handlers/base.py", line 143, in _get_response
    response = response.render()
  File "/Users/xiao2/Desktop/Coder/MyBlog/server/venv/lib/python3.7/site-packages/django/template/response.py", line 106, in render
    self.content = self.rendered_content
  File "/Users/xiao2/Desktop/Coder/MyBlog/server/venv/lib/python3.7/site-packages/rest_framework/response.py", line 70, in rendered_content
    ret = renderer.render(self.data, accepted_media_type, context)
  File "/Users/xiao2/Desktop/Coder/MyBlog/server/venv/lib/python3.7/site-packages/rest_framework/renderers.py", line 725, in render
    context = self.get_context(data, accepted_media_type, renderer_context)
  File "/Users/xiao2/Desktop/Coder/MyBlog/server/venv/lib/python3.7/site-packages/rest_framework/renderers.py", line 681, in get_context
    'content': self.get_content(renderer, data, accepted_media_type, renderer_context),
  File "/Users/xiao2/Desktop/Coder/MyBlog/server/venv/lib/python3.7/site-packages/rest_framework/renderers.py", line 414, in get_content
    content = renderer.render(data, accepted_media_type, renderer_context)
  File "/Users/xiao2/Desktop/Coder/MyBlog/server/venv/lib/python3.7/site-packages/rest_framework/renderers.py", line 104, in render
    allow_nan=not self.strict, separators=separators
  File "/Users/xiao2/Desktop/Coder/MyBlog/server/venv/lib/python3.7/site-packages/rest_framework/utils/json.py", line 25, in dumps
    return json.dumps(*args, **kwargs)
  File "/usr/local/Cellar/python/3.7.3/Frameworks/Python.framework/Versions/3.7/lib/python3.7/json/__init__.py", line 238, in dumps
    **kw).encode(obj)
  File "/usr/local/Cellar/python/3.7.3/Frameworks/Python.framework/Versions/3.7/lib/python3.7/json/encoder.py", line 201, in encode
    chunks = list(chunks)
  File "/usr/local/Cellar/python/3.7.3/Frameworks/Python.framework/Versions/3.7/lib/python3.7/json/encoder.py", line 431, in _iterencode
    yield from _iterencode_dict(o, _current_indent_level)
  File "/usr/local/Cellar/python/3.7.3/Frameworks/Python.framework/Versions/3.7/lib/python3.7/json/encoder.py", line 405, in _iterencode_dict
    yield from chunks
  File "/usr/local/Cellar/python/3.7.3/Frameworks/Python.framework/Versions/3.7/lib/python3.7/json/encoder.py", line 438, in _iterencode
    o = _default(o)
  File "/Users/xiao2/Desktop/Coder/MyBlog/server/venv/lib/python3.7/site-packages/rest_framework/utils/encoders.py", line 67, in default
    return super().default(obj)
  File "/usr/local/Cellar/python/3.7.3/Frameworks/Python.framework/Versions/3.7/lib/python3.7/json/encoder.py", line 179, in default
    raise TypeError(f'Object of type {o.__class__.__name__} '
TypeError: Object of type AttributeError is not JSON serializable
[2019-11-28 15:44:19,922][Thread-1:123145482866688][task_id:django.request][log.py:228][ERROR][Internal Server Error: /api2/api/nextArticle]
Traceback (most recent call last):
  File "/Users/xiao2/Desktop/Coder/MyBlog/server/venv/lib/python3.7/site-packages/django/core/handlers/exception.py", line 34, in inner
    response = get_response(request)
  File "/Users/xiao2/Desktop/Coder/MyBlog/server/venv/lib/python3.7/site-packages/django/core/handlers/base.py", line 145, in _get_response
    response = self.process_exception_by_middleware(e, request)
  File "/Users/xiao2/Desktop/Coder/MyBlog/server/venv/lib/python3.7/site-packages/django/core/handlers/base.py", line 143, in _get_response
    response = response.render()
  File "/Users/xiao2/Desktop/Coder/MyBlog/server/venv/lib/python3.7/site-packages/django/template/response.py", line 106, in render
    self.content = self.rendered_content
  File "/Users/xiao2/Desktop/Coder/MyBlog/server/venv/lib/python3.7/site-packages/rest_framework/response.py", line 70, in rendered_content
    ret = renderer.render(self.data, accepted_media_type, context)
  File "/Users/xiao2/Desktop/Coder/MyBlog/server/venv/lib/python3.7/site-packages/rest_framework/renderers.py", line 725, in render
    context = self.get_context(data, accepted_media_type, renderer_context)
  File "/Users/xiao2/Desktop/Coder/MyBlog/server/venv/lib/python3.7/site-packages/rest_framework/renderers.py", line 681, in get_context
    'content': self.get_content(renderer, data, accepted_media_type, renderer_context),
  File "/Users/xiao2/Desktop/Coder/MyBlog/server/venv/lib/python3.7/site-packages/rest_framework/renderers.py", line 414, in get_content
    content = renderer.render(data, accepted_media_type, renderer_context)
  File "/Users/xiao2/Desktop/Coder/MyBlog/server/venv/lib/python3.7/site-packages/rest_framework/renderers.py", line 104, in render
    allow_nan=not self.strict, separators=separators
  File "/Users/xiao2/Desktop/Coder/MyBlog/server/venv/lib/python3.7/site-packages/rest_framework/utils/json.py", line 25, in dumps
    return json.dumps(*args, **kwargs)
  File "/usr/local/Cellar/python/3.7.3/Frameworks/Python.framework/Versions/3.7/lib/python3.7/json/__init__.py", line 238, in dumps
    **kw).encode(obj)
  File "/usr/local/Cellar/python/3.7.3/Frameworks/Python.framework/Versions/3.7/lib/python3.7/json/encoder.py", line 201, in encode
    chunks = list(chunks)
  File "/usr/local/Cellar/python/3.7.3/Frameworks/Python.framework/Versions/3.7/lib/python3.7/json/encoder.py", line 431, in _iterencode
    yield from _iterencode_dict(o, _current_indent_level)
  File "/usr/local/Cellar/python/3.7.3/Frameworks/Python.framework/Versions/3.7/lib/python3.7/json/encoder.py", line 405, in _iterencode_dict
    yield from chunks
  File "/usr/local/Cellar/python/3.7.3/Frameworks/Python.framework/Versions/3.7/lib/python3.7/json/encoder.py", line 405, in _iterencode_dict
    yield from chunks
  File "/usr/local/Cellar/python/3.7.3/Frameworks/Python.framework/Versions/3.7/lib/python3.7/json/encoder.py", line 438, in _iterencode
    o = _default(o)
  File "/Users/xiao2/Desktop/Coder/MyBlog/server/venv/lib/python3.7/site-packages/rest_framework/utils/encoders.py", line 67, in default
    return super().default(obj)
  File "/usr/local/Cellar/python/3.7.3/Frameworks/Python.framework/Versions/3.7/lib/python3.7/json/encoder.py", line 179, in default
    raise TypeError(f'Object of type {o.__class__.__name__} '
TypeError: Object of type Article is not JSON serializable
[2019-11-28 15:45:13,684][Thread-1:123145482866688][task_id:django.request][log.py:228][ERROR][Internal Server Error: /api2/api/nextArticle]
Traceback (most recent call last):
  File "/Users/xiao2/Desktop/Coder/MyBlog/server/venv/lib/python3.7/site-packages/django/core/handlers/exception.py", line 34, in inner
    response = get_response(request)
  File "/Users/xiao2/Desktop/Coder/MyBlog/server/venv/lib/python3.7/site-packages/django/core/handlers/base.py", line 145, in _get_response
    response = self.process_exception_by_middleware(e, request)
  File "/Users/xiao2/Desktop/Coder/MyBlog/server/venv/lib/python3.7/site-packages/django/core/handlers/base.py", line 143, in _get_response
    response = response.render()
  File "/Users/xiao2/Desktop/Coder/MyBlog/server/venv/lib/python3.7/site-packages/django/template/response.py", line 106, in render
    self.content = self.rendered_content
  File "/Users/xiao2/Desktop/Coder/MyBlog/server/venv/lib/python3.7/site-packages/rest_framework/response.py", line 70, in rendered_content
    ret = renderer.render(self.data, accepted_media_type, context)
  File "/Users/xiao2/Desktop/Coder/MyBlog/server/venv/lib/python3.7/site-packages/rest_framework/renderers.py", line 725, in render
    context = self.get_context(data, accepted_media_type, renderer_context)
  File "/Users/xiao2/Desktop/Coder/MyBlog/server/venv/lib/python3.7/site-packages/rest_framework/renderers.py", line 681, in get_context
    'content': self.get_content(renderer, data, accepted_media_type, renderer_context),
  File "/Users/xiao2/Desktop/Coder/MyBlog/server/venv/lib/python3.7/site-packages/rest_framework/renderers.py", line 414, in get_content
    content = renderer.render(data, accepted_media_type, renderer_context)
  File "/Users/xiao2/Desktop/Coder/MyBlog/server/venv/lib/python3.7/site-packages/rest_framework/renderers.py", line 104, in render
    allow_nan=not self.strict, separators=separators
  File "/Users/xiao2/Desktop/Coder/MyBlog/server/venv/lib/python3.7/site-packages/rest_framework/utils/json.py", line 25, in dumps
    return json.dumps(*args, **kwargs)
  File "/usr/local/Cellar/python/3.7.3/Frameworks/Python.framework/Versions/3.7/lib/python3.7/json/__init__.py", line 238, in dumps
    **kw).encode(obj)
  File "/usr/local/Cellar/python/3.7.3/Frameworks/Python.framework/Versions/3.7/lib/python3.7/json/encoder.py", line 201, in encode
    chunks = list(chunks)
  File "/usr/local/Cellar/python/3.7.3/Frameworks/Python.framework/Versions/3.7/lib/python3.7/json/encoder.py", line 431, in _iterencode
    yield from _iterencode_dict(o, _current_indent_level)
  File "/usr/local/Cellar/python/3.7.3/Frameworks/Python.framework/Versions/3.7/lib/python3.7/json/encoder.py", line 405, in _iterencode_dict
    yield from chunks
  File "/usr/local/Cellar/python/3.7.3/Frameworks/Python.framework/Versions/3.7/lib/python3.7/json/encoder.py", line 405, in _iterencode_dict
    yield from chunks
  File "/usr/local/Cellar/python/3.7.3/Frameworks/Python.framework/Versions/3.7/lib/python3.7/json/encoder.py", line 438, in _iterencode
    o = _default(o)
  File "/Users/xiao2/Desktop/Coder/MyBlog/server/venv/lib/python3.7/site-packages/rest_framework/utils/encoders.py", line 67, in default
    return super().default(obj)
  File "/usr/local/Cellar/python/3.7.3/Frameworks/Python.framework/Versions/3.7/lib/python3.7/json/encoder.py", line 179, in default
    raise TypeError(f'Object of type {o.__class__.__name__} '
TypeError: Object of type Article is not JSON serializable
[2019-11-28 15:49:03,547][Thread-1:123145555271680][task_id:django.request][log.py:228][ERROR][Internal Server Error: /api2/api/nextArticle]
Traceback (most recent call last):
  File "/Users/xiao2/Desktop/Coder/MyBlog/server/venv/lib/python3.7/site-packages/django/core/handlers/exception.py", line 34, in inner
    response = get_response(request)
  File "/Users/xiao2/Desktop/Coder/MyBlog/server/venv/lib/python3.7/site-packages/django/core/handlers/base.py", line 145, in _get_response
    response = self.process_exception_by_middleware(e, request)
  File "/Users/xiao2/Desktop/Coder/MyBlog/server/venv/lib/python3.7/site-packages/django/core/handlers/base.py", line 143, in _get_response
    response = response.render()
  File "/Users/xiao2/Desktop/Coder/MyBlog/server/venv/lib/python3.7/site-packages/django/template/response.py", line 106, in render
    self.content = self.rendered_content
  File "/Users/xiao2/Desktop/Coder/MyBlog/server/venv/lib/python3.7/site-packages/rest_framework/response.py", line 70, in rendered_content
    ret = renderer.render(self.data, accepted_media_type, context)
  File "/Users/xiao2/Desktop/Coder/MyBlog/server/venv/lib/python3.7/site-packages/rest_framework/renderers.py", line 725, in render
    context = self.get_context(data, accepted_media_type, renderer_context)
  File "/Users/xiao2/Desktop/Coder/MyBlog/server/venv/lib/python3.7/site-packages/rest_framework/renderers.py", line 681, in get_context
    'content': self.get_content(renderer, data, accepted_media_type, renderer_context),
  File "/Users/xiao2/Desktop/Coder/MyBlog/server/venv/lib/python3.7/site-packages/rest_framework/renderers.py", line 414, in get_content
    content = renderer.render(data, accepted_media_type, renderer_context)
  File "/Users/xiao2/Desktop/Coder/MyBlog/server/venv/lib/python3.7/site-packages/rest_framework/renderers.py", line 104, in render
    allow_nan=not self.strict, separators=separators
  File "/Users/xiao2/Desktop/Coder/MyBlog/server/venv/lib/python3.7/site-packages/rest_framework/utils/json.py", line 25, in dumps
    return json.dumps(*args, **kwargs)
  File "/usr/local/Cellar/python/3.7.3/Frameworks/Python.framework/Versions/3.7/lib/python3.7/json/__init__.py", line 238, in dumps
    **kw).encode(obj)
  File "/usr/local/Cellar/python/3.7.3/Frameworks/Python.framework/Versions/3.7/lib/python3.7/json/encoder.py", line 201, in encode
    chunks = list(chunks)
  File "/usr/local/Cellar/python/3.7.3/Frameworks/Python.framework/Versions/3.7/lib/python3.7/json/encoder.py", line 431, in _iterencode
    yield from _iterencode_dict(o, _current_indent_level)
  File "/usr/local/Cellar/python/3.7.3/Frameworks/Python.framework/Versions/3.7/lib/python3.7/json/encoder.py", line 405, in _iterencode_dict
    yield from chunks
  File "/usr/local/Cellar/python/3.7.3/Frameworks/Python.framework/Versions/3.7/lib/python3.7/json/encoder.py", line 405, in _iterencode_dict
    yield from chunks
  File "/usr/local/Cellar/python/3.7.3/Frameworks/Python.framework/Versions/3.7/lib/python3.7/json/encoder.py", line 438, in _iterencode
    o = _default(o)
  File "/Users/xiao2/Desktop/Coder/MyBlog/server/venv/lib/python3.7/site-packages/rest_framework/utils/encoders.py", line 67, in default
    return super().default(obj)
  File "/usr/local/Cellar/python/3.7.3/Frameworks/Python.framework/Versions/3.7/lib/python3.7/json/encoder.py", line 179, in default
    raise TypeError(f'Object of type {o.__class__.__name__} '
TypeError: Object of type ArticleListSerializer is not JSON serializable
[2019-11-28 15:49:34,013][Thread-1:123145384566784][task_id:django.request][log.py:228][ERROR][Internal Server Error: /api2/api/nextArticle]
Traceback (most recent call last):
  File "/Users/xiao2/Desktop/Coder/MyBlog/server/venv/lib/python3.7/site-packages/django/core/handlers/exception.py", line 34, in inner
    response = get_response(request)
  File "/Users/xiao2/Desktop/Coder/MyBlog/server/venv/lib/python3.7/site-packages/django/core/handlers/base.py", line 145, in _get_response
    response = self.process_exception_by_middleware(e, request)
  File "/Users/xiao2/Desktop/Coder/MyBlog/server/venv/lib/python3.7/site-packages/django/core/handlers/base.py", line 143, in _get_response
    response = response.render()
  File "/Users/xiao2/Desktop/Coder/MyBlog/server/venv/lib/python3.7/site-packages/django/template/response.py", line 106, in render
    self.content = self.rendered_content
  File "/Users/xiao2/Desktop/Coder/MyBlog/server/venv/lib/python3.7/site-packages/rest_framework/response.py", line 70, in rendered_content
    ret = renderer.render(self.data, accepted_media_type, context)
  File "/Users/xiao2/Desktop/Coder/MyBlog/server/venv/lib/python3.7/site-packages/rest_framework/renderers.py", line 725, in render
    context = self.get_context(data, accepted_media_type, renderer_context)
  File "/Users/xiao2/Desktop/Coder/MyBlog/server/venv/lib/python3.7/site-packages/rest_framework/renderers.py", line 681, in get_context
    'content': self.get_content(renderer, data, accepted_media_type, renderer_context),
  File "/Users/xiao2/Desktop/Coder/MyBlog/server/venv/lib/python3.7/site-packages/rest_framework/renderers.py", line 414, in get_content
    content = renderer.render(data, accepted_media_type, renderer_context)
  File "/Users/xiao2/Desktop/Coder/MyBlog/server/venv/lib/python3.7/site-packages/rest_framework/renderers.py", line 104, in render
    allow_nan=not self.strict, separators=separators
  File "/Users/xiao2/Desktop/Coder/MyBlog/server/venv/lib/python3.7/site-packages/rest_framework/utils/json.py", line 25, in dumps
    return json.dumps(*args, **kwargs)
  File "/usr/local/Cellar/python/3.7.3/Frameworks/Python.framework/Versions/3.7/lib/python3.7/json/__init__.py", line 238, in dumps
    **kw).encode(obj)
  File "/usr/local/Cellar/python/3.7.3/Frameworks/Python.framework/Versions/3.7/lib/python3.7/json/encoder.py", line 201, in encode
    chunks = list(chunks)
  File "/usr/local/Cellar/python/3.7.3/Frameworks/Python.framework/Versions/3.7/lib/python3.7/json/encoder.py", line 431, in _iterencode
    yield from _iterencode_dict(o, _current_indent_level)
  File "/usr/local/Cellar/python/3.7.3/Frameworks/Python.framework/Versions/3.7/lib/python3.7/json/encoder.py", line 405, in _iterencode_dict
    yield from chunks
  File "/usr/local/Cellar/python/3.7.3/Frameworks/Python.framework/Versions/3.7/lib/python3.7/json/encoder.py", line 405, in _iterencode_dict
    yield from chunks
  File "/usr/local/Cellar/python/3.7.3/Frameworks/Python.framework/Versions/3.7/lib/python3.7/json/encoder.py", line 438, in _iterencode
    o = _default(o)
  File "/Users/xiao2/Desktop/Coder/MyBlog/server/venv/lib/python3.7/site-packages/rest_framework/utils/encoders.py", line 67, in default
    return super().default(obj)
  File "/usr/local/Cellar/python/3.7.3/Frameworks/Python.framework/Versions/3.7/lib/python3.7/json/encoder.py", line 179, in default
    raise TypeError(f'Object of type {o.__class__.__name__} '
TypeError: Object of type Article is not JSON serializable
[2019-11-28 15:51:10,586][Thread-1:123145535352832][task_id:django.request][log.py:228][ERROR][Internal Server Error: /api2/api/nextArticle]
Traceback (most recent call last):
  File "/Users/xiao2/Desktop/Coder/MyBlog/server/venv/lib/python3.7/site-packages/django/core/handlers/exception.py", line 34, in inner
    response = get_response(request)
  File "/Users/xiao2/Desktop/Coder/MyBlog/server/venv/lib/python3.7/site-packages/django/core/handlers/base.py", line 145, in _get_response
    response = self.process_exception_by_middleware(e, request)
  File "/Users/xiao2/Desktop/Coder/MyBlog/server/venv/lib/python3.7/site-packages/django/core/handlers/base.py", line 143, in _get_response
    response = response.render()
  File "/Users/xiao2/Desktop/Coder/MyBlog/server/venv/lib/python3.7/site-packages/django/template/response.py", line 106, in render
    self.content = self.rendered_content
  File "/Users/xiao2/Desktop/Coder/MyBlog/server/venv/lib/python3.7/site-packages/rest_framework/response.py", line 70, in rendered_content
    ret = renderer.render(self.data, accepted_media_type, context)
  File "/Users/xiao2/Desktop/Coder/MyBlog/server/venv/lib/python3.7/site-packages/rest_framework/renderers.py", line 725, in render
    context = self.get_context(data, accepted_media_type, renderer_context)
  File "/Users/xiao2/Desktop/Coder/MyBlog/server/venv/lib/python3.7/site-packages/rest_framework/renderers.py", line 681, in get_context
    'content': self.get_content(renderer, data, accepted_media_type, renderer_context),
  File "/Users/xiao2/Desktop/Coder/MyBlog/server/venv/lib/python3.7/site-packages/rest_framework/renderers.py", line 414, in get_content
    content = renderer.render(data, accepted_media_type, renderer_context)
  File "/Users/xiao2/Desktop/Coder/MyBlog/server/venv/lib/python3.7/site-packages/rest_framework/renderers.py", line 104, in render
    allow_nan=not self.strict, separators=separators
  File "/Users/xiao2/Desktop/Coder/MyBlog/server/venv/lib/python3.7/site-packages/rest_framework/utils/json.py", line 25, in dumps
    return json.dumps(*args, **kwargs)
  File "/usr/local/Cellar/python/3.7.3/Frameworks/Python.framework/Versions/3.7/lib/python3.7/json/__init__.py", line 238, in dumps
    **kw).encode(obj)
  File "/usr/local/Cellar/python/3.7.3/Frameworks/Python.framework/Versions/3.7/lib/python3.7/json/encoder.py", line 201, in encode
    chunks = list(chunks)
  File "/usr/local/Cellar/python/3.7.3/Frameworks/Python.framework/Versions/3.7/lib/python3.7/json/encoder.py", line 431, in _iterencode
    yield from _iterencode_dict(o, _current_indent_level)
  File "/usr/local/Cellar/python/3.7.3/Frameworks/Python.framework/Versions/3.7/lib/python3.7/json/encoder.py", line 405, in _iterencode_dict
    yield from chunks
  File "/usr/local/Cellar/python/3.7.3/Frameworks/Python.framework/Versions/3.7/lib/python3.7/json/encoder.py", line 405, in _iterencode_dict
    yield from chunks
  File "/usr/local/Cellar/python/3.7.3/Frameworks/Python.framework/Versions/3.7/lib/python3.7/json/encoder.py", line 438, in _iterencode
    o = _default(o)
  File "/Users/xiao2/Desktop/Coder/MyBlog/server/venv/lib/python3.7/site-packages/rest_framework/utils/encoders.py", line 67, in default
    return super().default(obj)
  File "/usr/local/Cellar/python/3.7.3/Frameworks/Python.framework/Versions/3.7/lib/python3.7/json/encoder.py", line 179, in default
    raise TypeError(f'Object of type {o.__class__.__name__} '
TypeError: Object of type ArticleListSerializer is not JSON serializable
[2019-11-29 08:59:25,251][Thread-2:123145465090048][task_id:django.request][log.py:228][ERROR][Internal Server Error: /api2/api/articleList]
Traceback (most recent call last):
  File "/Users/xiao2/Desktop/Coder/MyBlog/server/venv/lib/python3.7/site-packages/django/core/handlers/exception.py", line 34, in inner
    response = get_response(request)
  File "/Users/xiao2/Desktop/Coder/MyBlog/server/venv/lib/python3.7/site-packages/django/core/handlers/base.py", line 145, in _get_response
    response = self.process_exception_by_middleware(e, request)
  File "/Users/xiao2/Desktop/Coder/MyBlog/server/venv/lib/python3.7/site-packages/django/core/handlers/base.py", line 143, in _get_response
    response = response.render()
  File "/Users/xiao2/Desktop/Coder/MyBlog/server/venv/lib/python3.7/site-packages/django/template/response.py", line 106, in render
    self.content = self.rendered_content
  File "/Users/xiao2/Desktop/Coder/MyBlog/server/venv/lib/python3.7/site-packages/rest_framework/response.py", line 70, in rendered_content
    ret = renderer.render(self.data, accepted_media_type, context)
  File "/Users/xiao2/Desktop/Coder/MyBlog/server/venv/lib/python3.7/site-packages/rest_framework/renderers.py", line 104, in render
    allow_nan=not self.strict, separators=separators
  File "/Users/xiao2/Desktop/Coder/MyBlog/server/venv/lib/python3.7/site-packages/rest_framework/utils/json.py", line 25, in dumps
    return json.dumps(*args, **kwargs)
  File "/usr/local/Cellar/python/3.7.3/Frameworks/Python.framework/Versions/3.7/lib/python3.7/json/__init__.py", line 238, in dumps
    **kw).encode(obj)
  File "/usr/local/Cellar/python/3.7.3/Frameworks/Python.framework/Versions/3.7/lib/python3.7/json/encoder.py", line 199, in encode
    chunks = self.iterencode(o, _one_shot=True)
  File "/usr/local/Cellar/python/3.7.3/Frameworks/Python.framework/Versions/3.7/lib/python3.7/json/encoder.py", line 257, in iterencode
    return _iterencode(o, 0)
  File "/Users/xiao2/Desktop/Coder/MyBlog/server/venv/lib/python3.7/site-packages/rest_framework/utils/encoders.py", line 67, in default
    return super().default(obj)
  File "/usr/local/Cellar/python/3.7.3/Frameworks/Python.framework/Versions/3.7/lib/python3.7/json/encoder.py", line 179, in default
    raise TypeError(f'Object of type {o.__class__.__name__} '
TypeError: Object of type InternalError is not JSON serializable
[2019-11-29 08:59:42,357][Thread-2:123145465090048][task_id:django.request][log.py:228][ERROR][Internal Server Error: /api2/api/articleList]
Traceback (most recent call last):
  File "/Users/xiao2/Desktop/Coder/MyBlog/server/venv/lib/python3.7/site-packages/django/core/handlers/exception.py", line 34, in inner
    response = get_response(request)
  File "/Users/xiao2/Desktop/Coder/MyBlog/server/venv/lib/python3.7/site-packages/django/core/handlers/base.py", line 145, in _get_response
    response = self.process_exception_by_middleware(e, request)
  File "/Users/xiao2/Desktop/Coder/MyBlog/server/venv/lib/python3.7/site-packages/django/core/handlers/base.py", line 143, in _get_response
    response = response.render()
  File "/Users/xiao2/Desktop/Coder/MyBlog/server/venv/lib/python3.7/site-packages/django/template/response.py", line 106, in render
    self.content = self.rendered_content
  File "/Users/xiao2/Desktop/Coder/MyBlog/server/venv/lib/python3.7/site-packages/rest_framework/response.py", line 70, in rendered_content
    ret = renderer.render(self.data, accepted_media_type, context)
  File "/Users/xiao2/Desktop/Coder/MyBlog/server/venv/lib/python3.7/site-packages/rest_framework/renderers.py", line 104, in render
    allow_nan=not self.strict, separators=separators
  File "/Users/xiao2/Desktop/Coder/MyBlog/server/venv/lib/python3.7/site-packages/rest_framework/utils/json.py", line 25, in dumps
    return json.dumps(*args, **kwargs)
  File "/usr/local/Cellar/python/3.7.3/Frameworks/Python.framework/Versions/3.7/lib/python3.7/json/__init__.py", line 238, in dumps
    **kw).encode(obj)
  File "/usr/local/Cellar/python/3.7.3/Frameworks/Python.framework/Versions/3.7/lib/python3.7/json/encoder.py", line 199, in encode
    chunks = self.iterencode(o, _one_shot=True)
  File "/usr/local/Cellar/python/3.7.3/Frameworks/Python.framework/Versions/3.7/lib/python3.7/json/encoder.py", line 257, in iterencode
    return _iterencode(o, 0)
  File "/Users/xiao2/Desktop/Coder/MyBlog/server/venv/lib/python3.7/site-packages/rest_framework/utils/encoders.py", line 67, in default
    return super().default(obj)
  File "/usr/local/Cellar/python/3.7.3/Frameworks/Python.framework/Versions/3.7/lib/python3.7/json/encoder.py", line 179, in default
    raise TypeError(f'Object of type {o.__class__.__name__} '
TypeError: Object of type InternalError is not JSON serializable
